Workbook
Name Ancillary: backup!$B$20:$C$29
Name Area_EBM: backup!$B$4:$C$17
Name Dep_Sch_Others: conversion!$A$368:$D$403
Name Depreciation_Schedule: conversion!$A$266:$D$301
Name Interest_Sch_Others: conversion!$A$407:$D$463
Name Interest_Schedule: conversion!$A$306:$D$363
Name Machine_details: backup!$B$1:$Q$118
Name Machines: backup!$D$32:$L$77
Name SKU_Data: input!$A$10:$C$127

Sheet summary
A1: ="Country "&input!C4 -> Country India | B1: ="Currency "&input!C5 -> Currency INR | C1: ="Supplier "&input!C6 -> Supplier Silvassa
A2: ="Product "&input!C2 -> Product Lifeboy 125g | B2: ="Period "&input!C7 -> Period Sep25 | C2: SKU Code | D2: =input!C3 -> xxxxx
A3: =input!A8&" "&input!B8 -> Annual Volume pcs | B3: =input!C8 -> 4913500 | C3: ="Payment term "&input!C111&" days" -> Payment term 60 days
A4: Details | B4: =input!C5&"/1000" -> INR/1000 | C4: EUR/1000 | D4: % of Total Cost
A5: Material | B5: =B12 -> 9461.6805 | C5: =B5/input!$C$102 -> 90.742116 | D5: =B5/$B$10 -> 0.73754519
A6: Conversion | B6: =B15 -> 1842.1048 | C6: =B6/input!$C$102 -> 17.666681 | D6: =B6/$B$10 -> 0.14359347
A7: Margin | B7: =B25 -> 368.42096 | C7: =B7/input!$C$102 -> 3.5333362 | D7: =B7/$B$10 -> 0.028718694
A8: Packaging | B8: =B28 -> 156.405 | C8: =B8/input!$C$102 -> 1.5 | D8: =B8/$B$10 -> 0.012191889
A9: Freight | B9: =B29 -> 1000 | C9: =B9/input!$C$102 -> 9.5904862 | D9: =B9/$B$10 -> 0.07795076
A10: Total | B10: =SUM(B5:B9) -> 12828.611 | C10: =SUM(C5:C9) -> 123.03262 | D10: =B10/$B$10 -> 1
A12: Material Cost | B12: =SUM(B13:B13) -> 9461.6805 | C12: =SUM(C13:C13) -> 90.742116 | D12: =B12/$B$10 -> 0.73754519
A13: Paper | B13: =material!D44 -> 9461.6805 | C13: =B13/input!$C$102 -> 90.742116 | D13: =B13/$B$10 -> 0.73754519
A15: Conversion Cost | B15: =SUM(B16:B23) -> 1842.1048 | C15: =SUM(C16:C23) -> 17.666681 | D15: =B15/$B$10 -> 0.14359347
A16: Electricity | B16: =conversion!D151 -> 555.70446 | C16: =B16/input!$C$102 -> 5.329476 | D16: =B16/$B$10 -> 0.043317585
A17: Labour-Direct | B17: =conversion!D153 -> 166.47368 | C17: =B17/input!$C$102 -> 1.5965635 | D17: =B17/$B$10 -> 0.01297675
A18: Labour-Indirect | B18: =conversion!E237 -> 299.47405 | C18: =B18/input!$C$102 -> 2.8721018 | D18: =B18/$B$10 -> 0.02334423
A19: Repair & Maintenance | B19: =conversion!D129 -> 73.150838 | C19: =B19/input!$C$102 -> 0.70155211 | D19: =B19/$B$10 -> 0.0057021634
A20: Other Overheads | B20: =conversion!D133 -> 73.150838 | C20: =B20/input!$C$102 -> 0.70155211 | D20: =B20/$B$10 -> 0.0057021634
A21: Lease | B21: =conversion!D241 -> 0 | C21: =B21/input!$C$102 -> 0 | D21: =B21/$B$10 -> 0
A22: Depreciation | B22: =conversion!D115+conversion!E234 -> 230.68784 | C22: =B22/input!$C$102 -> 2.2124086 | D22: =B22/$B$10 -> 0.017982293
A23: Interest | B23: =conversion!D119+conversion!E235+conversion!D263 -> 443.46311 | C23: =B23/input!$C$102 -> 4.2530268 | D23: =B23/$B$10 -> 0.034568286
A25: Margin | B25: =B15*input!C82 -> 368.42096 | C25: =B25/input!$C$102 -> 3.5333362 | D25: =B25/$B$10 -> 0.028718694
A27: Distribution | B27: =SUM(B28:B29) -> 1156.405 | C27: =SUM(C28:C29) -> 11.090486 | D27: =B27/$B$10 -> 0.090142649
A28: Packaging | B28: =conversion!D248 -> 156.405 | C28: =B28/input!$C$102 -> 1.5 | D28: =B28/$B$10 -> 0.012191889
A29: Freight | B29: =conversion!D253 -> 1000 | C29: =B29/input!$C$102 -> 9.5904862 | D29: =B29/$B$10 -> 0.07795076
A31: Process Costing | B31: =B4 -> INR/1000 | C31: =C4 -> EUR/1000 | D31: =D4 -> % of Total Cost | E31: Material | F31: Energy | G31: Labour | H31: Repairs | I31: Other OH | J31: Lease | K31: Depreciation | L31: Interest | M31: Shipping | N31: Margin
A32: Feedstock | B32: =SUM(E32:N32) -> 9539.2766 | C32: =B32/input!$C$102 -> 91.486301 | D32: =B32/$B$36 -> 0.74359386 | E32: =material!D44 -> 9461.6805 | L32: =conversion!D263 -> 64.663441 | N32: =SUM(F32:M32)*input!$C$82 -> 12.932688
A33: Corrugating | B33: =SUM(E33:N33) -> 2132.9296 | C33: =B33/input!$C$102 -> 20.455832 | D33: =B33/$B$36 -> 0.16626349 | F33: =conversion!D151 -> 555.70446 | G33: =conversion!D153+conversion!E237 -> 465.94773 | H33: =conversion!D129 -> 73.150838 | I33: =conversion!D133 -> 73.150838 | J33: =conversion!D241 -> 0 | K33: =conversion!D115+conversion!E234 -> 230.68784 | L33: =conversion!D119+conversion!E235 -> 378.79967 | N33: =SUM(F33:M33)*input!$C$82 -> 355.48827
A34: Dispatch | B34: =SUM(E34:N34) -> 1156.405 | C34: =B34/input!$C$102 -> 11.090486 | D34: =B34/$B$36 -> 0.090142649 | M34: =conversion!D253+conversion!D248 -> 1156.405
B36: =SUM(B32:B34) -> 12828.611 | C36: =SUM(C32:C34) -> 123.03262 | D36: =B36/$B$36 -> 1 | E36: =SUM(E32:E34) -> 9461.6805 | F36: =SUM(F32:F34) -> 555.70446 | G36: =SUM(G32:G34) -> 465.94773 | H36: =SUM(H32:H34) -> 73.150838 | I36: =SUM(I32:I34) -> 73.150838 | J36: =SUM(J32:J34) -> 0 | K36: =SUM(K32:K34) -> 230.68784 | L36: =SUM(L32:L34) -> 443.46311 | ... N36: =SUM(N32:N34) -> 368.42096
B37: =B36-B10 -> 0 | C37: =C36-C10 -> 0 | E37: =E36-B5 -> 0 | F37: =F36-B16 -> 0 | G37: =G36-B17-B18 -> 0 | H37: =H36-B19 -> 0 | I37: =I36-B20 -> 0 | K37: =K36-B22 -> 0 | L37: =L36-B23 -> 0 | M37: =B27-M36 -> 0 | N37: =N36-B25 -> 0

Sheet input
D1: Note | E1: Mandatory field
A2: SKU Description | C2: Lifeboy 125g
A3: SKU Code | C3: xxxxx
A4: Country | C4: India
A5: Currency Symbol | C5: =VLOOKUP($C$4,_xlnm.Database,MATCH($A5,Database!$A$3:$P$3,0),0) -> INR
A6: Supplier | C6: Silvassa
A7: Costing Period | C7: Sep25
A8: Annual Volume | B8: pcs | C8: 4913500
A10: Material Details
A11: Paper Rate
A12: 115 | B12: =input!$C$5&"/kg" -> INR/kg | C12: 42
A13: 180 | B13: =input!$C$5&"/kg" -> INR/kg | C13: 48
A14: Ink Rate | B14: =input!$C$5&"/kg" -> INR/kg | C14: 150
A15: Glue Rate | B15: =input!$C$5&"/kg" -> INR/kg | C15: 50
A17: Specifications
A19: Inner Dimensions
A20: Length | B20: mm | C20: 315
A21: Width | B21: mm | C21: 195
A22: Height | B22: mm | C22: 138
A24: No of Ply | B24: Nos | C24: 3
A25: Flute 1 | B25: Type | C25: B
A26: Flute 2 | B26: Type | C26: C
A28: Construction
A29: K1 | B29: GSM | C29: 180
A30: K1 Type | B30: RCT | C30: HRCT
A31: M1 | B31: GSM | C31: 115
A32: M1 Type | B32: RCT | C32: HRCT
A33: K2 | B33: GSM | C33: 180
A34: K2 Type | B34: RCT | C34: HRCT
A35: M2 | B35: GSM | C35: 115
A36: M2 Type | B36: RCT | C36: HRCT
A37: K3 | B37: GSM | C37: 180
A38: K3 Type | B38: RCT | C38: HRCT
A40: Outer Dimensions
A41: Add Length | B41: mm | C41: 30
A42: Add Width | B42: mm | C42: 15
A44: Printing Method | C44: Flexo | D44: * Please select from Drop down list
A45: No of Colours | C45: 3
A46: Type of Die Cutting | C46: Rotary | D46: * Please select from Drop down list
A48: Machine Details
...

Sheet material
B3: SKU Code | C3: Unit | D3: =_xlfn.XLOOKUP(B3,input!A:A,input!C:C) -> xxxxx
B4: SKU Description | D4: =_xlfn.XLOOKUP(B4,input!A:A,input!C:C) -> Lifeboy 125g
B5: Annual Volume | C5: pcs | D5: =_xlfn.XLOOKUP(B5,input!A:A,input!C:C) -> 4913500
B7: Inner Dimensions
B8: Length | C8: mm | D8: =_xlfn.XLOOKUP(B8,input!A:A,input!C:C) -> 315
B9: Width | C9: mm | D9: =_xlfn.XLOOKUP(B9,input!A:A,input!C:C) -> 195
B10: Height | C10: mm | D10: =_xlfn.XLOOKUP(B10,input!A:A,input!C:C) -> 138
B12: No of Ply | D12: =_xlfn.XLOOKUP(B12,input!A:A,input!C:C) -> 3
B13: Flute 1 | D13: =_xlfn.XLOOKUP(B13,input!A:A,input!C:C) -> B
B14: Flute 2 | D14: =_xlfn.XLOOKUP(B14,input!A:A,input!C:C) -> C
B16: Construction
B17: K1 | C17: GSM | D17: =_xlfn.XLOOKUP(B17,input!A:A,input!C:C) -> 180
B18: M1 | C18: GSM | D18: =_xlfn.XLOOKUP(B18,input!A:A,input!C:C) -> 115
B19: K2 | C19: GSM | D19: =_xlfn.XLOOKUP(B19,input!A:A,input!C:C) -> 180
B20: M2 | C20: GSM | D20: =_xlfn.XLOOKUP(B20,input!A:A,input!C:C) -> 115
B21: K3 | C21: GSM | D21: =_xlfn.XLOOKUP(B21,input!A:A,input!C:C) -> 180
B23: GSM | C23: GSM | D23: =IF($D$12=5,$D$17+$D$18*VLOOKUP($D$13,backup!$B$131:$E$136,COLUMNS(backup!$B$131:$C$131),0)+$D$19+$D$20*VLOOKUP(D14,backup!$B$131:$E$136,COLUMNS(backup!$B$131:$C$131),0)+$D$21,IF($D$12=3,$D$17+$D$18*VLOOKUP(D13,backup!$B$131:$E$136,COLUMNS(backup!$B$131:$C$131),0)+$D$19)) -> 515.25
B25: Add Length | C25: mm | D25: =_xlfn.XLOOKUP(B25,input!A:A,input!C:C) -> 30
B26: Add Width | C26: mm | D26: =_xlfn.XLOOKUP(B26,input!A:A,input!C:C) -> 15
B27: Length Flat Blank | C27: mm | D27: =2*($D$8+$D$9)+D25 -> 1050
B28: Width Flat Blank | C28: mm | D28: =$D$9+$D$10+$D$26 -> 348
B30: Area | C30: SQM | D30: =D27*D28/10^6 -> 0.3654
B32: Weight of layers
B33: K1 | C33: g | D33: =D17*$D$30 -> 65.772
B34: M1 | C34: g | D34: =D18*$D$30*VLOOKUP($D$13,backup!$B$131:$C$136,COLUMNS(backup!$B$131:$C$131),0) -> 56.72835
B35: K2 | C35: g | D35: =D19*$D$30 -> 65.772
B36: M2 | C36: g | D36: =IF(D12=3,0,D20*$D$30*VLOOKUP($D$14,backup!$B$131:$C$136,COLUMNS(backup!$B$131:$C$131),0)) -> 0
B37: K3 | C37: g | D37: =IF(D12=3,0,D21*$D$30) -> 0
B38: Total Weight | C38: g | D38: =SUM(D33:D37) -> 188.27235
B40: Paper Cost | C40: =input!$C$5&" / 1000 pcs" -> INR / 1000 pcs | D40: =_xlfn.XLOOKUP(D17,input!$A:$A,input!$C:$C,0)*material!D33+_xlfn.XLOOKUP(material!D18,input!$A:$A,input!$C:$C,0)*material!D34+_xlfn.XLOOKUP(material!D19,input!$A:$A,input!$C:$C,0)*material!D35+_xlfn.XLOOKUP(D20,input!$A:$A,input!$C:$C,0)*material!D36+_xlfn.XLOOKUP(material!D21,input!$A:$A,input!$C:$C,0)*material!D37 -> 8696.7027
B42: Total Wastage | C42: % | D42: =_xlfn.XLOOKUP($B$42,conversion!$B:$B,conversion!$D:$D,0) -> 0.087961819
B44: Material | C44: =input!$C$5&" / 1000 pcs" -> INR / 1000 pcs | D44: =D40*(1+D42) -> 9461.6805

Sheet conversion
B10: SKU Code | C10: Unit | D10: =_xlfn.XLOOKUP(B10,input!A:A,input!C:C) -> xxxxx
B11: SKU Description | D11: =_xlfn.XLOOKUP(B11,input!A:A,input!C:C) -> Lifeboy 125g
B12: Production
B13: =input!A8 -> Annual Volume | C13: =input!B8 -> pcs | D13: =_xlfn.XLOOKUP($B13,input!$A:$A,input!C:C) -> 4913500
B14: Capacity Required | C14: pcs | D14: =D13/75% -> 6551333.3
B16: Corrugation Line | D16: =_xlfn.XLOOKUP($B16,input!$A:$A,input!$C:$C) -> BHS Eco Line
B17: Machine Width | C17: mm | D17: =_xlfn.XLOOKUP($D$16,backup!$D:$D,backup!$H:$H,0)*1000 -> 1800
B18: Line Speed | C18: Mtr/ Min | D18: =_xlfn.XLOOKUP($D$16,backup!$D:$D,backup!$G:$G,0) -> 150
B20: Flat Size of Corrugate
B21: Length | C21: mm | D21: =material!D27 -> 1050
B22: Width | C22: mm | D22: =material!D28 -> 348
B23: Area of 1 Corrugate | C23: Sq. Mtrs | D23: =D21*D22/10^6 -> 0.3654
B25: Layout (Sheet Margins)
B26: Side Lay-1 | C26: mm | D26: 25
B27: Side Lay-2 | C27: mm | D27: 25
B28: Gripper Margin | C28: mm | D28: 8
B30: Trim Wastage | C30: % | D30: =(D26+D27)/D17 -> 0.027777778
B32: No of Ups per sheet
B33: Widthwise | C33: Nos | D33: =INT((D17-D26-D27)/D22) -> 5
B35: Actual Size to use
B36: Width | C36: mm | D36: =D22*D33 -> 1740
B38: Corrugation Machine Utilised | C38: Hours | D38: =(D50/(D18*input!$C$98)/60)*conversion!D45 -> 143.31042
B39: No of Machines Required | C39: Nos | D39: =D38/input!$C$99 -> 0.01809475
B41: Printing Method | D41: =_xlfn.XLOOKUP(B41,input!$A:$A,input!$C:$C,0) -> Flexo
B42: Printing Machine | D42: =_xlfn.XLOOKUP(B42,input!$A:$A,input!$C:$C,0) -> TCY 6 PA + RDC
B43: Line Speed | C43: Mtr/Min | D43: =VLOOKUP(D42,backup!$D$32:$J$77,COLUMNS(backup!$D$32:$G$32),0) -> 70
B44: No of Colours | C44: Nos | D44: =_xlfn.XLOOKUP(B44,input!$A:$A,input!$C:$C,0) -> 3
B45: No of Print Runs / year | C45: Nos | D45: =_xlfn.XLOOKUP($B$57,input!$A:$A,input!$C:$C,0) -> 12
B46: Average Order Size | C46: Nos | D46: =IFERROR(D13/D45,0) -> 409458.33
B47: Area per Corrugate | C47: Sq/m | D47: =D23 -> 0.3654
B48: Average Run Size | C48: Sq/m | D48: =D46*D47 -> 149616.07
B49: Print Width | C49: mm | D49: =D36 -> 1740
B50: Running Length | C50: Mtrs | D50: =D48*1000/D49 -> 85986.25
B51: Machine Utilised | C51: Hours | D51: =D50/(D43*input!$C$98)/60*conversion!D45 -> 307.09375
B52: No of Machines Required | C52: Nos | D52: =D51/input!$C$99 -> 0.038774463
B54: Set Up
B55: No of Orders / Year | C55: Nos | D55: =_xlfn.XLOOKUP($B55,input!$A:$A,input!C:C) -> #N/A
B56: Average Order Size | C56: Nos | D56: =D13/D55 -> #N/A
B57: No of Set Ups/Year | C57: Nos | D57: =_xlfn.XLOOKUP($B$57,input!$A:$A,input!$C:$C,0) -> 12
B58: Time Required for Set Up | C58: Mins | D58: =_xlfn.XLOOKUP($D44,backup!$B:$B,backup!$E:$E,0) -> 75
...

Sheet backup
B2: Corrugation Facility Area | C2: EBM
B3: Area Type | C3: Recommended Size (SQM) | D3: Notes
B5: IMM Production Hall | C5: =SUMPRODUCT(E33:E77,J33:J77) -> 22.95487 | D5: Including space between machines, operator walkways
B6: Raw Material Storage | C6: =conversion!D176 -> 49.051247 | D6: Silo + bag storage, covered with material loaders, fire safety
B7: Finished Goods Warehouse | C7: =conversion!D193 -> 65.625514 | D7: 3–5 days buffer stock, stacked pallets, racking possible
B8: Tool Room & Mould Storage | C8: =C5*5% -> 1.1477435 | D8: For in-use and spare moulds; includes EOT crane space
B9: QA, Testing & Lab | C9: =C5*1% -> 0.2295487 | D9: QC, testing, documentation
B10: Maintenance + Utility Block | C10: =C5*5% -> 1.1477435 | D10: Compressor, pump room, electrical panels, workshop
B11: Office/Admin Block | C11: =C5*5% -> 1.1477435 | D11: Planning, HR, finance, customer service, etc.
B12: Canteen & Washrooms | C12: =C5*1% -> 0.2295487 | D12: Based on workforce (~150–200 people)
B13: Loading/Unloading Bays | C13: =C5*1% -> 0.2295487 | D13: 5 Bays - Dock-level bays for raw/finished goods
B14: Future Expansion | C14: 5
B15: Total Built Up Area | C15: =SUM(C5:C14) -> 146.76351
B16: FSI | C16: 0.7
B17: Land Area | C17: =C15/C16 -> 209.66215
B19: List of Auxillary Equipments
B20: Equipment List | C20: EUR | D20: =input!A102 -> Euro | E20: =input!C5 -> INR | F20: Purpose | G20: Remarks
B21: Boiler / Thermic Fluid Heater | C21: 100000 | D21: {=_xlfn.XLOOKUP(D20,input!$A5:$A$498,input!$C$5:$C$498)} -> 104.27 | E21: =D21*C21 -> 10427000 | F21: Generates steam for preheaters | G21: Diesel/gas/solid fuel
B22: Air Compressor | C22: 40000 | D22: =D21 -> 104.27 | E22: =D22*C22 -> 4170800 | F22: Pneumatic supply | G22: For auto controls
B23: Glue Preparation Unit | C23: 45000 | D23: =D22 -> 104.27 | E23: =D23*C23 -> 4692150 | F23: Starch-based adhesive preparation
B24: Ink Kitchen / Mixing Unit | C24: 30000 | D24: =D23 -> 104.27 | E24: =D24*C24 -> 3128100 | F24: Ink preparation
B25: Waste & Trim Collection System | C25: 40000 | D25: =D24 -> 104.27 | E25: =D25*C25 -> 4170800 | F25: Dust extraction & paper scrap
B26: Material Handling (Conveyors, Pallet Trucks, Bundlers, Palletizers) | C26: 30000 | D26: =D25 -> 104.27 | E26: =D26*C26 -> 3128100 | F26: Movement of sheets & boxes
B27: Chiller / Water Circulation System | C27: 100000 | D27: =D25 -> 104.27 | E27: =D27*C27 -> 10427000 | F27: For roll cooling | G27: Optional
B28: Panel Cabelling etc | C28: 121506.68 | D28: =D26 -> 104.27 | E28: =D28*C28 -> 12669502 | F28: For roll cooling | G28: Optional
B29: Total Cost | C29: =SUM(C21:C28) -> 506506.68 | E29: =SUM(E21:E28) -> 52813452
B31: Machine Details | F31: Euro
B32: Type | C32: Make | D32: Model | E32: No of Machines | F32: Machine Cost € | G32: Line Speed (Mtr/ Min) | H32: Machine Width (Mtr) | I32: Power Consumption KWH | J32: Machine Footprint SQM | L32: INR Machine Cost
B33: Corrugation Line | C33: BHS | D33: BHS / Fosver | E33: =IFERROR(HLOOKUP($D33,conversion!$D$16:$D$39,ROWS(conversion!$C$16:$C$39),0),0) -> 0 | F33: =1822600.24 -> 1822600.2 | G33: 400 | H33: 2.2 | I33: 340 | J33: 450 | L33: =_xlfn.XLOOKUP($F$31,input!$A:$A,input!C:C)*F33 -> 1.9004253e+08
B34: Corrugation Line | C34: HSIEH HSU | D34: HSIEH HSU | E34: =IFERROR(HLOOKUP($D34,conversion!$D$16:$D$39,ROWS(conversion!$C$16:$C$39),0),0) -> 0 | F34: 1800000 | G34: 250 | H34: 1.8 | I34: 340 | J34: 450 | L34: =_xlfn.XLOOKUP($F$31,input!$A:$A,input!C:C)*F34 -> 187686000
B35: Corrugation Line | C35: TCY | D35: TCY QSS 250 | E35: =IFERROR(HLOOKUP($D35,conversion!$D$16:$D$39,ROWS(conversion!$C$16:$C$39),0),0) -> 0 | F35: 1800000 | G35: 250 | H35: 1.8 | I35: 340 | J35: 450 | L35: =_xlfn.XLOOKUP($F$31,input!$A:$A,input!C:C)*F35 -> 187686000
B36: Corrugation Line | C36: TCY | D36: TCY QSS 300 | E36: =IFERROR(HLOOKUP($D36,conversion!$D$16:$D$39,ROWS(conversion!$C$16:$C$39),0),0) -> 0 | F36: 1800000 | G36: 300 | H36: 1.8 | I36: 340 | J36: 450 | L36: =_xlfn.XLOOKUP($F$31,input!$A:$A,input!C:C)*F36 -> 187686000
B37: Corrugation Line | C37: TCY | D37: TCY QSS 350 | E37: =IFERROR(HLOOKUP($D37,conversion!$D$16:$D$39,ROWS(conversion!$C$16:$C$39),0),0) -> 0 | F37: 1800000 | G37: 350 | H37: 1.8 | I37: 340 | J37: 450 | L37: =_xlfn.XLOOKUP($F$31,input!$A:$A,input!C:C)*F37 -> 187686000
B38: Corrugation Line | C38: BHS | D38: BHS Eco Line | E38: =IFERROR(HLOOKUP($D38,conversion!$D$16:$D$39,ROWS(conversion!$C$16:$C$39),0),0) -> 0.01809475 | F38: 2950000 | G38: 150 | H38: 1.8 | I38: 340 | J38: 450 | L38: =_xlfn.XLOOKUP($F$31,input!$A:$A,input!C:C)*F38 -> 307596500
B39: Corrugation Line | C39: BHS | D39: BHS S line | E39: =IFERROR(HLOOKUP($D39,conversion!$D$16:$D$39,ROWS(conversion!$C$16:$C$39),0),0) -> 0 | F39: 3950000 | G39: 250 | H39: 2.2 | I39: 340 | J39: 450 | L39: =_xlfn.XLOOKUP($F$31,input!$A:$A,input!C:C)*F39 -> 411866500
B40: Corrugation Line | C40: Fosver | D40: Fosver S line | E40: =IFERROR(HLOOKUP($D40,conversion!$D$16:$D$39,ROWS(conversion!$C$16:$C$39),0),0) -> 0 | F40: 4750000 | G40: 370 | H40: 2.4 | I40: 340 | J40: 450 | L40: =_xlfn.XLOOKUP($F$31,input!$A:$A,input!C:C)*F40 -> 495282500
B41: Corrugation Line | C41: Fosver | D41: Fosver Pro Line | E41: =IFERROR(HLOOKUP($D41,conversion!$D$16:$D$39,ROWS(conversion!$C$16:$C$39),0),0) -> 0 | F41: 3950000 | G41: 270 | H41: 2.4 | I41: 340 | J41: 450 | L41: =_xlfn.XLOOKUP($F$31,input!$A:$A,input!C:C)*F41 -> 411866500
B42: Corrugation Line | C42: Mitsubishi | D42: Mitsubishi SH 400 | E42: =IFERROR(HLOOKUP($D42,conversion!$D$16:$D$39,ROWS(conversion!$C$16:$C$39),0),0) -> 0 | F42: 5950000 | G42: 400 | H42: 2.4 | I42: 340 | J42: 450 | L42: =_xlfn.XLOOKUP($F$31,input!$A:$A,input!C:C)*F42 -> 620406500
L43: =_xlfn.XLOOKUP($F$31,input!$A:$A,input!C:C)*F43 -> 0
B44: Printing Machine | C44: TCY | D44: TCY 6 PA + RDC | E44: =IFERROR(HLOOKUP($D44,conversion!$D$42:$D$52,ROWS(conversion!$C$42:$C$52),0),0) -> 0.038774463 | F44: =500000 -> 500000 | G44: 70 | H44: 2.1 | I44: 80 | J44: 150 | L44: =_xlfn.XLOOKUP($F$31,input!$A:$A,input!C:C)*F44 -> 52135000
...

Sheet Database
A1: =SUM(D4:P20)-[1]Database!$A$1 -> 0
D2: kWH | E2: Manpower Cost | J2: per sqm | K2: per sqm | L2: per sqm | O2: Exchange rate with Euro | P2: Exchange rate with USD | W2: KM | X2: 300
A3: Country | B3: Currency | C3: Currency Symbol | D3: Electricity Rate | E3: Skilled Labour | F3: Engineer | G3: Production Manager | H3: Depreciation on P&M | I3: Depreciation on Building | J3: Land Cost | K3: Building Cost | L3: Lease Cost | M3: Interest on Long Term Loan | N3: Interest on Working Capital | O3: Euro | P3: USD | W3: =#REF!/X2 -> #REF!
A4: Argentina | B4: Argentinian Pesos | C4: ARS | D4: {=_xlfn.XLOOKUP( $A4, [1]Database!$A$5:$A$20, _xlfn.XLOOKUP( D$3, [1]Database!$D$4:$T$4, [1]Database!$D$5:$T$20 ) )} -> 129.15 | E4: {=_xlfn.XLOOKUP( $A4, [1]Database!$A$5:$A$20, _xlfn.XLOOKUP( E$3, [1]Database!$D$4:$T$4, [1]Database!$D$5:$T$20 ) )} -> 9792000 | F4: {=_xlfn.XLOOKUP( $A4, [1]Database!$A$5:$A$20, _xlfn.XLOOKUP( F$3, [1]Database!$D$4:$T$4, [1]Database!$D$5:$T$20 ) )} -> 1632000 | G4: {=_xlfn.XLOOKUP( $A4, [1]Database!$A$5:$A$20, _xlfn.XLOOKUP( G$3, [1]Database!$D$4:$T$4, [1]Database!$D$5:$T$20 ) )} -> 13056000 | H4: {=_xlfn.XLOOKUP( $A4, [1]Database!$A$5:$A$20, _xlfn.XLOOKUP( H$3, [1]Database!$D$4:$T$4, [1]Database!$D$5:$T$20 ) )} -> 0.1 | I4: {=_xlfn.XLOOKUP( $A4, [1]Database!$A$5:$A$20, _xlfn.XLOOKUP( I$3, [1]Database!$D$4:$T$4, [1]Database!$D$5:$T$20 ) )} -> 0.02 | J4: {=_xlfn.XLOOKUP( $A4, [1]Database!$A$5:$A$20, _xlfn.XLOOKUP( J$3, [1]Database!$D$4:$T$4, [1]Database!$D$5:$T$20 ) )} -> 194373 | K4: {=_xlfn.XLOOKUP( $A4, [1]Database!$A$5:$A$20, _xlfn.XLOOKUP( K$3, [1]Database!$D$4:$T$4, [1]Database!$D$5:$T$20 ) )} -> 0 | ... P4: {=_xlfn.XLOOKUP( $A4, [1]Database!$A$5:$A$20, _xlfn.XLOOKUP( P$3, [1]Database!$D$4:$T$4, [1]Database!$D$5:$T$20 ) )} -> 1451.24
A5: Brazil | B5: Brazilian Reals | C5: BRL | D5: {=_xlfn.XLOOKUP( $A5, [1]Database!$A$5:$A$20, _xlfn.XLOOKUP( D$3, [1]Database!$D$4:$T$4, [1]Database!$D$5:$T$20 ) )} -> 0.657 | E5: {=_xlfn.XLOOKUP( $A5, [1]Database!$A$5:$A$20, _xlfn.XLOOKUP( E$3, [1]Database!$D$4:$T$4, [1]Database!$D$5:$T$20 ) )} -> 73000 | F5: {=_xlfn.XLOOKUP( $A5, [1]Database!$A$5:$A$20, _xlfn.XLOOKUP( F$3, [1]Database!$D$4:$T$4, [1]Database!$D$5:$T$20 ) )} -> 210240 | G5: {=_xlfn.XLOOKUP( $A5, [1]Database!$A$5:$A$20, _xlfn.XLOOKUP( G$3, [1]Database!$D$4:$T$4, [1]Database!$D$5:$T$20 ) )} -> 315360 | H5: {=_xlfn.XLOOKUP( $A5, [1]Database!$A$5:$A$20, _xlfn.XLOOKUP( H$3, [1]Database!$D$4:$T$4, [1]Database!$D$5:$T$20 ) )} -> 0.1 | I5: {=_xlfn.XLOOKUP( $A5, [1]Database!$A$5:$A$20, _xlfn.XLOOKUP( I$3, [1]Database!$D$4:$T$4, [1]Database!$D$5:$T$20 ) )} -> 0.04 | J5: {=_xlfn.XLOOKUP( $A5, [1]Database!$A$5:$A$20, _xlfn.XLOOKUP( J$3, [1]Database!$D$4:$T$4, [1]Database!$D$5:$T$20 ) )} -> 2533.6 | K5: {=_xlfn.XLOOKUP( $A5, [1]Database!$A$5:$A$20, _xlfn.XLOOKUP( K$3, [1]Database!$D$4:$T$4, [1]Database!$D$5:$T$20 ) )} -> 14843.75 | ... P5: {=_xlfn.XLOOKUP( $A5, [1]Database!$A$5:$A$20, _xlfn.XLOOKUP( P$3, [1]Database!$D$4:$T$4, [1]Database!$D$5:$T$20 ) )} -> 5.37
A6: China | B6: Chinese Yuan | C6: CNY | D6: {=_xlfn.XLOOKUP( $A6, [1]Database!$A$5:$A$20, _xlfn.XLOOKUP( D$3, [1]Database!$D$4:$T$4, [1]Database!$D$5:$T$20 ) )} -> 0.794 | E6: {=_xlfn.XLOOKUP( $A6, [1]Database!$A$5:$A$20, _xlfn.XLOOKUP( E$3, [1]Database!$D$4:$T$4, [1]Database!$D$5:$T$20 ) )} -> 420000 | F6: {=_xlfn.XLOOKUP( $A6, [1]Database!$A$5:$A$20, _xlfn.XLOOKUP( F$3, [1]Database!$D$4:$T$4, [1]Database!$D$5:$T$20 ) )} -> 420000 | G6: {=_xlfn.XLOOKUP( $A6, [1]Database!$A$5:$A$20, _xlfn.XLOOKUP( G$3, [1]Database!$D$4:$T$4, [1]Database!$D$5:$T$20 ) )} -> 487200 | H6: {=_xlfn.XLOOKUP( $A6, [1]Database!$A$5:$A$20, _xlfn.XLOOKUP( H$3, [1]Database!$D$4:$T$4, [1]Database!$D$5:$T$20 ) )} -> 0.1 | I6: {=_xlfn.XLOOKUP( $A6, [1]Database!$A$5:$A$20, _xlfn.XLOOKUP( I$3, [1]Database!$D$4:$T$4, [1]Database!$D$5:$T$20 ) )} -> 0.1 | J6: {=_xlfn.XLOOKUP( $A6, [1]Database!$A$5:$A$20, _xlfn.XLOOKUP( J$3, [1]Database!$D$4:$T$4, [1]Database!$D$5:$T$20 ) )} -> 1228.5 | K6: {=_xlfn.XLOOKUP( $A6, [1]Database!$A$5:$A$20, _xlfn.XLOOKUP( K$3, [1]Database!$D$4:$T$4, [1]Database!$D$5:$T$20 ) )} -> 1056.51 | ... P6: {=_xlfn.XLOOKUP( $A6, [1]Database!$A$5:$A$20, _xlfn.XLOOKUP( P$3, [1]Database!$D$4:$T$4, [1]Database!$D$5:$T$20 ) )} -> 7.11
A7: France | B7: Euros | C7: EUR | D7: {=_xlfn.XLOOKUP( $A7, [1]Database!$A$5:$A$20, _xlfn.XLOOKUP( D$3, [1]Database!$D$4:$T$4, [1]Database!$D$5:$T$20 ) )} -> 0.153 | E7: {=_xlfn.XLOOKUP( $A7, [1]Database!$A$5:$A$20, _xlfn.XLOOKUP( E$3, [1]Database!$D$4:$T$4, [1]Database!$D$5:$T$20 ) )} -> 34800 | F7: {=_xlfn.XLOOKUP( $A7, [1]Database!$A$5:$A$20, _xlfn.XLOOKUP( F$3, [1]Database!$D$4:$T$4, [1]Database!$D$5:$T$20 ) )} -> 71050 | G7: {=_xlfn.XLOOKUP( $A7, [1]Database!$A$5:$A$20, _xlfn.XLOOKUP( G$3, [1]Database!$D$4:$T$4, [1]Database!$D$5:$T$20 ) )} -> 94250 | H7: {=_xlfn.XLOOKUP( $A7, [1]Database!$A$5:$A$20, _xlfn.XLOOKUP( H$3, [1]Database!$D$4:$T$4, [1]Database!$D$5:$T$20 ) )} -> 0.1 | I7: {=_xlfn.XLOOKUP( $A7, [1]Database!$A$5:$A$20, _xlfn.XLOOKUP( I$3, [1]Database!$D$4:$T$4, [1]Database!$D$5:$T$20 ) )} -> 0.1 | J7: {=_xlfn.XLOOKUP( $A7, [1]Database!$A$5:$A$20, _xlfn.XLOOKUP( J$3, [1]Database!$D$4:$T$4, [1]Database!$D$5:$T$20 ) )} -> 0 | K7: {=_xlfn.XLOOKUP( $A7, [1]Database!$A$5:$A$20, _xlfn.XLOOKUP( K$3, [1]Database!$D$4:$T$4, [1]Database!$D$5:$T$20 ) )} -> 0 | ... P7: {=_xlfn.XLOOKUP( $A7, [1]Database!$A$5:$A$20, _xlfn.XLOOKUP( P$3, [1]Database!$D$4:$T$4, [1]Database!$D$5:$T$20 ) )} -> 0.86
A8: Germany | B8: Euros | C8: EUR | D8: {=_xlfn.XLOOKUP( $A8, [1]Database!$A$5:$A$20, _xlfn.XLOOKUP( D$3, [1]Database!$D$4:$T$4, [1]Database!$D$5:$T$20 ) )} -> 0.251 | E8: {=_xlfn.XLOOKUP( $A8, [1]Database!$A$5:$A$20, _xlfn.XLOOKUP( E$3, [1]Database!$D$4:$T$4, [1]Database!$D$5:$T$20 ) )} -> 36000 | F8: {=_xlfn.XLOOKUP( $A8, [1]Database!$A$5:$A$20, _xlfn.XLOOKUP( F$3, [1]Database!$D$4:$T$4, [1]Database!$D$5:$T$20 ) )} -> 75000 | G8: {=_xlfn.XLOOKUP( $A8, [1]Database!$A$5:$A$20, _xlfn.XLOOKUP( G$3, [1]Database!$D$4:$T$4, [1]Database!$D$5:$T$20 ) )} -> 85000 | H8: {=_xlfn.XLOOKUP( $A8, [1]Database!$A$5:$A$20, _xlfn.XLOOKUP( H$3, [1]Database!$D$4:$T$4, [1]Database!$D$5:$T$20 ) )} -> 0.1 | I8: {=_xlfn.XLOOKUP( $A8, [1]Database!$A$5:$A$20, _xlfn.XLOOKUP( I$3, [1]Database!$D$4:$T$4, [1]Database!$D$5:$T$20 ) )} -> 0.1 | J8: {=_xlfn.XLOOKUP( $A8, [1]Database!$A$5:$A$20, _xlfn.XLOOKUP( J$3, [1]Database!$D$4:$T$4, [1]Database!$D$5:$T$20 ) )} -> 0 | K8: {=_xlfn.XLOOKUP( $A8, [1]Database!$A$5:$A$20, _xlfn.XLOOKUP( K$3, [1]Database!$D$4:$T$4, [1]Database!$D$5:$T$20 ) )} -> 0 | ... P8: {=_xlfn.XLOOKUP( $A8, [1]Database!$A$5:$A$20, _xlfn.XLOOKUP( P$3, [1]Database!$D$4:$T$4, [1]Database!$D$5:$T$20 ) )} -> 0.86
A9: Hungary | B9: Hungarian Forints | C9: HUF | D9: {=_xlfn.XLOOKUP( $A9, [1]Database!$A$5:$A$20, _xlfn.XLOOKUP( D$3, [1]Database!$D$4:$T$4, [1]Database!$D$5:$T$20 ) )} -> 92.17 | E9: {=_xlfn.XLOOKUP( $A9, [1]Database!$A$5:$A$20, _xlfn.XLOOKUP( E$3, [1]Database!$D$4:$T$4, [1]Database!$D$5:$T$20 ) )} -> 4476000 | F9: {=_xlfn.XLOOKUP( $A9, [1]Database!$A$5:$A$20, _xlfn.XLOOKUP( F$3, [1]Database!$D$4:$T$4, [1]Database!$D$5:$T$20 ) )} -> 10800000 | G9: {=_xlfn.XLOOKUP( $A9, [1]Database!$A$5:$A$20, _xlfn.XLOOKUP( G$3, [1]Database!$D$4:$T$4, [1]Database!$D$5:$T$20 ) )} -> 16560000 | H9: {=_xlfn.XLOOKUP( $A9, [1]Database!$A$5:$A$20, _xlfn.XLOOKUP( H$3, [1]Database!$D$4:$T$4, [1]Database!$D$5:$T$20 ) )} -> 0.02 | I9: {=_xlfn.XLOOKUP( $A9, [1]Database!$A$5:$A$20, _xlfn.XLOOKUP( I$3, [1]Database!$D$4:$T$4, [1]Database!$D$5:$T$20 ) )} -> 0.145 | J9: {=_xlfn.XLOOKUP( $A9, [1]Database!$A$5:$A$20, _xlfn.XLOOKUP( J$3, [1]Database!$D$4:$T$4, [1]Database!$D$5:$T$20 ) )} -> 0 | K9: {=_xlfn.XLOOKUP( $A9, [1]Database!$A$5:$A$20, _xlfn.XLOOKUP( K$3, [1]Database!$D$4:$T$4, [1]Database!$D$5:$T$20 ) )} -> 0 | ... P9: {=_xlfn.XLOOKUP( $A9, [1]Database!$A$5:$A$20, _xlfn.XLOOKUP( P$3, [1]Database!$D$4:$T$4, [1]Database!$D$5:$T$20 ) )} -> 328.47
A10: India | B10: Indian Rupees | C10: INR | D10: {=_xlfn.XLOOKUP( $A10, [1]Database!$A$5:$A$20, _xlfn.XLOOKUP( D$3, [1]Database!$D$4:$T$4, [1]Database!$D$5:$T$20 ) )} -> 10.72 | E10: {=_xlfn.XLOOKUP( $A10, [1]Database!$A$5:$A$20, _xlfn.XLOOKUP( E$3, [1]Database!$D$4:$T$4, [1]Database!$D$5:$T$20 ) )} -> 541800 | F10: {=_xlfn.XLOOKUP( $A10, [1]Database!$A$5:$A$20, _xlfn.XLOOKUP( F$3, [1]Database!$D$4:$T$4, [1]Database!$D$5:$T$20 ) )} -> 1260000 | G10: {=_xlfn.XLOOKUP( $A10, [1]Database!$A$5:$A$20, _xlfn.XLOOKUP( G$3, [1]Database!$D$4:$T$4, [1]Database!$D$5:$T$20 ) )} -> 1890000 | H10: {=_xlfn.XLOOKUP( $A10, [1]Database!$A$5:$A$20, _xlfn.XLOOKUP( H$3, [1]Database!$D$4:$T$4, [1]Database!$D$5:$T$20 ) )} -> 0.15 | I10: {=_xlfn.XLOOKUP( $A10, [1]Database!$A$5:$A$20, _xlfn.XLOOKUP( I$3, [1]Database!$D$4:$T$4, [1]Database!$D$5:$T$20 ) )} -> 0.1 | J10: {=_xlfn.XLOOKUP( $A10, [1]Database!$A$5:$A$20, _xlfn.XLOOKUP( J$3, [1]Database!$D$4:$T$4, [1]Database!$D$5:$T$20 ) )} -> 23519.019 | K10: {=_xlfn.XLOOKUP( $A10, [1]Database!$A$5:$A$20, _xlfn.XLOOKUP( K$3, [1]Database!$D$4:$T$4, [1]Database!$D$5:$T$20 ) )} -> 7000 | ... P10: {=_xlfn.XLOOKUP( $A10, [1]Database!$A$5:$A$20, _xlfn.XLOOKUP( P$3, [1]Database!$D$4:$T$4, [1]Database!$D$5:$T$20 ) )} -> 87
A11: Indonesia | B11: Indonesian Rupiah | C11: IDR | D11: {=_xlfn.XLOOKUP( $A11, [1]Database!$A$5:$A$20, _xlfn.XLOOKUP( D$3, [1]Database!$D$4:$T$4, [1]Database!$D$5:$T$20 ) )} -> 1114.74 | E11: {=_xlfn.XLOOKUP( $A11, [1]Database!$A$5:$A$20, _xlfn.XLOOKUP( E$3, [1]Database!$D$4:$T$4, [1]Database!$D$5:$T$20 ) )} -> 7332000 | F11: {=_xlfn.XLOOKUP( $A11, [1]Database!$A$5:$A$20, _xlfn.XLOOKUP( F$3, [1]Database!$D$4:$T$4, [1]Database!$D$5:$T$20 ) )} -> 19552000 | G11: {=_xlfn.XLOOKUP( $A11, [1]Database!$A$5:$A$20, _xlfn.XLOOKUP( G$3, [1]Database!$D$4:$T$4, [1]Database!$D$5:$T$20 ) )} -> 24440000 | H11: {=_xlfn.XLOOKUP( $A11, [1]Database!$A$5:$A$20, _xlfn.XLOOKUP( H$3, [1]Database!$D$4:$T$4, [1]Database!$D$5:$T$20 ) )} -> 0.25 | I11: {=_xlfn.XLOOKUP( $A11, [1]Database!$A$5:$A$20, _xlfn.XLOOKUP( I$3, [1]Database!$D$4:$T$4, [1]Database!$D$5:$T$20 ) )} -> 0.1 | J11: {=_xlfn.XLOOKUP( $A11, [1]Database!$A$5:$A$20, _xlfn.XLOOKUP( J$3, [1]Database!$D$4:$T$4, [1]Database!$D$5:$T$20 ) )} -> 1700000 | K11: {=_xlfn.XLOOKUP( $A11, [1]Database!$A$5:$A$20, _xlfn.XLOOKUP( K$3, [1]Database!$D$4:$T$4, [1]Database!$D$5:$T$20 ) )} -> 5500000 | ... P11: {=_xlfn.XLOOKUP( $A11, [1]Database!$A$5:$A$20, _xlfn.XLOOKUP( P$3, [1]Database!$D$4:$T$4, [1]Database!$D$5:$T$20 ) )} -> 16665.3
A12: Mexico | B12: Mexican Pesos | C12: MXN | D12: {=_xlfn.XLOOKUP( $A12, [1]Database!$A$5:$A$20, _xlfn.XLOOKUP( D$3, [1]Database!$D$4:$T$4, [1]Database!$D$5:$T$20 ) )} -> 3.972 | E12: {=_xlfn.XLOOKUP( $A12, [1]Database!$A$5:$A$20, _xlfn.XLOOKUP( E$3, [1]Database!$D$4:$T$4, [1]Database!$D$5:$T$20 ) )} -> 180000 | F12: {=_xlfn.XLOOKUP( $A12, [1]Database!$A$5:$A$20, _xlfn.XLOOKUP( F$3, [1]Database!$D$4:$T$4, [1]Database!$D$5:$T$20 ) )} -> 492000 | G12: {=_xlfn.XLOOKUP( $A12, [1]Database!$A$5:$A$20, _xlfn.XLOOKUP( G$3, [1]Database!$D$4:$T$4, [1]Database!$D$5:$T$20 ) )} -> 852000 | H12: {=_xlfn.XLOOKUP( $A12, [1]Database!$A$5:$A$20, _xlfn.XLOOKUP( H$3, [1]Database!$D$4:$T$4, [1]Database!$D$5:$T$20 ) )} -> 0.1 | I12: {=_xlfn.XLOOKUP( $A12, [1]Database!$A$5:$A$20, _xlfn.XLOOKUP( I$3, [1]Database!$D$4:$T$4, [1]Database!$D$5:$T$20 ) )} -> 0.05 | J12: {=_xlfn.XLOOKUP( $A12, [1]Database!$A$5:$A$20, _xlfn.XLOOKUP( J$3, [1]Database!$D$4:$T$4, [1]Database!$D$5:$T$20 ) )} -> 0 | K12: {=_xlfn.XLOOKUP( $A12, [1]Database!$A$5:$A$20, _xlfn.XLOOKUP( K$3, [1]Database!$D$4:$T$4, [1]Database!$D$5:$T$20 ) )} -> 0 | ... P12: {=_xlfn.XLOOKUP( $A12, [1]Database!$A$5:$A$20, _xlfn.XLOOKUP( P$3, [1]Database!$D$4:$T$4, [1]Database!$D$5:$T$20 ) )} -> 18.32
A13: Pakistan | B13: Pakistani Rupees | C13: PKR | D13: {=_xlfn.XLOOKUP( $A13, [1]Database!$A$5:$A$20, _xlfn.XLOOKUP( D$3, [1]Database!$D$4:$T$4, [1]Database!$D$5:$T$20 ) )} -> 41.99 | E13: {=_xlfn.XLOOKUP( $A13, [1]Database!$A$5:$A$20, _xlfn.XLOOKUP( E$3, [1]Database!$D$4:$T$4, [1]Database!$D$5:$T$20 ) )} -> 504000 | F13: {=_xlfn.XLOOKUP( $A13, [1]Database!$A$5:$A$20, _xlfn.XLOOKUP( F$3, [1]Database!$D$4:$T$4, [1]Database!$D$5:$T$20 ) )} -> 384000 | G13: {=_xlfn.XLOOKUP( $A13, [1]Database!$A$5:$A$20, _xlfn.XLOOKUP( G$3, [1]Database!$D$4:$T$4, [1]Database!$D$5:$T$20 ) )} -> 2400000 | H13: {=_xlfn.XLOOKUP( $A13, [1]Database!$A$5:$A$20, _xlfn.XLOOKUP( H$3, [1]Database!$D$4:$T$4, [1]Database!$D$5:$T$20 ) )} -> 0.15 | I13: {=_xlfn.XLOOKUP( $A13, [1]Database!$A$5:$A$20, _xlfn.XLOOKUP( I$3, [1]Database!$D$4:$T$4, [1]Database!$D$5:$T$20 ) )} -> 0.1 | J13: {=_xlfn.XLOOKUP( $A13, [1]Database!$A$5:$A$20, _xlfn.XLOOKUP( J$3, [1]Database!$D$4:$T$4, [1]Database!$D$5:$T$20 ) )} -> 0 | K13: {=_xlfn.XLOOKUP( $A13, [1]Database!$A$5:$A$20, _xlfn.XLOOKUP( K$3, [1]Database!$D$4:$T$4, [1]Database!$D$5:$T$20 ) )} -> 0 | ... P13: {=_xlfn.XLOOKUP( $A13, [1]Database!$A$5:$A$20, _xlfn.XLOOKUP( P$3, [1]Database!$D$4:$T$4, [1]Database!$D$5:$T$20 ) )} -> 282.99
A14: Philippines | B14: Philippines Pesos | C14: PHP | D14: {=_xlfn.XLOOKUP( $A14, [1]Database!$A$5:$A$20, _xlfn.XLOOKUP( D$3, [1]Database!$D$4:$T$4, [1]Database!$D$5:$T$20 ) )} -> 8.847 | E14: {=_xlfn.XLOOKUP( $A14, [1]Database!$A$5:$A$20, _xlfn.XLOOKUP( E$3, [1]Database!$D$4:$T$4, [1]Database!$D$5:$T$20 ) )} -> 242880 | F14: {=_xlfn.XLOOKUP( $A14, [1]Database!$A$5:$A$20, _xlfn.XLOOKUP( F$3, [1]Database!$D$4:$T$4, [1]Database!$D$5:$T$20 ) )} -> 473470.52 | G14: {=_xlfn.XLOOKUP( $A14, [1]Database!$A$5:$A$20, _xlfn.XLOOKUP( G$3, [1]Database!$D$4:$T$4, [1]Database!$D$5:$T$20 ) )} -> 538167.68 | H14: {=_xlfn.XLOOKUP( $A14, [1]Database!$A$5:$A$20, _xlfn.XLOOKUP( H$3, [1]Database!$D$4:$T$4, [1]Database!$D$5:$T$20 ) )} -> 0.1 | I14: {=_xlfn.XLOOKUP( $A14, [1]Database!$A$5:$A$20, _xlfn.XLOOKUP( I$3, [1]Database!$D$4:$T$4, [1]Database!$D$5:$T$20 ) )} -> 0.1 | J14: {=_xlfn.XLOOKUP( $A14, [1]Database!$A$5:$A$20, _xlfn.XLOOKUP( J$3, [1]Database!$D$4:$T$4, [1]Database!$D$5:$T$20 ) )} -> 16240 | K14: {=_xlfn.XLOOKUP( $A14, [1]Database!$A$5:$A$20, _xlfn.XLOOKUP( K$3, [1]Database!$D$4:$T$4, [1]Database!$D$5:$T$20 ) )} -> 20000 | ... P14: {=_xlfn.XLOOKUP( $A14, [1]Database!$A$5:$A$20, _xlfn.XLOOKUP( P$3, [1]Database!$D$4:$T$4, [1]Database!$D$5:$T$20 ) )} -> 58.89
A15: South Africa | B15: South African Rand | C15: ZAR | D15: {=_xlfn.XLOOKUP( $A15, [1]Database!$A$5:$A$20, _xlfn.XLOOKUP( D$3, [1]Database!$D$4:$T$4, [1]Database!$D$5:$T$20 ) )} -> 1.795 | E15: {=_xlfn.XLOOKUP( $A15, [1]Database!$A$5:$A$20, _xlfn.XLOOKUP( E$3, [1]Database!$D$4:$T$4, [1]Database!$D$5:$T$20 ) )} -> 231858 | F15: {=_xlfn.XLOOKUP( $A15, [1]Database!$A$5:$A$20, _xlfn.XLOOKUP( F$3, [1]Database!$D$4:$T$4, [1]Database!$D$5:$T$20 ) )} -> 494630.4 | G15: {=_xlfn.XLOOKUP( $A15, [1]Database!$A$5:$A$20, _xlfn.XLOOKUP( G$3, [1]Database!$D$4:$T$4, [1]Database!$D$5:$T$20 ) )} -> 772860 | H15: {=_xlfn.XLOOKUP( $A15, [1]Database!$A$5:$A$20, _xlfn.XLOOKUP( H$3, [1]Database!$D$4:$T$4, [1]Database!$D$5:$T$20 ) )} -> 0.2 | I15: {=_xlfn.XLOOKUP( $A15, [1]Database!$A$5:$A$20, _xlfn.XLOOKUP( I$3, [1]Database!$D$4:$T$4, [1]Database!$D$5:$T$20 ) )} -> 0.05 | J15: {=_xlfn.XLOOKUP( $A15, [1]Database!$A$5:$A$20, _xlfn.XLOOKUP( J$3, [1]Database!$D$4:$T$4, [1]Database!$D$5:$T$20 ) )} -> 0 | K15: {=_xlfn.XLOOKUP( $A15, [1]Database!$A$5:$A$20, _xlfn.XLOOKUP( K$3, [1]Database!$D$4:$T$4, [1]Database!$D$5:$T$20 ) )} -> 0 | ... P15: {=_xlfn.XLOOKUP( $A15, [1]Database!$A$5:$A$20, _xlfn.XLOOKUP( P$3, [1]Database!$D$4:$T$4, [1]Database!$D$5:$T$20 ) )} -> 17.13
... A19: Vietnam | B19: Vietnamese Dong | C19: VND | D19: {=_xlfn.XLOOKUP( $A19, [1]Database!$A$5:$A$20, _xlfn.XLOOKUP( D$3, [1]Database!$D$4:$T$4, [1]Database!$D$5:$T$20 ) )} -> 1744 | E19: {=_xlfn.XLOOKUP( $A19, [1]Database!$A$5:$A$20, _xlfn.XLOOKUP( E$3, [1]Database!$D$4:$T$4, [1]Database!$D$5:$T$20 ) )} -> 139920000 | F19: {=_xlfn.XLOOKUP( $A19, [1]Database!$A$5:$A$20, _xlfn.XLOOKUP( F$3, [1]Database!$D$4:$T$4, [1]Database!$D$5:$T$20 ) )} -> 8.2716216e+08 | G19: {=_xlfn.XLOOKUP( $A19, [1]Database!$A$5:$A$20, _xlfn.XLOOKUP( G$3, [1]Database!$D$4:$T$4, [1]Database!$D$5:$T$20 ) )} -> 9.2173476e+08 | H19: {=_xlfn.XLOOKUP( $A19, [1]Database!$A$5:$A$20, _xlfn.XLOOKUP( H$3, [1]Database!$D$4:$T$4, [1]Database!$D$5:$T$20 ) )} -> 0.1 | I19: {=_xlfn.XLOOKUP( $A19, [1]Database!$A$5:$A$20, _xlfn.XLOOKUP( I$3, [1]Database!$D$4:$T$4, [1]Database!$D$5:$T$20 ) )} -> 0.1 | J19: {=_xlfn.XLOOKUP( $A19, [1]Database!$A$5:$A$20, _xlfn.XLOOKUP( J$3, [1]Database!$D$4:$T$4, [1]Database!$D$5:$T$20 ) )} -> 3586051.9 | K19: {=_xlfn.XLOOKUP( $A19, [1]Database!$A$5:$A$20, _xlfn.XLOOKUP( K$3, [1]Database!$D$4:$T$4, [1]Database!$D$5:$T$20 ) )} -> 3403710.2 | ... P19: {=_xlfn.XLOOKUP( $A19, [1]Database!$A$5:$A$20, _xlfn.XLOOKUP( P$3, [1]Database!$D$4:$T$4, [1]Database!$D$5:$T$20 ) )} -> 26369

Sheet logs
A2: Sl No | B2: Date | C2: Cost INR/ TH | D2: Change | E2: Reason
A3: 1 | B3: 17thDec25 | C3: 12884.431
A4: =A3+1 -> 2 | B4: 18thDec25 | C4: 12828.611 | D4: =(C3-C4)/C3 -> 0.004332356 | E4: Change in Land & Building Cost per sq mt & Labour Rate
