Workbook
Name Ancillary: backup!$B$20:$C$39
Name Area_EBM: backup!$B$4:$C$17
Name Dep_Sch_Others: conversion!$A$324:$D$360
Name Depreciation_Schedule: conversion!$A$219:$D$256
Name Interest_Sch_Others: conversion!$A$364:$D$421
Name Interest_Schedule: conversion!$A$260:$D$319
Name Machine_details: backup!$B$1:$H$142
Name Machine_Power: backup!#REF!
Name Machines: backup!$D$42:$K$47
Name SKU_Data: input!$A$9:$C$105

Sheet summary
A1: ="Country "&input!C4 -> Country India | B1: ="Currency "&input!C5 -> Currency INR | C1: ="Supplier "&input!C6 -> Supplier Slivassa
A2: ="Product "&input!C2 -> Product Bottle Mono PE CMT220ml19g W/O MB PCR70% | B2: ="Period "&input!C7 -> Period Sep25 | C2: SKU Code | D2: =input!C3 -> XXXXX
A3: =input!A8&" "&input!B8 -> Annual Volume pcs | B3: =input!C8 -> 62975559 | C3: ="Payment term "&input!C99&" days" -> Payment term 60 days
A4: Details | B4: =input!C5&"/1000" -> INR/1000 | C4: EUR/1000 | D4: % of Total Cost
A5: Material | B5: =B12 -> 1804.9592 | C5: =B5/input!$C$88 -> 17.310436 | D5: =B5/$B$10 -> 0.44507393
A6: Conversion | B6: =B18 -> 1669.3608 | C6: =B6/input!$C$88 -> 16.009981 | D6: =B6/$B$10 -> 0.41163754
A7: Margin | B7: =B28 -> 333.87215 | C7: =B7/input!$C$88 -> 3.2019963 | D7: =B7/$B$10 -> 0.082327508
A8: Packaging | B8: =B31 -> 236.11111 | C8: =B8/input!$C$88 -> 2.2644204 | D8: =B8/$B$10 -> 0.058221206
A9: Freight | B9: =B32 -> 11.111111 | C9: =B9/input!$C$88 -> 0.10656096 | D9: =B9/$B$10 -> 0.0027398215
A10: Total | B10: =SUM(B5:B9) -> 4055.4143 | C10: =SUM(C5:C9) -> 38.893395 | D10: =B10/$B$10 -> 1
A12: Material Cost | B12: =SUM(B13:B15) -> 1804.9592 | C12: =SUM(C13:C15) -> 17.310436 | D12: =B12/$B$10 -> 0.44507393
A13: Resin | B13: =SUMIF(material!$A:$A,summary!A13,material!$D:$D) -> 1647.3029 | C13: =B13/input!$C$88 -> 15.798436 | D13: =B13/$B$10 -> 0.40619843
A14: Masterbatch | B14: =SUMIF(material!$A:$A,summary!A14,material!$D:$D) -> 157.65624 | C14: =B14/input!$C$88 -> 1.512 | D14: =B14/$B$10 -> 0.038875495
A15: UV Additives | B15: =SUMIF(material!$A:$A,summary!A15,material!$D:$D) -> 0 | C15: =B15/input!$C$88 -> 0 | D15: =B15/$B$10 -> 0
A16: Anti-Scratch Coating | B16: =SUMIF(material!$A:$A,summary!A16,material!$D:$D) -> 0 | C16: =B16/input!$C$88 -> 0 | D16: =B16/$B$10 -> 0
A18: Conversion Cost | B18: =SUM(B19:B26) -> 1669.3608 | C18: =SUM(C19:C26) -> 16.009981 | D18: =B18/$B$10 -> 0.41163754
A19: Electricity | B19: =conversion!D91 -> 263.53333 | C19: =B19/input!$C$88 -> 2.5274128 | D19: =B19/$B$10 -> 0.064983085
A20: Labour-Direct | B20: =conversion!D93 -> 74.971591 | C20: =B20/input!$C$88 -> 0.71901401 | D20: =B20/$B$10 -> 0.01848679
A21: Labour-Indirect | B21: =conversion!E189 -> 75.167979 | C21: =B21/input!$C$88 -> 0.72089747 | D21: =B21/$B$10 -> 0.018535216
A22: Repair & Maintenance | B22: =conversion!D74 -> 137.68043 | C22: =B22/input!$C$88 -> 1.3204222 | D22: =B22/$B$10 -> 0.033949781
A23: Other Overheads | B23: =conversion!D78 -> 137.68043 | C23: =B23/input!$C$88 -> 1.3204222 | D23: =B23/$B$10 -> 0.033949781
A24: Lease | B24: =conversion!E188 -> 0 | C24: =B24/input!$C$88 -> 0 | D24: =B24/$B$10 -> 0
A25: Depreciation | B25: =conversion!D60+conversion!E186 -> 414.57034 | C25: =B25/input!$C$88 -> 3.9759311 | D25: =B25/$B$10 -> 0.10222638
A26: Interest | B26: =conversion!D64+conversion!E187+conversion!D217 -> 565.75666 | C26: =B26/input!$C$88 -> 5.4258814 | D26: =B26/$B$10 -> 0.1395065
A28: Margin | B28: =B18*input!C68 -> 333.87215 | C28: =B28/input!$C$88 -> 3.2019963 | D28: =B28/$B$10 -> 0.082327508
A30: Distribution | B30: =SUM(B31:B32) -> 247.22222 | C30: =SUM(C31:C32) -> 2.3709813 | D30: =B30/$B$10 -> 0.060961027
A31: Packgaging | B31: =conversion!D200 -> 236.11111 | C31: =B31/input!$C$88 -> 2.2644204 | D31: =B31/$B$10 -> 0.058221206
A32: Freight | B32: =conversion!D207 -> 11.111111 | C32: =B32/input!$C$88 -> 0.10656096 | D32: =B32/$B$10 -> 0.0027398215
A34: Process Costing | B34: =B4 -> INR/1000 | C34: =C4 -> EUR/1000 | D34: =D4 -> % of Total Cost | E34: Material | F34: Energy | G34: Labour | H34: Repairs | I34: Other OH | J34: Lease | K34: Depreciation | L34: Interest | M34: Shipping | N34: Margin
A35: Feedstock | B35: =SUM(E35:N35) -> 1828.809 | C35: =B35/input!$C$88 -> 17.539168 | D35: =B35/$B$39 -> 0.45095492 | E35: =B13+B14+B15 -> 1804.9592 | L35: =conversion!D217 -> 19.874889 | N35: =SUM(F35:M35)*input!$C$68 -> 3.9749779
A36: Single-step injection stretch blow molding | B36: =SUM(E36:N36) -> 1979.383 | C36: =B36/input!$C$88 -> 18.983246 | D36: =B36/$B$39 -> 0.48808405 | F36: =conversion!D91 -> 263.53333 | G36: =conversion!D93+conversion!E189 -> 150.13957 | H36: =conversion!D74 -> 137.68043 | I36: =conversion!D78 -> 137.68043 | J36: =conversion!E188 -> 0 | K36: =conversion!D60+conversion!E186 -> 414.57034 | L36: =conversion!D64+conversion!E187 -> 545.88177 | N36: =SUM(F36:M36)*input!$C$68 -> 329.89717
A37: Dispatch | B37: =SUM(E37:N37) -> 247.22222 | C37: =B37/input!$C$88 -> 2.3709813 | D37: =B37/$B$39 -> 0.060961027 | M37: =conversion!D200+conversion!D207 -> 247.22222
B39: =SUM(B35:B37) -> 4055.4143 | C39: =SUM(C35:C37) -> 38.893395 | D39: =B39/$B$39 -> 1 | E39: =SUM(E35:E37) -> 1804.9592 | F39: =SUM(F35:F37) -> 263.53333 | G39: =SUM(G35:G37) -> 150.13957 | H39: =SUM(H35:H37) -> 137.68043 | I39: =SUM(I35:I37) -> 137.68043 | J39: =SUM(J35:J37) -> 0 | K39: =SUM(K35:K37) -> 414.57034 | L39: =SUM(L35:L37) -> 565.75666 | ... N39: =SUM(N35:N37) -> 333.87215
B40: =B39-B10 -> 0 | C40: =C39-C10 -> 0 | E40: =E39-B5 -> 0 | F40: =F39-B19 -> 0 | G40: =G39-B20-B21 -> 0 | H40: =H39-B22 -> 0 | I40: =I39-B23 -> 0 | J40: =J39-B24 -> 0 | K40: =K39-B25 -> 0 | L40: =L39-B26 -> 0 | M40: =M39-B30 -> 0 | N40: =N39-B28 -> 0

Sheet input
A2: SKU Description | C2: Bottle Mono PE CMT220ml19g W/O MB PCR70%
A3: SKU Code | C3: XXXXX
A4: Country | C4: India | D4: * Please select from Drop down list
A5: Currency Symbol | C5: =VLOOKUP($C$4,_xlnm.Database,MATCH($A5,Database!$A$3:$P$3,0),0) -> INR
A6: Supplier | C6: Slivassa
A7: Costing Period | C7: Sep25
A8: Annual Volume | B8: pcs | C8: 62975559
A10: Material Details
A11: Weight | B11: g | C11: 17.5
A12: Layer 1 Ratio | B12: % | C12: 0.98
A13: Layer 1 Polymer Type | C13: PET | D13: * Please select from Drop down list
A14: Layer 1 Polymer Grade | C14: B56003
A15: Layer 1 Polymer Rate | B15: =$C$5&"/kg" -> INR/kg | C15: 95
A16: Layer 1 Masterbatch Dosage | B16: % | C16: 0.02
A17: Layer 1 Masterbatch Rate | B17: =$C$5&"/kg" -> INR/kg | C17: =IF(D17=0,VLOOKUP($C$4,_xlnm.Database,MATCH($A17,Database!$A$3:$U$3,0),0),D17) -> 450.4464 | E17: * User may input as required
A18: Layer 1 UV Additive Dosage | B18: % | C18: 0
A19: Layer 1 UV Additive Rate | C19: 0 | E19: * User may input as required
A21: Layer 2 Ratio | B21: % | C21: 0
A22: Layer 2 Regrind Ratio | B22: % | C22: 0
A23: Layer 2 Polymer Type | C23: PET | D23: * Please select from Drop down list
A24: Layer 2 Polymer Grade
A25: Layer 2 Polymer Rate | B25: =$C$5&"/kg" -> INR/kg
A26: Layer 2 Masterbatch Dosage | B26: % | C26: 0
A27: Layer 2 Masterbatch Rate | B27: =$C$5&"/kg" -> INR/kg | C27: 0 | E27: * User may input as required
A28: Layer 2 UV Additive Dosage | B28: % | C28: 0
A29: Layer 2 UV Additive Rate | B29: =$C$5&"/kg" -> INR/kg | C29: 0 | E29: * User may input as required
A31: Anti-Scratch Coating Ratio | B31: % | C31: 0
A32: Anti-Scratch Coating Rate | B32: =$C$5&"/kg" -> INR/kg | C32: 0 | E32: * User may input as required
A34: Manufacturing Process | C34: ISBM 1
A35: Step 1 | C35: Bottle
A36: Mould Cavitation | B36: Nos | C36: 8
A37: Mould Cycle Time | B37: Secs | C37: 16
A38: Machine Model & Tonnage | C38: ASB 70 DPH V4 | D38: * Please select from Drop down list
A39: No of Set Up / Year | B39: Nos | C39: 6
A40: No of Ramp Ups/Year | B40: Nos | C40: 6
A42: Energy
A43: Electricity Rate | B43: =$C$5&"/kWH" -> INR/kWH | C43: =IF(D43=0,VLOOKUP($C$4,_xlnm.Database,MATCH($A43,Database!$A$3:$P$3,0),0),D43) -> 10.72 | E43: * User may input as required
A45: Manpower Cost
A46: Skilled Labour | B46: =$C$5&"/year" -> INR/year | C46: =IF(D46=0,VLOOKUP($C$4,_xlnm.Database,MATCH($A46,Database!$A$3:$P$3,0),0),D46) -> 541800
A47: Engineer | B47: =$C$5&"/year" -> INR/year | C47: =IF(D47=0,VLOOKUP($C$4,_xlnm.Database,MATCH($A47,Database!$A$3:$P$3,0),0),D47) -> 1260000
...

Sheet material
B3: SKU Code | C3: Unit | D3: =_xlfn.XLOOKUP(B3,input!A:A,input!C:C) -> XXXXX
B4: SKU Description | D4: =_xlfn.XLOOKUP(B4,input!A:A,input!C:C) -> Bottle Mono PE CMT220ml19g W/O MB PCR70%
B5: =input!A11 -> Weight | C5: g | D5: =_xlfn.XLOOKUP($B5,input!$A:$A,input!$C:$C) -> 17.5
B7: Layer 1 Ratio | C7: % | D7: =_xlfn.XLOOKUP($B7,input!$A:$A,input!$C:$C) -> 0.98
B8: Layer 1 Polymer Rate | C8: =input!$C$5&"/kg" -> INR/kg | D8: =_xlfn.XLOOKUP($B8,input!$A:$A,input!$C:$C) -> 95
A9: Resin | B9: Layer 1 Resin Cost | C9: =input!$C$5&" / 1000 pcs" -> INR / 1000 pcs | D9: =$D$5*D7*D8 -> 1629.25
B11: Layer 1 Masterbatch Dosage | C11: % | D11: =_xlfn.XLOOKUP($B11,input!$A:$A,input!$C:$C) -> 0.02
B12: Layer 1 Masterbatch Rate | C12: =input!$C$5&"/kg" -> INR/kg | D12: =_xlfn.XLOOKUP($B12,input!$A:$A,input!$C:$C) -> 450.4464
A13: Masterbatch | B13: Layer 1 Masterbatch Cost | C13: =input!$C$5&" / 1000 pcs" -> INR / 1000 pcs | D13: =$D$5*D11*D12 -> 157.65624
B15: Layer 1 UV Additive Dosage | C15: % | D15: =_xlfn.XLOOKUP($B15,input!$A:$A,input!$C:$C) -> 0
B16: Layer 1 UV Additive Rate | C16: =input!$C$5&"/kg" -> INR/kg | D16: =_xlfn.XLOOKUP($B16,input!$A:$A,input!$C:$C) -> 0
A17: UV Additives | B17: Layer 1 UV Additive Cost | C17: =input!$C$5&" / 1000 pcs" -> INR / 1000 pcs | D17: =D9*D11*D15*D16 -> 0
B19: Layer 2 Ratio | C19: % | D19: =_xlfn.XLOOKUP($B19,input!$A:$A,input!$C:$C) -> 0
B20: Layer 2 Polymer Rate | C20: =input!$C$5&"/kg" -> INR/kg | D20: =_xlfn.XLOOKUP($B20,input!$A:$A,input!$C:$C) -> 0
A21: Resin | B21: Layer 2 Resin Cost | C21: =input!$C$5&" / 1000 pcs" -> INR / 1000 pcs | D21: =D13*D15*D19*D20 -> 0
B23: Layer 2 Masterbatch Dosage | C23: % | D23: =_xlfn.XLOOKUP($B23,input!$A:$A,input!$C:$C) -> 0
B24: Layer 2 Masterbatch Rate | C24: =input!$C$5&"/kg" -> INR/kg | D24: =_xlfn.XLOOKUP($B24,input!$A:$A,input!$C:$C) -> 0
A25: Masterbatch | B25: Layer 2 Masterbatch Cost | C25: =input!$C$5&" / 1000 pcs" -> INR / 1000 pcs | D25: =D5*D19*D23*D24 -> 0
B27: Layer 2 UV Additive Dosage | C27: % | D27: =_xlfn.XLOOKUP($B27,input!$A:$A,input!$C:$C) -> 0
B28: Layer 2 UV Additive Rate | C28: =input!$C$5&"/kg" -> INR/kg | D28: =_xlfn.XLOOKUP($B28,input!$A:$A,input!$C:$C) -> 0
A29: UV Additives | B29: Layer 2 UV Additive Cost | C29: =input!$C$5&" / 1000 pcs" -> INR / 1000 pcs | D29: =D5*D19*D27*D28 -> 0
B31: Anti-Scratch Coating Ratio | C31: % | D31: =_xlfn.XLOOKUP($B31,input!$A:$A,input!C:C) -> 0
B32: Anti-Scratch Coating Rate | C32: =input!$C$5&"/kg" -> INR/kg | D32: =_xlfn.XLOOKUP($B32,input!$A:$A,input!$C:$C) -> 0
A33: Material | B33: Anti-Scratch Coating Cost | C33: =input!$C$5&" / 1000 pcs" -> INR / 1000 pcs | D33: =$D$5*D31*D32 -> 0
B36: Preform Wastage | C36: % | D36: =_xlfn.XLOOKUP(B36,conversion!$B:$B,conversion!$D:$D,0) -> 0.010102897
A37: Resin | B37: Preform Wastage | C37: =input!$C$5&" / 1000 pcs" -> INR / 1000 pcs | D37: =SUMIF($C$7:$C$34,$C37,D$7:D$34)*D$36 -> 18.05293
B39: Other Costs
A40: Resin | B40: Label Cost | C40: =input!$C$5&" / 1000 pcs" -> INR / 1000 pcs | D40: =_xlfn.XLOOKUP(B40,input!$A:$A,input!$C:$C,0) -> 0
B42: Material | C42: =input!$C$5&" / 1000 pcs" -> INR / 1000 pcs | D42: =SUMIF($C$7:$C$40,$C42,D$7:D$40) -> 1804.9592

Sheet conversion
D9: 1
B10: SKU Code | C10: Unit | D10: =_xlfn.XLOOKUP(B10,input!$A:$A,input!$C:$C) -> XXXXX
B11: SKU Description | D11: =_xlfn.XLOOKUP(B11,input!A:A,input!C:C) -> Bottle Mono PE CMT220ml19g W/O MB PCR70%
B12: Production
B13: =input!A8 -> Annual Volume | C13: =input!B8 -> pcs | D13: =_xlfn.XLOOKUP($B13,input!$A:$A,input!$C:$C) -> 62975559
B14: Capacity Required | C14: =C13 -> pcs | D14: =D13/75% -> 83967412
D15: Step 1
B16: Manufacturing Process | D16: =_xlfn.XLOOKUP($B16,input!$A:$A,input!$C:$C) -> ISBM 1
B17: Type | D17: =_xlfn.XLOOKUP(D15,input!$A:$A,input!$C:$C,0) -> Bottle
B18: Mould Cavitation | C18: Nos | D18: =_xlfn.XLOOKUP($B18,input!$A:$A,input!$C:$C) -> 8
B19: Mould Cycle Time | C19: Secs | D19: =_xlfn.XLOOKUP($B19,input!$A:$A,input!$C:$C) -> 16
B20: Machine Model & Tonnage | D20: =_xlfn.XLOOKUP($B20,input!$A:$A,input!$C:$C) -> ASB 70 DPH V4
B21: Output / Hour | C21: Nos | D21: =3600/D19*D18 -> 1800
B22: Output / Annum | C22: Nos | D22: =D21*input!$C$85 -> 14256000
B23: Hours Required for Set up | C23: Nos | D23: =D31*D32/60 -> 18
B24: Hours Required for Ramp Up | C24: Nos | D24: =D37*D38/60 -> 4.5
B25: Hours Required for Production | C25: Nos | D25: =D14/D21 -> 46648.562
B26: No of Machines Required | C26: Nos | D26: =ROUNDUP(SUM(D23:D25)/input!$C$85,0) -> 6
B27: Capacity Utilized | C27: % | D27: =D13/(D22*D26) -> 0.73624625
B28: Actual Production Hours / Annum | C28: Hours | D28: =D13/D21 -> 34986.422
B30: Preform Change Over
B31: No of Set Up / Year | C31: Nos | D31: =_xlfn.XLOOKUP($B31,input!$A:$A,input!$C:$C) -> 6
B32: Time Required for Set Up | C32: Mins | D32: 180
B33: No of Component Wasted | C33: Nos | D33: 0
B34: Set Up Wastage | C34: % | D34: 0
B36: Preform Ramp Up
B37: No of Ramp Ups/Year | C37: Nos | D37: =D31 -> 6
B38: Time required Ramp Up | C38: Mins | D38: 45
B39: Machine Speed at Ramp Up | C39: Pcs/ Min | D39: =60/D19*D18*input!$C$84 -> 24
B40: No of Component Wasted at Ramp Up | C40: Nos | D40: =D37*D38*D39 -> 6480
B41: Ramp Up Wastage | C41: % | D41: =IFERROR(D40/$D$13,0) -> 0.00010289706
B43: Core & Cavity Change Over
B44: No of Set Ups/Year | C44: Nos | D44: =D31 -> 6
B45: Time Required for Set Up | C45: Min | D45: =8*60 -> 480
B46: Machine Speed at Set up | C46: Pcs/Min | D46: 0
B47: No of Components Wasted at Set up | C47: Nos | D47: =D44*D45*D46 -> 0
B48: Set Up Wastage | C48: % | D48: =IFERROR(D47/D13,0) -> 0
B50: Burning Loss | C50: % | D50: =IF(D20=0,0,1%) -> 0.01
B51: Preform Wastage | C51: % | D51: =D34+D41+D48+D50 -> 0.010102897
B53: Machine Cost | C53: =input!$C$5 -> INR | D53: =_xlfn.XLOOKUP(D20,backup!$D:$D,backup!$K:$K,0)*$D$26 -> 3.3947392e+08
...

Sheet backup
B2: Preform Facility Area | C2: EBM
B3: Area Type | C3: Recommended Size (SQM) | D3: Notes
C4: India
B5: IMM Production Hall | C5: =conversion!D26*60 -> 360 | D5: Including space between machines, operator walkways
B6: Raw Material Storage | C6: =conversion!D126 -> 170.02375 | D6: Silo + bag storage, covered with material loaders, fire safety
B7: Finished Goods Warehouse | C7: =conversion!D143 -> 109.03303 | D7: 3–5 days buffer stock, stacked pallets, racking possible
B8: Tool Room & Mould Storage | C8: =C5*5% -> 18 | D8: For in-use and spare moulds; includes EOT crane space
B9: QA, Testing & Lab | C9: =C5*1% -> 3.6 | D9: QC, testing, documentation
B10: Maintenance + Utility Block | C10: =C5*5% -> 18 | D10: Compressor, pump room, electrical panels, workshop
B11: Office/Admin Block | C11: =C5*5% -> 18 | D11: Planning, HR, finance, customer service, etc.
B12: Canteen & Washrooms | C12: =C5*1% -> 3.6 | D12: Based on workforce (~150–200 people)
B13: Loading/Unloading Bays | C13: =C5*1% -> 3.6 | D13: 5 Bays - Dock-level bays for raw/finished goods
B14: Future Expansion | C14: 5
B15: Total Built Up Area | C15: =SUM(C5:C14) -> 708.85677
B16: FSI | C16: 0.7
B17: Land Area | C17: =C15/C16 -> 1012.6525
B19: List of Auxillary Equipments
B20: Equipment List | C20: Euro | E20: =E41&" to "&input!C5 -> Euro to INR
B21: No of Machines | C21: =conversion!D26 -> 6
B22: Hopper Dryer | C22: =1200*C21 -> 7200 | E22: =_xlfn.XLOOKUP($C$20,input!$A:$A,input!C:C,0)*C22 -> 750744
B23: Hopper Loader | C23: =2000*C21 -> 12000 | E23: =_xlfn.XLOOKUP($C$20,input!$A:$A,input!C:C,0)*C23 -> 1251240
B24: Industrial Chiller | C24: =10000/10 -> 1000 | D24: * check Volume & change number of chillers needed | E24: =_xlfn.XLOOKUP($C$20,input!$A:$A,input!C:C,0)*C24 -> 104270
B25: Plastic Granulator | C25: =1000/10 -> 100 | E25: =_xlfn.XLOOKUP($C$20,input!$A:$A,input!C:C,0)*C25 -> 10427
B26: Doser Unit | C26: =5000/10 -> 500 | E26: =_xlfn.XLOOKUP($C$20,input!$A:$A,input!C:C,0)*C26 -> 52135
B27: Lab Equipment | C27: =7500/10 -> 750 | E27: =_xlfn.XLOOKUP($C$20,input!$A:$A,input!C:C,0)*C27 -> 78202.5
B28: Forklift | C28: =(500*4)/10 -> 200 | D28: * 4 Numbers | E28: =_xlfn.XLOOKUP($C$20,input!$A:$A,input!C:C,0)*C28 -> 20854
B29: Generator for Power | C29: =15000/10 -> 1500 | D29: * estimate | E29: =_xlfn.XLOOKUP($C$20,input!$A:$A,input!C:C,0)*C29 -> 156405
B30: Water & Air Pipe lines | C30: =10000/10 -> 1000 | D30: * estimate | E30: =_xlfn.XLOOKUP($C$20,input!$A:$A,input!C:C,0)*C30 -> 104270
B31: Stabilizer & Electric connections | C31: =25000/10 -> 2500 | D31: * estimate | E31: =_xlfn.XLOOKUP($C$20,input!$A:$A,input!C:C,0)*C31 -> 260675
B32: Fire Safety Equipment | C32: =25000/10 -> 2500 | D32: * estimate | E32: =_xlfn.XLOOKUP($C$20,input!$A:$A,input!C:C,0)*C32 -> 260675
B33: PLC + HMI + basic sensorization + simple reject + wiring for Spray coating Automation | C33: =60000/10 -> 6000 | E33: =_xlfn.XLOOKUP($C$20,input!$A:$A,input!C:C,0)*C33 -> 625620
B34: Dehumidifier | E34: =_xlfn.XLOOKUP($C$20,input!$A:$A,input!C:C,0)*C34 -> 0
B35: Compressors / Silos / Utilities | E35: =_xlfn.XLOOKUP($C$20,input!$A:$A,input!C:C,0)*C35 -> 0
B36: Supply Chain Capex | C36: 0 | E36: =_xlfn.XLOOKUP($C$20,input!$A:$A,input!C:C,0)*C36 -> 0
B37: Air Conditioning | C37: =(C5)*2350/(1500*0.0929) -> 6071.0441 | D37: * 2350 per 1500 SQFT | E37: =_xlfn.XLOOKUP($C$20,input!$A:$A,input!C:C,0)*C37 -> 633027.77
B38: Contingencies | C38: =SUM(C22:C37)*10% -> 4132.1044 | D38: * contingencies | E38: =_xlfn.XLOOKUP($C$20,input!$A:$A,input!C:C,0)*C38 -> 430854.53
B39: Total Cost | C39: =SUM(C22:C38) -> 45453.149 | E39: =SUM(E22:E38) -> 4739399.8 | G39: =C39*103/10^7 -> 0.46816743
B41: Machine Details | E41: Euro
B42: Type | C42: Make | D42: Model | E42: Machine Cost | F42: Power Consumption KWH | G42: Speed | H42: Machine Footprint SQM | K42: =input!C5&" Machine Cost" -> INR Machine Cost
B43: ISBM 1 | C43: ASB | D43: ASB 70 DPH V4 | E43: =(495000+25000)*(100%+$C$66) -> 542620 | F43: 65 | H43: 40 | K43: =_xlfn.XLOOKUP($E$41,input!$A:$A,input!C:C)*E43 -> 56578987
...

Sheet rational_sheet
B2: Details | C2: Unit | D2: Assumption | E2: Rationale | F2: Source | G2: Screenshot
B3: Financials
B4: Land Area | C4: SQM
B5: Building Area | C5: SQM
B6: Land Cost | C6: ₹/SQM | D6: 14833.58 | E6: - Cost for Industrial land in the area of supplier | F6: Industrial Land for sale in Silvassa | Buy 88+ Industrial Plots in Silvassa | G6: #VALUE! | H6: 2177 SQFT = ₹ 30 lakhs 1 SQFT = ₹ 1378.04 0.0929 SQM = ₹ 1378.04 1 SQM = 1378.04 / 0.0929 = ₹ 14,833.58
B7: Building Cost | C7: ₹/SQM | D7: 36681.16 | E7: - Cost of Constructing Building & Industrial Shed in the area of supplier | F7: Factory for sale in Silvassa | Buy 165+ Industrial Building in Silvassa | G7: #VALUE! | H7: 16140 SQFT = ₹ 5.5cr 1 SQFT = ₹ 3407.68 0.0929 SQM = ₹ 3407.68 1 SQM = 3407.68 / 0.0929 = ₹ 36,681.16
B8: Lease Cost | C8: ₹/SQM | D8: 1560.6 | E8: - Cost of leasing factory Land & Building in area of supplier | F8: Factory for Rent in Silvassa | Rental Factory in Silvassa | G8: #VALUE! | H8: 26900 SQFT = ₹ 39 lakhs 1 SQFT = ₹ 144.98 0.0929 SQM = ₹ 144.98 1 SQM = 144.98 / 0.0929 = ₹ 1,560.60
B9: Type of Premises | E9: Option to select whether factory is leased or owned
B10: Depreciation on Building | C10: % | D10: 0.1 | E10: - As per Income Tax Act - Compensates the company for utilizing the building in production activities & ensures its upkeep. | F10: https://incometaxindia.gov.in/charts%20%20tables/depreciation%20rates.htm
B11: Depreciation on Plant and Machinery | C11: % | D11: 0.15 | E11: - Applied on a reducing balance basis over a period of up to 15 years - Accounts for ongoing wear & tear caused by extreme operating conditions, with certain components requiring replacement every 5 to 10 years | F11: https://incometaxindia.gov.in/charts%20%20tables/depreciation%20rates.htm | G11: #VALUE!
B12: Interest on Long Term Loan | C12: % | D12: 0.1075 | E12: - based on prevailing banking interest rates in the country - Calculated basis Simple Interest - Assumption that all assets & replacements are fully financed through bank loans | F12: Business Loan Interest Rates, Fees & Charges (October 2025) | HDFC Bank | G12: #VALUE!
B13: Interest on Working Capital | C13: % | D13: 0.0925 | E13: - Based on prevailing banking interest rates in the country | F13: Bill Discounting Scheme - NSIC : National Small Industries Corporation Ltd. | G13: #VALUE!
B14: Electricity | C14: ₹/KWH | D14: 7.5 | E14: - Rate assumed for the industrial use as prevalent in the specific area of the country.
B15: Rpair & Maintenance | C15: % | D15: 0.025 | E15: - Regular Maintenance for wear & tear of Machines
B16: Other Overheads | C16: % | D16: 0.025 | E16: - Cover any costs like Administrative costs, Office space, Travel & Logistics, IT, communication, HR & Training Costs, Compliance & Certifications, etc
B18: Manpower Details
B19: Skilled Labour | C19: ₹/ Annum | D19: =360000*128% -> 460800 | E19: Annual Salary + Benefits - Employer’s contributions to Provident Fund(12%) - Employer’s Pension (4.81%) - Bonus - 10% | F19: Machine operator salary in Silvassa, Dadra and Nagar Haveli | G19: #VALUE!
B20: Engineer | C20: ₹/ Annum | D20: =550000*128% -> 704000 | E20: Annual Salary + Benefits - Employer’s contributions to Provident Fund(12%) - Employer’s Pension (4.81%) - Bonus - 10% | F20: Engineer salary in Silvassa, Dadra and Nagar Haveli | G20: #VALUE!
B21: Production Manager | C21: ₹/ Annum | D21: =1800000*128% -> 2304000 | E21: Annual Salary + Benefits - Employer’s contributions to Provident Fund(12%) - Employer’s Pension (4.81%) - Bonus - 10% | F21: Production manager salary in Silvassa, Dadra and Nagar Haveli | G21: #VALUE!
B22: No of Shifts

Sheet Database
A1: =SUM(D4:P20)-[1]Database!$A$1 -> 0
D2: kWH | E2: Manpower Cost | J2: per sqm | K2: per sqm | L2: per sqm | O2: Exchange rate with Euro | P2: Exchange rate with USD | AC2: KM | AD2: 300
A3: Country | B3: Currency | C3: Currency Symbol | D3: Electricity Rate | E3: Skilled Labour | F3: Engineer | G3: Production Manager | H3: Depreciation on P&M | I3: Depreciation on Building | J3: Land Cost | K3: Building Cost | L3: Lease Cost | M3: Interest on Long Term Loan | N3: Interest on Working Capital | O3: Euro | P3: USD | Q3: Layer 1 Masterbatch Rate | R3: Layer 2 Masterbatch Rate | S3: Layer 1 UV Additive Rate | T3: Layer 2 UV Additive Rate | U3: Anti-Scratch Coating Rate | AC3: =#REF!/AD2 -> #REF!
A4: Argentina | B4: Argentinian Pesos | C4: ARS | D4: {=_xlfn.XLOOKUP( $A4, [1]Database!$A$5:$A$20, _xlfn.XLOOKUP( D$3, [1]Database!$D$4:$T$4, [1]Database!$D$5:$T$20 ) )} -> 129.15 | E4: {=_xlfn.XLOOKUP( $A4, [1]Database!$A$5:$A$20, _xlfn.XLOOKUP( E$3, [1]Database!$D$4:$T$4, [1]Database!$D$5:$T$20 ) )} -> 9792000 | F4: {=_xlfn.XLOOKUP( $A4, [1]Database!$A$5:$A$20, _xlfn.XLOOKUP( F$3, [1]Database!$D$4:$T$4, [1]Database!$D$5:$T$20 ) )} -> 1632000 | G4: {=_xlfn.XLOOKUP( $A4, [1]Database!$A$5:$A$20, _xlfn.XLOOKUP( G$3, [1]Database!$D$4:$T$4, [1]Database!$D$5:$T$20 ) )} -> 13056000 | H4: {=_xlfn.XLOOKUP( $A4, [1]Database!$A$5:$A$20, _xlfn.XLOOKUP( H$3, [1]Database!$D$4:$T$4, [1]Database!$D$5:$T$20 ) )} -> 0.1 | I4: {=_xlfn.XLOOKUP( $A4, [1]Database!$A$5:$A$20, _xlfn.XLOOKUP( I$3, [1]Database!$D$4:$T$4, [1]Database!$D$5:$T$20 ) )} -> 0.02 | J4: {=_xlfn.XLOOKUP( $A4, [1]Database!$A$5:$A$20, _xlfn.XLOOKUP( J$3, [1]Database!$D$4:$T$4, [1]Database!$D$5:$T$20 ) )} -> 194373 | K4: {=_xlfn.XLOOKUP( $A4, [1]Database!$A$5:$A$20, _xlfn.XLOOKUP( K$3, [1]Database!$D$4:$T$4, [1]Database!$D$5:$T$20 ) )} -> 0 | ... P4: {=_xlfn.XLOOKUP( $A4, [1]Database!$A$5:$A$20, _xlfn.XLOOKUP( P$3, [1]Database!$D$4:$T$4, [1]Database!$D$5:$T$20 ) )} -> 1451.24 | Q4: =Q$7*$O4 -> 7275.5712 | R4: =R$7*$O4 -> 7275.5712 | S4: =S$7*$O4 -> 4041.984 | T4: =T$7*$O4 -> 4041.984 | U4: =U$7*$O4 -> 0
A5: Brazil | B5: Brazilian Reals | C5: BRL | D5: {=_xlfn.XLOOKUP( $A5, [1]Database!$A$5:$A$20, _xlfn.XLOOKUP( D$3, [1]Database!$D$4:$T$4, [1]Database!$D$5:$T$20 ) )} -> 0.657 | E5: {=_xlfn.XLOOKUP( $A5, [1]Database!$A$5:$A$20, _xlfn.XLOOKUP( E$3, [1]Database!$D$4:$T$4, [1]Database!$D$5:$T$20 ) )} -> 73000 | F5: {=_xlfn.XLOOKUP( $A5, [1]Database!$A$5:$A$20, _xlfn.XLOOKUP( F$3, [1]Database!$D$4:$T$4, [1]Database!$D$5:$T$20 ) )} -> 210240 | G5: {=_xlfn.XLOOKUP( $A5, [1]Database!$A$5:$A$20, _xlfn.XLOOKUP( G$3, [1]Database!$D$4:$T$4, [1]Database!$D$5:$T$20 ) )} -> 315360 | H5: {=_xlfn.XLOOKUP( $A5, [1]Database!$A$5:$A$20, _xlfn.XLOOKUP( H$3, [1]Database!$D$4:$T$4, [1]Database!$D$5:$T$20 ) )} -> 0.1 | I5: {=_xlfn.XLOOKUP( $A5, [1]Database!$A$5:$A$20, _xlfn.XLOOKUP( I$3, [1]Database!$D$4:$T$4, [1]Database!$D$5:$T$20 ) )} -> 0.04 | J5: {=_xlfn.XLOOKUP( $A5, [1]Database!$A$5:$A$20, _xlfn.XLOOKUP( J$3, [1]Database!$D$4:$T$4, [1]Database!$D$5:$T$20 ) )} -> 2533.6 | K5: {=_xlfn.XLOOKUP( $A5, [1]Database!$A$5:$A$20, _xlfn.XLOOKUP( K$3, [1]Database!$D$4:$T$4, [1]Database!$D$5:$T$20 ) )} -> 14843.75 | ... P5: {=_xlfn.XLOOKUP( $A5, [1]Database!$A$5:$A$20, _xlfn.XLOOKUP( P$3, [1]Database!$D$4:$T$4, [1]Database!$D$5:$T$20 ) )} -> 5.37 | Q5: =Q$7*$O5 -> 26.9136 | R5: =R$7*$O5 -> 26.9136 | S5: =S$7*$O5 -> 14.952 | T5: =T$7*$O5 -> 14.952 | U5: =U$7*$O5 -> 0
A6: China | B6: Chinese Yuan | C6: CNY | D6: {=_xlfn.XLOOKUP( $A6, [1]Database!$A$5:$A$20, _xlfn.XLOOKUP( D$3, [1]Database!$D$4:$T$4, [1]Database!$D$5:$T$20 ) )} -> 0.794 | E6: {=_xlfn.XLOOKUP( $A6, [1]Database!$A$5:$A$20, _xlfn.XLOOKUP( E$3, [1]Database!$D$4:$T$4, [1]Database!$D$5:$T$20 ) )} -> 420000 | F6: {=_xlfn.XLOOKUP( $A6, [1]Database!$A$5:$A$20, _xlfn.XLOOKUP( F$3, [1]Database!$D$4:$T$4, [1]Database!$D$5:$T$20 ) )} -> 420000 | G6: {=_xlfn.XLOOKUP( $A6, [1]Database!$A$5:$A$20, _xlfn.XLOOKUP( G$3, [1]Database!$D$4:$T$4, [1]Database!$D$5:$T$20 ) )} -> 487200 | H6: {=_xlfn.XLOOKUP( $A6, [1]Database!$A$5:$A$20, _xlfn.XLOOKUP( H$3, [1]Database!$D$4:$T$4, [1]Database!$D$5:$T$20 ) )} -> 0.1 | I6: {=_xlfn.XLOOKUP( $A6, [1]Database!$A$5:$A$20, _xlfn.XLOOKUP( I$3, [1]Database!$D$4:$T$4, [1]Database!$D$5:$T$20 ) )} -> 0.1 | J6: {=_xlfn.XLOOKUP( $A6, [1]Database!$A$5:$A$20, _xlfn.XLOOKUP( J$3, [1]Database!$D$4:$T$4, [1]Database!$D$5:$T$20 ) )} -> 1228.5 | K6: {=_xlfn.XLOOKUP( $A6, [1]Database!$A$5:$A$20, _xlfn.XLOOKUP( K$3, [1]Database!$D$4:$T$4, [1]Database!$D$5:$T$20 ) )} -> 1056.51 | ... P6: {=_xlfn.XLOOKUP( $A6, [1]Database!$A$5:$A$20, _xlfn.XLOOKUP( P$3, [1]Database!$D$4:$T$4, [1]Database!$D$5:$T$20 ) )} -> 7.11 | Q6: =Q$7*$O6 -> 35.3808 | R6: =R$7*$O6 -> 35.3808 | S6: =S$7*$O6 -> 19.656 | T6: =T$7*$O6 -> 19.656 | U6: =U$7*$O6 -> 0
A7: France | B7: Euros | C7: EUR | D7: {=_xlfn.XLOOKUP( $A7, [1]Database!$A$5:$A$20, _xlfn.XLOOKUP( D$3, [1]Database!$D$4:$T$4, [1]Database!$D$5:$T$20 ) )} -> 0.153 | E7: {=_xlfn.XLOOKUP( $A7, [1]Database!$A$5:$A$20, _xlfn.XLOOKUP( E$3, [1]Database!$D$4:$T$4, [1]Database!$D$5:$T$20 ) )} -> 34800 | F7: {=_xlfn.XLOOKUP( $A7, [1]Database!$A$5:$A$20, _xlfn.XLOOKUP( F$3, [1]Database!$D$4:$T$4, [1]Database!$D$5:$T$20 ) )} -> 71050 | G7: {=_xlfn.XLOOKUP( $A7, [1]Database!$A$5:$A$20, _xlfn.XLOOKUP( G$3, [1]Database!$D$4:$T$4, [1]Database!$D$5:$T$20 ) )} -> 94250 | H7: {=_xlfn.XLOOKUP( $A7, [1]Database!$A$5:$A$20, _xlfn.XLOOKUP( H$3, [1]Database!$D$4:$T$4, [1]Database!$D$5:$T$20 ) )} -> 0.1 | I7: {=_xlfn.XLOOKUP( $A7, [1]Database!$A$5:$A$20, _xlfn.XLOOKUP( I$3, [1]Database!$D$4:$T$4, [1]Database!$D$5:$T$20 ) )} -> 0.1 | J7: {=_xlfn.XLOOKUP( $A7, [1]Database!$A$5:$A$20, _xlfn.XLOOKUP( J$3, [1]Database!$D$4:$T$4, [1]Database!$D$5:$T$20 ) )} -> 0 | K7: {=_xlfn.XLOOKUP( $A7, [1]Database!$A$5:$A$20, _xlfn.XLOOKUP( K$3, [1]Database!$D$4:$T$4, [1]Database!$D$5:$T$20 ) )} -> 0 | ... P7: {=_xlfn.XLOOKUP( $A7, [1]Database!$A$5:$A$20, _xlfn.XLOOKUP( P$3, [1]Database!$D$4:$T$4, [1]Database!$D$5:$T$20 ) )} -> 0.86 | Q7: 4.32 | R7: 4.32 | S7: 2.4 | T7: 2.4
A8: Germany | B8: Euros | C8: EUR | D8: {=_xlfn.XLOOKUP( $A8, [1]Database!$A$5:$A$20, _xlfn.XLOOKUP( D$3, [1]Database!$D$4:$T$4, [1]Database!$D$5:$T$20 ) )} -> 0.251 | E8: {=_xlfn.XLOOKUP( $A8, [1]Database!$A$5:$A$20, _xlfn.XLOOKUP( E$3, [1]Database!$D$4:$T$4, [1]Database!$D$5:$T$20 ) )} -> 36000 | F8: {=_xlfn.XLOOKUP( $A8, [1]Database!$A$5:$A$20, _xlfn.XLOOKUP( F$3, [1]Database!$D$4:$T$4, [1]Database!$D$5:$T$20 ) )} -> 75000 | G8: {=_xlfn.XLOOKUP( $A8, [1]Database!$A$5:$A$20, _xlfn.XLOOKUP( G$3, [1]Database!$D$4:$T$4, [1]Database!$D$5:$T$20 ) )} -> 85000 | H8: {=_xlfn.XLOOKUP( $A8, [1]Database!$A$5:$A$20, _xlfn.XLOOKUP( H$3, [1]Database!$D$4:$T$4, [1]Database!$D$5:$T$20 ) )} -> 0.1 | I8: {=_xlfn.XLOOKUP( $A8, [1]Database!$A$5:$A$20, _xlfn.XLOOKUP( I$3, [1]Database!$D$4:$T$4, [1]Database!$D$5:$T$20 ) )} -> 0.1 | J8: {=_xlfn.XLOOKUP( $A8, [1]Database!$A$5:$A$20, _xlfn.XLOOKUP( J$3, [1]Database!$D$4:$T$4, [1]Database!$D$5:$T$20 ) )} -> 0 | K8: {=_xlfn.XLOOKUP( $A8, [1]Database!$A$5:$A$20, _xlfn.XLOOKUP( K$3, [1]Database!$D$4:$T$4, [1]Database!$D$5:$T$20 ) )} -> 0 | ... P8: {=_xlfn.XLOOKUP( $A8, [1]Database!$A$5:$A$20, _xlfn.XLOOKUP( P$3, [1]Database!$D$4:$T$4, [1]Database!$D$5:$T$20 ) )} -> 0.86 | Q8: =Q$7*$O8 -> 4.32 | R8: =R$7*$O8 -> 4.32 | S8: =S$7*$O8 -> 2.4 | T8: =T$7*$O8 -> 2.4 | U8: =U$7*$O8 -> 0
A9: Hungary | B9: Hungarian Forints | C9: HUF | D9: {=_xlfn.XLOOKUP( $A9, [1]Database!$A$5:$A$20, _xlfn.XLOOKUP( D$3, [1]Database!$D$4:$T$4, [1]Database!$D$5:$T$20 ) )} -> 92.17 | E9: {=_xlfn.XLOOKUP( $A9, [1]Database!$A$5:$A$20, _xlfn.XLOOKUP( E$3, [1]Database!$D$4:$T$4, [1]Database!$D$5:$T$20 ) )} -> 4476000 | F9: {=_xlfn.XLOOKUP( $A9, [1]Database!$A$5:$A$20, _xlfn.XLOOKUP( F$3, [1]Database!$D$4:$T$4, [1]Database!$D$5:$T$20 ) )} -> 10800000 | G9: {=_xlfn.XLOOKUP( $A9, [1]Database!$A$5:$A$20, _xlfn.XLOOKUP( G$3, [1]Database!$D$4:$T$4, [1]Database!$D$5:$T$20 ) )} -> 16560000 | H9: {=_xlfn.XLOOKUP( $A9, [1]Database!$A$5:$A$20, _xlfn.XLOOKUP( H$3, [1]Database!$D$4:$T$4, [1]Database!$D$5:$T$20 ) )} -> 0.02 | I9: {=_xlfn.XLOOKUP( $A9, [1]Database!$A$5:$A$20, _xlfn.XLOOKUP( I$3, [1]Database!$D$4:$T$4, [1]Database!$D$5:$T$20 ) )} -> 0.145 | J9: {=_xlfn.XLOOKUP( $A9, [1]Database!$A$5:$A$20, _xlfn.XLOOKUP( J$3, [1]Database!$D$4:$T$4, [1]Database!$D$5:$T$20 ) )} -> 0 | K9: {=_xlfn.XLOOKUP( $A9, [1]Database!$A$5:$A$20, _xlfn.XLOOKUP( K$3, [1]Database!$D$4:$T$4, [1]Database!$D$5:$T$20 ) )} -> 0 | ... P9: {=_xlfn.XLOOKUP( $A9, [1]Database!$A$5:$A$20, _xlfn.XLOOKUP( P$3, [1]Database!$D$4:$T$4, [1]Database!$D$5:$T$20 ) )} -> 328.47 | Q9: =Q$7*$O9 -> 1646.784 | R9: =R$7*$O9 -> 1646.784 | S9: =S$7*$O9 -> 914.88 | T9: =T$7*$O9 -> 914.88 | U9: =U$7*$O9 -> 0
A10: India | B10: Indian Rupees | C10: INR | D10: {=_xlfn.XLOOKUP( $A10, [1]Database!$A$5:$A$20, _xlfn.XLOOKUP( D$3, [1]Database!$D$4:$T$4, [1]Database!$D$5:$T$20 ) )} -> 10.72 | E10: {=_xlfn.XLOOKUP( $A10, [1]Database!$A$5:$A$20, _xlfn.XLOOKUP( E$3, [1]Database!$D$4:$T$4, [1]Database!$D$5:$T$20 ) )} -> 541800 | F10: {=_xlfn.XLOOKUP( $A10, [1]Database!$A$5:$A$20, _xlfn.XLOOKUP( F$3, [1]Database!$D$4:$T$4, [1]Database!$D$5:$T$20 ) )} -> 1260000 | G10: {=_xlfn.XLOOKUP( $A10, [1]Database!$A$5:$A$20, _xlfn.XLOOKUP( G$3, [1]Database!$D$4:$T$4, [1]Database!$D$5:$T$20 ) )} -> 1890000 | H10: {=_xlfn.XLOOKUP( $A10, [1]Database!$A$5:$A$20, _xlfn.XLOOKUP( H$3, [1]Database!$D$4:$T$4, [1]Database!$D$5:$T$20 ) )} -> 0.15 | I10: {=_xlfn.XLOOKUP( $A10, [1]Database!$A$5:$A$20, _xlfn.XLOOKUP( I$3, [1]Database!$D$4:$T$4, [1]Database!$D$5:$T$20 ) )} -> 0.1 | J10: {=_xlfn.XLOOKUP( $A10, [1]Database!$A$5:$A$20, _xlfn.XLOOKUP( J$3, [1]Database!$D$4:$T$4, [1]Database!$D$5:$T$20 ) )} -> 23519.019 | K10: {=_xlfn.XLOOKUP( $A10, [1]Database!$A$5:$A$20, _xlfn.XLOOKUP( K$3, [1]Database!$D$4:$T$4, [1]Database!$D$5:$T$20 ) )} -> 7000 | ... P10: {=_xlfn.XLOOKUP( $A10, [1]Database!$A$5:$A$20, _xlfn.XLOOKUP( P$3, [1]Database!$D$4:$T$4, [1]Database!$D$5:$T$20 ) )} -> 87 | Q10: =Q$7*$O10 -> 450.4464 | R10: =R$7*$O10 -> 450.4464 | S10: =S$7*$O10 -> 250.248 | T10: =T$7*$O10 -> 250.248 | U10: =U$7*$O10 -> 0
A11: Indonesia | B11: Indonesian Rupiah | C11: IDR | D11: {=_xlfn.XLOOKUP( $A11, [1]Database!$A$5:$A$20, _xlfn.XLOOKUP( D$3, [1]Database!$D$4:$T$4, [1]Database!$D$5:$T$20 ) )} -> 1114.74 | E11: {=_xlfn.XLOOKUP( $A11, [1]Database!$A$5:$A$20, _xlfn.XLOOKUP( E$3, [1]Database!$D$4:$T$4, [1]Database!$D$5:$T$20 ) )} -> 7332000 | F11: {=_xlfn.XLOOKUP( $A11, [1]Database!$A$5:$A$20, _xlfn.XLOOKUP( F$3, [1]Database!$D$4:$T$4, [1]Database!$D$5:$T$20 ) )} -> 19552000 | G11: {=_xlfn.XLOOKUP( $A11, [1]Database!$A$5:$A$20, _xlfn.XLOOKUP( G$3, [1]Database!$D$4:$T$4, [1]Database!$D$5:$T$20 ) )} -> 24440000 | H11: {=_xlfn.XLOOKUP( $A11, [1]Database!$A$5:$A$20, _xlfn.XLOOKUP( H$3, [1]Database!$D$4:$T$4, [1]Database!$D$5:$T$20 ) )} -> 0.25 | I11: {=_xlfn.XLOOKUP( $A11, [1]Database!$A$5:$A$20, _xlfn.XLOOKUP( I$3, [1]Database!$D$4:$T$4, [1]Database!$D$5:$T$20 ) )} -> 0.1 | J11: {=_xlfn.XLOOKUP( $A11, [1]Database!$A$5:$A$20, _xlfn.XLOOKUP( J$3, [1]Database!$D$4:$T$4, [1]Database!$D$5:$T$20 ) )} -> 1700000 | K11: {=_xlfn.XLOOKUP( $A11, [1]Database!$A$5:$A$20, _xlfn.XLOOKUP( K$3, [1]Database!$D$4:$T$4, [1]Database!$D$5:$T$20 ) )} -> 5500000 | ... P11: {=_xlfn.XLOOKUP( $A11, [1]Database!$A$5:$A$20, _xlfn.XLOOKUP( P$3, [1]Database!$D$4:$T$4, [1]Database!$D$5:$T$20 ) )} -> 16665.3 | Q11: =Q$7*$O11 -> 83437.344 | R11: =R$7*$O11 -> 83437.344 | S11: =S$7*$O11 -> 46354.08 | T11: =T$7*$O11 -> 46354.08 | U11: =U$7*$O11 -> 0
A12: Mexico | B12: Mexican Pesos | C12: MXN | D12: {=_xlfn.XLOOKUP( $A12, [1]Database!$A$5:$A$20, _xlfn.XLOOKUP( D$3, [1]Database!$D$4:$T$4, [1]Database!$D$5:$T$20 ) )} -> 3.972 | E12: {=_xlfn.XLOOKUP( $A12, [1]Database!$A$5:$A$20, _xlfn.XLOOKUP( E$3, [1]Database!$D$4:$T$4, [1]Database!$D$5:$T$20 ) )} -> 180000 | F12: {=_xlfn.XLOOKUP( $A12, [1]Database!$A$5:$A$20, _xlfn.XLOOKUP( F$3, [1]Database!$D$4:$T$4, [1]Database!$D$5:$T$20 ) )} -> 492000 | G12: {=_xlfn.XLOOKUP( $A12, [1]Database!$A$5:$A$20, _xlfn.XLOOKUP( G$3, [1]Database!$D$4:$T$4, [1]Database!$D$5:$T$20 ) )} -> 852000 | H12: {=_xlfn.XLOOKUP( $A12, [1]Database!$A$5:$A$20, _xlfn.XLOOKUP( H$3, [1]Database!$D$4:$T$4, [1]Database!$D$5:$T$20 ) )} -> 0.1 | I12: {=_xlfn.XLOOKUP( $A12, [1]Database!$A$5:$A$20, _xlfn.XLOOKUP( I$3, [1]Database!$D$4:$T$4, [1]Database!$D$5:$T$20 ) )} -> 0.05 | J12: {=_xlfn.XLOOKUP( $A12, [1]Database!$A$5:$A$20, _xlfn.XLOOKUP( J$3, [1]Database!$D$4:$T$4, [1]Database!$D$5:$T$20 ) )} -> 0 | K12: {=_xlfn.XLOOKUP( $A12, [1]Database!$A$5:$A$20, _xlfn.XLOOKUP( K$3, [1]Database!$D$4:$T$4, [1]Database!$D$5:$T$20 ) )} -> 0 | ... P12: {=_xlfn.XLOOKUP( $A12, [1]Database!$A$5:$A$20, _xlfn.XLOOKUP( P$3, [1]Database!$D$4:$T$4, [1]Database!$D$5:$T$20 ) )} -> 18.32 | Q12: =Q$7*$O12 -> 91.8432 | R12: =R$7*$O12 -> 91.8432 | S12: =S$7*$O12 -> 51.024 | T12: =T$7*$O12 -> 51.024 | U12: =U$7*$O12 -> 0
A13: Pakistan | B13: Pakistani Rupees | C13: PKR | D13: {=_xlfn.XLOOKUP( $A13, [1]Database!$A$5:$A$20, _xlfn.XLOOKUP( D$3, [1]Database!$D$4:$T$4, [1]Database!$D$5:$T$20 ) )} -> 41.99 | E13: {=_xlfn.XLOOKUP( $A13, [1]Database!$A$5:$A$20, _xlfn.XLOOKUP( E$3, [1]Database!$D$4:$T$4, [1]Database!$D$5:$T$20 ) )} -> 504000 | F13: {=_xlfn.XLOOKUP( $A13, [1]Database!$A$5:$A$20, _xlfn.XLOOKUP( F$3, [1]Database!$D$4:$T$4, [1]Database!$D$5:$T$20 ) )} -> 384000 | G13: {=_xlfn.XLOOKUP( $A13, [1]Database!$A$5:$A$20, _xlfn.XLOOKUP( G$3, [1]Database!$D$4:$T$4, [1]Database!$D$5:$T$20 ) )} -> 2400000 | H13: {=_xlfn.XLOOKUP( $A13, [1]Database!$A$5:$A$20, _xlfn.XLOOKUP( H$3, [1]Database!$D$4:$T$4, [1]Database!$D$5:$T$20 ) )} -> 0.15 | I13: {=_xlfn.XLOOKUP( $A13, [1]Database!$A$5:$A$20, _xlfn.XLOOKUP( I$3, [1]Database!$D$4:$T$4, [1]Database!$D$5:$T$20 ) )} -> 0.1 | J13: {=_xlfn.XLOOKUP( $A13, [1]Database!$A$5:$A$20, _xlfn.XLOOKUP( J$3, [1]Database!$D$4:$T$4, [1]Database!$D$5:$T$20 ) )} -> 0 | K13: {=_xlfn.XLOOKUP( $A13, [1]Database!$A$5:$A$20, _xlfn.XLOOKUP( K$3, [1]Database!$D$4:$T$4, [1]Database!$D$5:$T$20 ) )} -> 0 | ... P13: {=_xlfn.XLOOKUP( $A13, [1]Database!$A$5:$A$20, _xlfn.XLOOKUP( P$3, [1]Database!$D$4:$T$4, [1]Database!$D$5:$T$20 ) )} -> 282.99 | Q13: =Q$7*$O13 -> 1419.2064 | R13: =R$7*$O13 -> 1419.2064 | S13: =S$7*$O13 -> 788.448 | T13: =T$7*$O13 -> 788.448 | U13: =U$7*$O13 -> 0
A14: Philippines | B14: Philippines Pesos | C14: PHP | D14: {=_xlfn.XLOOKUP( $A14, [1]Database!$A$5:$A$20, _xlfn.XLOOKUP( D$3, [1]Database!$D$4:$T$4, [1]Database!$D$5:$T$20 ) )} -> 8.847 | E14: {=_xlfn.XLOOKUP( $A14, [1]Database!$A$5:$A$20, _xlfn.XLOOKUP( E$3, [1]Database!$D$4:$T$4, [1]Database!$D$5:$T$20 ) )} -> 242880 | F14: {=_xlfn.XLOOKUP( $A14, [1]Database!$A$5:$A$20, _xlfn.XLOOKUP( F$3, [1]Database!$D$4:$T$4, [1]Database!$D$5:$T$20 ) )} -> 473470.52 | G14: {=_xlfn.XLOOKUP( $A14, [1]Database!$A$5:$A$20, _xlfn.XLOOKUP( G$3, [1]Database!$D$4:$T$4, [1]Database!$D$5:$T$20 ) )} -> 538167.68 | H14: {=_xlfn.XLOOKUP( $A14, [1]Database!$A$5:$A$20, _xlfn.XLOOKUP( H$3, [1]Database!$D$4:$T$4, [1]Database!$D$5:$T$20 ) )} -> 0.1 | I14: {=_xlfn.XLOOKUP( $A14, [1]Database!$A$5:$A$20, _xlfn.XLOOKUP( I$3, [1]Database!$D$4:$T$4, [1]Database!$D$5:$T$20 ) )} -> 0.1 | J14: {=_xlfn.XLOOKUP( $A14, [1]Database!$A$5:$A$20, _xlfn.XLOOKUP( J$3, [1]Database!$D$4:$T$4, [1]Database!$D$5:$T$20 ) )} -> 16240 | K14: {=_xlfn.XLOOKUP( $A14, [1]Database!$A$5:$A$20, _xlfn.XLOOKUP( K$3, [1]Database!$D$4:$T$4, [1]Database!$D$5:$T$20 ) )} -> 20000 | ... P14: {=_xlfn.XLOOKUP( $A14, [1]Database!$A$5:$A$20, _xlfn.XLOOKUP( P$3, [1]Database!$D$4:$T$4, [1]Database!$D$5:$T$20 ) )} -> 58.89 | Q14: =Q$7*$O14 -> 293.1984 | R14: =R$7*$O14 -> 293.1984 | S14: =S$7*$O14 -> 162.888 | T14: =T$7*$O14 -> 162.888 | U14: =U$7*$O14 -> 0
A15: South Africa | B15: South African Rand | C15: ZAR | D15: {=_xlfn.XLOOKUP( $A15, [1]Database!$A$5:$A$20, _xlfn.XLOOKUP( D$3, [1]Database!$D$4:$T$4, [1]Database!$D$5:$T$20 ) )} -> 1.795 | E15: {=_xlfn.XLOOKUP( $A15, [1]Database!$A$5:$A$20, _xlfn.XLOOKUP( E$3, [1]Database!$D$4:$T$4, [1]Database!$D$5:$T$20 ) )} -> 231858 | F15: {=_xlfn.XLOOKUP( $A15, [1]Database!$A$5:$A$20, _xlfn.XLOOKUP( F$3, [1]Database!$D$4:$T$4, [1]Database!$D$5:$T$20 ) )} -> 494630.4 | G15: {=_xlfn.XLOOKUP( $A15, [1]Database!$A$5:$A$20, _xlfn.XLOOKUP( G$3, [1]Database!$D$4:$T$4, [1]Database!$D$5:$T$20 ) )} -> 772860 | H15: {=_xlfn.XLOOKUP( $A15, [1]Database!$A$5:$A$20, _xlfn.XLOOKUP( H$3, [1]Database!$D$4:$T$4, [1]Database!$D$5:$T$20 ) )} -> 0.2 | I15: {=_xlfn.XLOOKUP( $A15, [1]Database!$A$5:$A$20, _xlfn.XLOOKUP( I$3, [1]Database!$D$4:$T$4, [1]Database!$D$5:$T$20 ) )} -> 0.05 | J15: {=_xlfn.XLOOKUP( $A15, [1]Database!$A$5:$A$20, _xlfn.XLOOKUP( J$3, [1]Database!$D$4:$T$4, [1]Database!$D$5:$T$20 ) )} -> 0 | K15: {=_xlfn.XLOOKUP( $A15, [1]Database!$A$5:$A$20, _xlfn.XLOOKUP( K$3, [1]Database!$D$4:$T$4, [1]Database!$D$5:$T$20 ) )} -> 0 | ... P15: {=_xlfn.XLOOKUP( $A15, [1]Database!$A$5:$A$20, _xlfn.XLOOKUP( P$3, [1]Database!$D$4:$T$4, [1]Database!$D$5:$T$20 ) )} -> 17.13 | Q15: =Q$7*$O15 -> 85.8816 | R15: =R$7*$O15 -> 85.8816 | S15: =S$7*$O15 -> 47.712 | T15: =T$7*$O15 -> 47.712 | U15: =U$7*$O15 -> 0
A16: Turkey | B16: Turkish Lira | C16: TRY | D16: {=_xlfn.XLOOKUP( $A16, [1]Database!$A$5:$A$20, _xlfn.XLOOKUP( D$3, [1]Database!$D$4:$T$4, [1]Database!$D$5:$T$20 ) )} -> 4.35 | E16: {=_xlfn.XLOOKUP( $A16, [1]Database!$A$5:$A$20, _xlfn.XLOOKUP( E$3, [1]Database!$D$4:$T$4, [1]Database!$D$5:$T$20 ) )} -> 281880 | F16: {=_xlfn.XLOOKUP( $A16, [1]Database!$A$5:$A$20, _xlfn.XLOOKUP( F$3, [1]Database!$D$4:$T$4, [1]Database!$D$5:$T$20 ) )} -> 548100 | G16: {=_xlfn.XLOOKUP( $A16, [1]Database!$A$5:$A$20, _xlfn.XLOOKUP( G$3, [1]Database!$D$4:$T$4, [1]Database!$D$5:$T$20 ) )} -> 532440 | H16: {=_xlfn.XLOOKUP( $A16, [1]Database!$A$5:$A$20, _xlfn.XLOOKUP( H$3, [1]Database!$D$4:$T$4, [1]Database!$D$5:$T$20 ) )} -> 0.1 | I16: {=_xlfn.XLOOKUP( $A16, [1]Database!$A$5:$A$20, _xlfn.XLOOKUP( I$3, [1]Database!$D$4:$T$4, [1]Database!$D$5:$T$20 ) )} -> 0.1 | J16: {=_xlfn.XLOOKUP( $A16, [1]Database!$A$5:$A$20, _xlfn.XLOOKUP( J$3, [1]Database!$D$4:$T$4, [1]Database!$D$5:$T$20 ) )} -> 0 | K16: {=_xlfn.XLOOKUP( $A16, [1]Database!$A$5:$A$20, _xlfn.XLOOKUP( K$3, [1]Database!$D$4:$T$4, [1]Database!$D$5:$T$20 ) )} -> 0 | ... P16: {=_xlfn.XLOOKUP( $A16, [1]Database!$A$5:$A$20, _xlfn.XLOOKUP( P$3, [1]Database!$D$4:$T$4, [1]Database!$D$5:$T$20 ) )} -> 42.43 | Q16: =Q$7*$O16 -> 212.9328 | R16: =R$7*$O16 -> 212.9328 | S16: =S$7*$O16 -> 118.296 | T16: =T$7*$O16 -> 118.296 | U16: =U$7*$O16 -> 0
A17: United Kingdom | B17: British Pounds | C17: GBP | D17: {=_xlfn.XLOOKUP( $A17, [1]Database!$A$5:$A$20, _xlfn.XLOOKUP( D$3, [1]Database!$D$4:$T$4, [1]Database!$D$5:$T$20 ) )} -> 0.346 | E17: {=_xlfn.XLOOKUP( $A17, [1]Database!$A$5:$A$20, _xlfn.XLOOKUP( E$3, [1]Database!$D$4:$T$4, [1]Database!$D$5:$T$20 ) )} -> 39900 | F17: {=_xlfn.XLOOKUP( $A17, [1]Database!$A$5:$A$20, _xlfn.XLOOKUP( F$3, [1]Database!$D$4:$T$4, [1]Database!$D$5:$T$20 ) )} -> 57190 | G17: {=_xlfn.XLOOKUP( $A17, [1]Database!$A$5:$A$20, _xlfn.XLOOKUP( G$3, [1]Database!$D$4:$T$4, [1]Database!$D$5:$T$20 ) )} -> 66500 | H17: {=_xlfn.XLOOKUP( $A17, [1]Database!$A$5:$A$20, _xlfn.XLOOKUP( H$3, [1]Database!$D$4:$T$4, [1]Database!$D$5:$T$20 ) )} -> 0.18 | I17: {=_xlfn.XLOOKUP( $A17, [1]Database!$A$5:$A$20, _xlfn.XLOOKUP( I$3, [1]Database!$D$4:$T$4, [1]Database!$D$5:$T$20 ) )} -> 0.03 | J17: {=_xlfn.XLOOKUP( $A17, [1]Database!$A$5:$A$20, _xlfn.XLOOKUP( J$3, [1]Database!$D$4:$T$4, [1]Database!$D$5:$T$20 ) )} -> 0 | K17: {=_xlfn.XLOOKUP( $A17, [1]Database!$A$5:$A$20, _xlfn.XLOOKUP( K$3, [1]Database!$D$4:$T$4, [1]Database!$D$5:$T$20 ) )} -> 0 | ... P17: {=_xlfn.XLOOKUP( $A17, [1]Database!$A$5:$A$20, _xlfn.XLOOKUP( P$3, [1]Database!$D$4:$T$4, [1]Database!$D$5:$T$20 ) )} -> 0.76 | Q17: =Q$7*$O17 -> 3.8016 | R17: =R$7*$O17 -> 3.8016 | S17: =S$7*$O17 -> 2.112 | T17: =T$7*$O17 -> 2.112 | U17: =U$7*$O17 -> 0
A18: United States | B18: U.S. Dollars | C18: USD | D18: {=_xlfn.XLOOKUP( $A18, [1]Database!$A$5:$A$20, _xlfn.XLOOKUP( D$3, [1]Database!$D$4:$T$4, [1]Database!$D$5:$T$20 ) )} -> 0.149 | E18: {=_xlfn.XLOOKUP( $A18, [1]Database!$A$5:$A$20, _xlfn.XLOOKUP( E$3, [1]Database!$D$4:$T$4, [1]Database!$D$5:$T$20 ) )} -> 98250.6 | F18: {=_xlfn.XLOOKUP( $A18, [1]Database!$A$5:$A$20, _xlfn.XLOOKUP( F$3, [1]Database!$D$4:$T$4, [1]Database!$D$5:$T$20 ) )} -> 130993.8 | G18: {=_xlfn.XLOOKUP( $A18, [1]Database!$A$5:$A$20, _xlfn.XLOOKUP( G$3, [1]Database!$D$4:$T$4, [1]Database!$D$5:$T$20 ) )} -> 117125.4 | H18: {=_xlfn.XLOOKUP( $A18, [1]Database!$A$5:$A$20, _xlfn.XLOOKUP( H$3, [1]Database!$D$4:$T$4, [1]Database!$D$5:$T$20 ) )} -> 0.1 | I18: {=_xlfn.XLOOKUP( $A18, [1]Database!$A$5:$A$20, _xlfn.XLOOKUP( I$3, [1]Database!$D$4:$T$4, [1]Database!$D$5:$T$20 ) )} -> 0.1 | J18: {=_xlfn.XLOOKUP( $A18, [1]Database!$A$5:$A$20, _xlfn.XLOOKUP( J$3, [1]Database!$D$4:$T$4, [1]Database!$D$5:$T$20 ) )} -> 2.47 | K18: {=_xlfn.XLOOKUP( $A18, [1]Database!$A$5:$A$20, _xlfn.XLOOKUP( K$3, [1]Database!$D$4:$T$4, [1]Database!$D$5:$T$20 ) )} -> 0 | ... P18: {=_xlfn.XLOOKUP( $A18, [1]Database!$A$5:$A$20, _xlfn.XLOOKUP( P$3, [1]Database!$D$4:$T$4, [1]Database!$D$5:$T$20 ) )} -> 1 | Q18: =Q$7*$O18 -> 5.0112 | R18: =R$7*$O18 -> 5.0112 | S18: =S$7*$O18 -> 2.784 | T18: =T$7*$O18 -> 2.784 | U18: =U$7*$O18 -> 0
A19: Vietnam | B19: Vietnamese Dong | C19: VND | D19: {=_xlfn.XLOOKUP( $A19, [1]Database!$A$5:$A$20, _xlfn.XLOOKUP( D$3, [1]Database!$D$4:$T$4, [1]Database!$D$5:$T$20 ) )} -> 1744 | E19: {=_xlfn.XLOOKUP( $A19, [1]Database!$A$5:$A$20, _xlfn.XLOOKUP( E$3, [1]Database!$D$4:$T$4, [1]Database!$D$5:$T$20 ) )} -> 139920000 | F19: {=_xlfn.XLOOKUP( $A19, [1]Database!$A$5:$A$20, _xlfn.XLOOKUP( F$3, [1]Database!$D$4:$T$4, [1]Database!$D$5:$T$20 ) )} -> 8.2716216e+08 | G19: {=_xlfn.XLOOKUP( $A19, [1]Database!$A$5:$A$20, _xlfn.XLOOKUP( G$3, [1]Database!$D$4:$T$4, [1]Database!$D$5:$T$20 ) )} -> 9.2173476e+08 | H19: {=_xlfn.XLOOKUP( $A19, [1]Database!$A$5:$A$20, _xlfn.XLOOKUP( H$3, [1]Database!$D$4:$T$4, [1]Database!$D$5:$T$20 ) )} -> 0.1 | I19: {=_xlfn.XLOOKUP( $A19, [1]Database!$A$5:$A$20, _xlfn.XLOOKUP( I$3, [1]Database!$D$4:$T$4, [1]Database!$D$5:$T$20 ) )} -> 0.1 | J19: {=_xlfn.XLOOKUP( $A19, [1]Database!$A$5:$A$20, _xlfn.XLOOKUP( J$3, [1]Database!$D$4:$T$4, [1]Database!$D$5:$T$20 ) )} -> 3586051.9 | K19: {=_xlfn.XLOOKUP( $A19, [1]Database!$A$5:$A$20, _xlfn.XLOOKUP( K$3, [1]Database!$D$4:$T$4, [1]Database!$D$5:$T$20 ) )} -> 3403710.2 | ... P19: {=_xlfn.XLOOKUP( $A19, [1]Database!$A$5:$A$20, _xlfn.XLOOKUP( P$3, [1]Database!$D$4:$T$4, [1]Database!$D$5:$T$20 ) )} -> 26369 | Q19: =Q$7*$O19 -> 131285.97 | R19: =R$7*$O19 -> 131285.97 | S19: =S$7*$O19 -> 72936.648 | T19: =T$7*$O19 -> 72936.648 | U19: =U$7*$O19 -> 0

Sheet log
A2: Sl No | B2: Date | C2: Cost INR/ TH | D2: Change | E2: Reason
A3: 1 | B3: 17thDec25 | C3: 4072.4904
A4: =A3+1 -> 2 | B4: 18thDec25 | C4: 4055.4143 | D4: =(C3-C4)/C3 -> 0.0041930303 | E4: Change in Land & Building Cost per sq mt & Labour Rate
