Workbook
Name Ancillary: backup!$B$20:$C$39
Name Area_EBM: backup!$B$4:$C$17
Name Dep_Sch_Others: conversion!$A$301:$D$336
Name Depreciation_Schedule: conversion!$A$199:$D$234
Name Input: 'Input-old'!$A$1:$C$150
Name Interest_Sch_Others: conversion!$A$340:$D$396
Name Interest_Schedule: conversion!$A$239:$D$296
Name Machine_details: backup!$B$1:$H$110
Name Machines: backup!$D$42:$K$52
Name SKU_Data: input!$A$11:$C$126

Sheet summary
A1: ="Country "&input!C4 -> Country India | B1: ="Currency "&input!C5 -> Currency INR | C1: ="Supplier "&input!C6 -> Supplier Silvassa
A2: ="Product "&input!C2 -> Product Comfort 220ml | B2: ="Period "&input!C7 -> Period Sep25 | C2: SKU Code | D2: =input!C3 -> xxxxx
A3: =input!A8&" "&input!B8 -> Annual Volume pcs | B3: =input!C8 -> 62975559 | C3: ="Payment term "&input!C110&" days" -> Payment term 60 days
A4: Details | B4: =input!C5&"/1000" -> INR/1000 | C4: EUR/1000 | D4: % of Total Cost
A5: Material | B5: =B12 -> 2085.3309 | C5: =B5/input!$C$101 -> 19.999337 | D5: =B5/$B$10 -> 0.65461391
A6: Conversion | B6: =B17 -> 710.86325 | C6: =B6/input!$C$101 -> 6.8175242 | D6: =B6/$B$10 -> 0.22314971
A7: Margin | B7: =B27 -> 142.17265 | C7: =B7/input!$C$101 -> 1.3635048 | D7: =B7/$B$10 -> 0.044629942
A8: Packaging | B8: =B30 -> 236.11111 | C8: =B8/input!$C$101 -> 2.2644204 | D8: =B8/$B$10 -> 0.074118511
A9: Freight | B9: =B31 -> 11.111111 | C9: =B9/input!$C$101 -> 0.10656096 | D9: =B9/$B$10 -> 0.0034879299
A10: Total | B10: =SUM(B5:B9) -> 3185.589 | C10: =SUM(C5:C9) -> 30.551347 | D10: =B10/$B$10 -> 1
A12: Material Cost | B12: =SUM(B13:B15) -> 2085.3309 | C12: =SUM(C13:C15) -> 19.999337 | D12: =B12/$B$10 -> 0.65461391
A13: Resin | B13: =SUMIF(material!$A:$A,summary!A13,material!$D:$D) -> 1914.3309 | C13: =B13/input!$C$101 -> 18.359364 | D13: =B13/$B$10 -> 0.60093467
A14: Masterbatch | B14: =SUMIF(material!$A:$A,summary!A14,material!$D:$D) -> 171 | C14: =B14/input!$C$101 -> 1.6399731 | D14: =B14/$B$10 -> 0.053679242
A15: Additives | B15: =SUMIF(material!$A:$A,summary!A15,material!$D:$D) -> 0 | C15: =B15/input!$C$101 -> 0 | D15: =B15/$B$10 -> 0
A17: Conversion Cost | B17: =SUM(B18:B25) -> 710.86325 | C17: =SUM(C18:C25) -> 6.8175242 | D17: =B17/$B$10 -> 0.22314971
A18: Electricity | B18: =conversion!D81 -> 84.941111 | C18: =B18/input!$C$101 -> 0.81462656 | D18: =B18/$B$10 -> 0.026664178
A19: Labour-Direct | B19: =conversion!D83 -> 50.918205 | C19: =B19/input!$C$101 -> 0.48833035 | D19: =B19/$B$10 -> 0.015983922
A20: Labour-Indirect | B20: =conversion!E167 -> 51.689015 | C20: =B20/input!$C$101 -> 0.49572279 | D20: =B20/$B$10 -> 0.01622589
A21: Repair & Maintenance | B21: =conversion!D65 -> 55.020108 | C21: =B21/input!$C$101 -> 0.52766959 | D21: =B21/$B$10 -> 0.017271565
A22: Other Overheads | B22: =conversion!D69 -> 55.020108 | C22: =B22/input!$C$101 -> 0.52766959 | D22: =B22/$B$10 -> 0.017271565
A23: Lease | B23: =conversion!D171 -> 0 | C23: =B23/input!$C$101 -> 0 | D23: =B23/$B$10 -> 0
A24: Depreciation | B24: =conversion!D49+conversion!E164 -> 167.08589 | C24: =B24/input!$C$101 -> 1.6024349 | D24: =B24/$B$10 -> 0.052450548
A25: Interest | B25: =conversion!D53+conversion!E165+conversion!D196 -> 246.18882 | C25: =B25/input!$C$101 -> 2.3610705 | D25: =B25/$B$10 -> 0.07728204
A27: Margin | B27: =B17*input!C77 -> 142.17265 | C27: =B27/input!$C$101 -> 1.3635048 | D27: =B27/$B$10 -> 0.044629942
A29: Distribution | B29: =SUM(B30:B31) -> 247.22222 | C29: =SUM(C30:C31) -> 2.3709813 | D29: =B29/$B$10 -> 0.077606441
A30: Packgaging | B30: =conversion!D179 -> 236.11111 | C30: =B30/input!$C$101 -> 2.2644204 | D30: =B30/$B$10 -> 0.074118511
A31: Freight | B31: =conversion!D186 -> 11.111111 | C31: =B31/input!$C$101 -> 0.10656096 | D31: =B31/$B$10 -> 0.0034879299
A33: Process Costing | B33: =B4 -> INR/1000 | C33: =C4 -> EUR/1000 | D33: =D4 -> % of Total Cost | E33: Material | F33: Energy | G33: Labour | H33: Repairs | I33: Other OH | J33: Lease | K33: Depreciation | L33: Interest | M33: Shipping | N33: Margin
A34: Feedstock | B34: =SUM(E34:N34) -> 2104.5256 | C34: =B34/input!$C$101 -> 20.183424 | D34: =B34/$B$38 -> 0.66063942 | E34: =B13+B14+B15 -> 2085.3309 | L34: =conversion!D196 -> 15.995662 | N34: =SUM(F34:M34)*input!$C$77 -> 3.1991325
A35: Extrusion | B35: =SUM(E35:N35) -> 833.84111 | C35: =B35/input!$C$101 -> 7.9969417 | D35: =B35/$B$38 -> 0.26175414 | F35: =conversion!D81 -> 84.941111 | G35: =conversion!D83+conversion!E167 -> 102.60722 | H35: =conversion!D65 -> 55.020108 | I35: =conversion!D69 -> 55.020108 | J35: =conversion!D171 -> 0 | K35: =conversion!D49+conversion!E164 -> 167.08589 | L35: =conversion!D53+conversion!E165 -> 230.19315 | N35: =SUM(F35:M35)*input!$C$77 -> 138.97352
A36: Dispatch | B36: =SUM(E36:N36) -> 247.22222 | C36: =B36/input!$C$101 -> 2.3709813 | D36: =B36/$B$38 -> 0.077606441 | M36: =conversion!D186+conversion!D179 -> 247.22222
B38: =SUM(B34:B36) -> 3185.589 | C38: =SUM(C34:C36) -> 30.551347 | D38: =B38/$B$38 -> 1 | E38: =SUM(E34:E36) -> 2085.3309 | F38: =SUM(F34:F36) -> 84.941111 | G38: =SUM(G34:G36) -> 102.60722 | H38: =SUM(H34:H36) -> 55.020108 | I38: =SUM(I34:I36) -> 55.020108 | J38: =SUM(J34:J36) -> 0 | K38: =SUM(K34:K36) -> 167.08589 | L38: =SUM(L34:L36) -> 246.18882 | ... N38: =SUM(N34:N36) -> 142.17265
B39: =B38-B10 -> 0 | C39: =C38-C10 -> 0 | E39: =E38-B5 -> 0 | F39: =F38-B18 -> 0 | G39: =G38-B19-B20 -> 0 | H39: =H38-B21 -> 0 | I39: =I38-B22 -> 0 | K39: =K38-B24 -> 0 | L39: =L38-B25 -> 0 | M39: =B29-M38 -> 0 | N39: =N38-B27 -> 0

Sheet Summary-old
B1: PLM | C1: Description | D1: Model Type | E1: Model | F1: Time Period | I1: Legend
I2: User Inputs (Can Change)
I3: Calculated / Formula (Cannot Change)
C4: Country
C5: Currency | E5: ₹
C7: Final Cost | D7: =$E$5&"/kg" -> ₹/kg
C9: Annual Volume | D9: Mn Pcs
B11: Final Cost Breakdown | C11: Material Cost | D11: =$E$5&"/kg" -> ₹/kg | E11: =material!D53 -> 2085.3309
C12: Conversion Cost | D12: =$E$5&"/kg" -> ₹/kg | E12: =conversion!D87 -> 738.0306
C13: Margin | D13: =$E$5&"/kg" -> ₹/kg
B16: Conversion Cost Breakdown | C16: Labour | D16: =$E$5&"/kg" -> ₹/kg
C17: Energy | D17: =$E$5&"/kg" -> ₹/kg | E17: =conversion!D81 -> 84.941111
C18: Overheads | D18: =$E$5&"/kg" -> ₹/kg
C19: Depreciation | D19: =$E$5&"/kg" -> ₹/kg | E19: =conversion!D49 -> 163.70879
C20: Margin | D20: =$E$5&"/kg" -> ₹/kg
B22: Material Cost & Scrap | C22: Direct Materials | D22: =$E$5&"/kg" -> ₹/kg | E22: =E11-E23 -> 2053.9
C23: Scrap | D23: =$E$5&"/kg" -> ₹/kg | E23: =material!D48 -> 31.430852
B24: Material Cost Breakdown | C24: Resin | D24: =$E$5&"/kg" -> ₹/kg | E24: =material!D9 -> 866.4
C25: Masterbatch | D25: =$E$5&"/kg" -> ₹/kg | E25: =material!D13 -> 171
C26: Additives | D26: =$E$5&"/kg" -> ₹/kg | E26: =material!D17 -> 0
C27: Wastage | D27: =$E$5&"/kg" -> ₹/kg

Sheet input
D1: Note
A2: SKU Description | C2: Comfort 220ml
A3: SKU Code | C3: xxxxx
A4: Country | C4: India | D4: * Please select from Drop down list
A5: Currency Symbol | C5: =VLOOKUP($C$4,_xlnm.Database,MATCH($A5,Database!$A$3:$P$3,0),0) -> INR
A6: Supplier | C6: Silvassa
A7: Costing Period | C7: Sep25
A8: Annual Volume | B8: pcs | C8: 62975559
A12: Material Details
A13: Weight | B13: g | C13: 19
A14: Layer 1 Ratio | B14: % | C14: 0.48
A15: Layer 1 Polymer Type | C15: HDPE | D15: * Please select from Drop down list
A16: Layer 1 Polymer Grade | C16: B56003
A17: Layer 1 Polymer Rate | B17: =$C$5&"/kg" -> INR/kg | C17: 95
A18: Layer 1 Masterbatch Dosage | B18: % | C18: 0.02
A19: Layer 1 Masterbatch Rate | B19: =$C$5&"/kg" -> INR/kg | C19: =IF(D19=0,VLOOKUP($C$4,_xlnm.Database,MATCH($A19,Database!$A$3:$V$3,0),0),D19) -> 450 | E19: * User may input as required
A20: Layer 1 Additive Dosage | B20: % | C20: 0
A21: Layer 1 Additive Rate | C21: 0 | E21: * User may input as required
A23: Layer 2 Ratio | B23: % | C23: 0.5
A24: Layer 2 Regrind Ratio | B24: %
A25: Layer 2 Polymer Type | C25: rHDPE | D25: * Please select from Drop down list
A26: Layer 2 Polymer Grade
A27: Layer 2 Polymer Rate | B27: =$C$5&"/kg" -> INR/kg | C27: 107
A28: Layer 2 Masterbatch Dosage | B28: % | C28: 0
A29: Layer 2 Masterbatch Rate | B29: =$C$5&"/kg" -> INR/kg | C29: 0 | E29: * User may input as required
A30: Layer 2 Additive Dosage | B30: % | C30: 0
A31: Layer 2 Additive Rate | C31: 0 | E31: * User may input as required
A33: Layer 3 Ratio | B33: % | C33: 0
A34: Layer 3 Polymer Type | C34: HDPE | D34: * Please select from Drop down list
A35: Layer 3 Polymer Grade
A36: Layer 3 Polymer Rate | C36: 0
A37: Layer 3 Masterbatch Dosage | B37: % | C37: 0
A38: Layer 3 Masterbatch Rate | C38: 0 | E38: * User may input as required
A39: Layer 3 Additive Dosage | B39: % | C39: 0
A40: Layer 3 Additive Rate | C40: 0 | E40: * User may input as required
A42: Regrind Ratio | B42: % | C42: 0
A44: Mould
A45: Mould Cavitation | B45: Nos | C45: 12
A46: Mould Cycle Time | B46: Secs | C46: 16.3
A47: Machine Model & Tonnage | C47: Jomar 65 | D47: * Please select from Drop down list
...

Sheet material
B3: SKU Code | C3: Unit | D3: =_xlfn.XLOOKUP(B3,input!A:A,input!C:C) -> xxxxx
B4: SKU Description | D4: =_xlfn.XLOOKUP(B4,input!A:A,input!C:C) -> Comfort 220ml
B5: =input!A13 -> Weight | C5: g | D5: =_xlfn.XLOOKUP($B5,input!$A:$A,input!C:C) -> 19
B7: Layer 1 Ratio | C7: % | D7: =_xlfn.XLOOKUP($B7,input!$A:$A,input!C:C) -> 0.48
B8: Layer 1 Polymer Rate | C8: =input!$C$5&"/kg" -> INR/kg | D8: =_xlfn.XLOOKUP($B8,input!$A:$A,input!C:C) -> 95
A9: =summary!$A$13 -> Resin | B9: Layer 1 Resin Cost | C9: =input!$C$5&" / 1000 pcs" -> INR / 1000 pcs | D9: =$D$5*D7*D8 -> 866.4
B11: Layer 1 Masterbatch Dosage | C11: % | D11: =_xlfn.XLOOKUP($B11,input!$A:$A,input!C:C) -> 0.02
B12: Layer 1 Masterbatch Rate | C12: =input!$C$5&"/kg" -> INR/kg | D12: =_xlfn.XLOOKUP($B12,input!$A:$A,input!C:C) -> 450
A13: =summary!$A$14 -> Masterbatch | B13: Layer 1 Masterbatch Cost | C13: =input!$C$5&" / 1000 pcs" -> INR / 1000 pcs | D13: =$D$5*D11*D12 -> 171
B15: Layer 1 Additive Dosage | C15: % | D15: =_xlfn.XLOOKUP($B15,input!$A:$A,input!C:C) -> 0
B16: Layer 1 Additive Rate | C16: =input!$C$5&"/kg" -> INR/kg | D16: =_xlfn.XLOOKUP($B16,input!$A:$A,input!C:C) -> 0
A17: =summary!$A$15 -> Additives | B17: Layer 1 Additive Cost | C17: =input!$C$5&" / 1000 pcs" -> INR / 1000 pcs | D17: =D9*D11*D15*D16 -> 0
B19: Layer 2 Ratio | C19: % | D19: =_xlfn.XLOOKUP($B19,input!$A:$A,input!C:C) -> 0.5
B20: Layer 2 Polymer Rate | C20: =input!$C$5&"/kg" -> INR/kg | D20: =_xlfn.XLOOKUP($B20,input!$A:$A,input!C:C) -> 107
A21: =summary!$A$13 -> Resin | B21: Layer 2 Resin Cost | C21: =input!$C$5&" / 1000 pcs" -> INR / 1000 pcs | D21: =$D$5*D19*D20 -> 1016.5
B23: Regrind Ratio | C23: % | D23: =_xlfn.XLOOKUP($B23,input!$A:$A,input!C:C) -> 0
B24: Regrind Polymer Rate | C24: =input!$C$5&"/kg" -> INR/kg | D24: =regrind!D54 -> 139.22688
A25: =summary!$A$13 -> Resin | B25: Regrind Resin Cost | C25: =input!$C$5&" / 1000 pcs" -> INR / 1000 pcs | D25: =$D$5*D23*D24*(100%-D27-D31) -> 0
B27: Layer 2 Masterbatch Dosage | C27: % | D27: =_xlfn.XLOOKUP($B27,input!$A:$A,input!C:C) -> 0
B28: Layer 2 Masterbatch Rate | C28: =input!$C$5&"/kg" -> INR/kg | D28: =_xlfn.XLOOKUP($B28,input!$A:$A,input!C:C) -> 0
A29: =summary!$A$14 -> Masterbatch | B29: Layer 2 Masterbatch Cost | C29: =input!$C$5&" / 1000 pcs" -> INR / 1000 pcs | D29: =D5*D19*D27*D28 -> 0
B31: Layer 2 Additive Dosage | C31: % | D31: =_xlfn.XLOOKUP($B31,input!$A:$A,input!C:C) -> 0
B32: Layer 2 Additive Rate | C32: =input!$C$5&"/kg" -> INR/kg | D32: =_xlfn.XLOOKUP($B32,input!$A:$A,input!C:C) -> 0
A33: =summary!$A$15 -> Additives | B33: Layer 2 Additive Cost | C33: =input!$C$5&" / 1000 pcs" -> INR / 1000 pcs | D33: =D5*D19*D31*D32 -> 0
B35: Layer 3 Ratio | C35: % | D35: =_xlfn.XLOOKUP($B35,input!$A:$A,input!C:C) -> 0
B36: Layer 3 Polymer Rate | C36: =input!$C$5&"/kg" -> INR/kg | D36: =_xlfn.XLOOKUP($B36,input!$A:$A,input!C:C) -> 0
A37: =summary!$A$13 -> Resin | B37: Layer 3 Resin Cost | C37: =input!$C$5&" / 1000 pcs" -> INR / 1000 pcs | D37: =D5*D35*D36*(100%-D39-D43) -> 0
B39: Layer 3 Masterbatch Dosage | C39: % | D39: =_xlfn.XLOOKUP($B39,input!$A:$A,input!C:C) -> 0
B40: Layer 3 Masterbatch Rate | C40: =input!$C$5&"/kg" -> INR/kg | D40: =_xlfn.XLOOKUP($B40,input!$A:$A,input!C:C) -> 0
A41: =summary!$A$14 -> Masterbatch | B41: Layer 3 Masterbatch Cost | C41: =input!$C$5&" / 1000 pcs" -> INR / 1000 pcs | D41: =D5*D35*D39*D40 -> 0
B43: Layer 3 Additive Dosage | C43: % | D43: =_xlfn.XLOOKUP($B43,input!$A:$A,input!C:C) -> 0
B44: Layer 3 Additive Rate | C44: =input!$C$5&"/kg" -> INR/kg | D44: =_xlfn.XLOOKUP($B44,input!$A:$A,input!C:C) -> 0
A45: =summary!$A$15 -> Additives | B45: Layer 3 Additive Cost | C45: =input!$C$5&" / 1000 pcs" -> INR / 1000 pcs | D45: =D5*D35*D43*D44 -> 0
B47: Wastage | C47: % | D47: =_xlfn.XLOOKUP(B47,conversion!$B:$B,conversion!$D:$D,0) -> 0.01530301
A48: =summary!$A$13 -> Resin | B48: Wastage | C48: =input!$C$5&" / 1000 pcs" -> INR / 1000 pcs | D48: =SUMIF($C$7:$C$45,$C48,D$7:D$45)*D$47 -> 31.430852
B50: Other Costs
A51: =summary!$A$13 -> Resin | B51: Label Cost | C51: =input!$C$5&" / 1000 pcs" -> INR / 1000 pcs
B53: Material | C53: =input!$C$5&" / 1000 pcs" -> INR / 1000 pcs | D53: =SUMIF($C$7:$C$51,$C53,D$7:D$51) -> 2085.3309

Sheet Input-old
A2: SKU Code | B2: 1
A3: SKU Description | B3: Comfort 220ml
A4: Country | B4: India
A5: Currency | B5: INR
A6: Supplier
A7: Costing Period
A8: Annual Volume (Tons) | B8: 62975559
A10: Material
A11: Resin | B11: =$B$5&" /Kg" -> INR /Kg | C11: 95 | D11: * Bale + Local Freight
A12: Masterbatch | B12: =$B$5&" /Kg" -> INR /Kg | C12: 450
A13: Additives | B13: =$B$5&" /Kg" -> INR /Kg | C13: 0
A15: Energy
A16: Electricity | B16: =$B$5&" /KWH" -> INR /KWH | C16: 7.5
A18: Manpower Cost
A19: Skilled Labour | B19: =$B$5&" /Annum" -> INR /Annum | C19: 460800
A20: Engineer | B20: =$B$5&" /Annum" -> INR /Annum | C20: 704000
A21: Production Manager | B21: =$B$5&" /Annum" -> INR /Annum | C21: 2304000
A22: No of Shifts | C22: 3
A24: Overheads
A25: Repairs | B25: Machine Value | C25: 0.02
A26: Other Overheads | B26: Machine Value | C26: 0.02
A27: Depreciation | B27: % | C27: 0.15 | D27: How is your depreciatioin being calculated
A28: Completed Life of Asset | B28: Years | C28: 5
A29: Depreciation on Building | B29: % | C29: 0.1
A31: Land Cost | B31: =$B$5&" /SQM" -> INR /SQM | C31: 14833.58
A32: Building Cost | B32: =$B$5&" /SQM" -> INR /SQM | C32: 36681.16 | D32: * Pre-Engineered Buildings (PEB)
A33: Lease Cost | B33: =$B$5&" /SQM" -> INR /SQM | C33: 1560.6
A34: Type of Premises | C34: Owned
A36: Financials
A37: Interest on Long Term Loan | B37: % | C37: 0.1075
A38: Interest on Working Capital | B38: % | C38: 0.0925
A39: Margin | B39: % | C39: 0.2
A40: LT Debt - Equity Ratio | B40: %
A42: Packing
A43: Woven Sack | B43: =$B$5 -> INR
A44: Weight per Box | B44: kg
A45: Packing Cost | B45: =$B$5&" /Kg" -> INR /Kg | C45: =C43/C44 -> #DIV/0!
A47: Logistics
A48: Container Type | C48: 22 Feet Container
A49: Weight per container | B49: kg
...

Sheet regrind
B3: SKU Code | C3: Unit | D3: =_xlfn.XLOOKUP(B3,input!A:A,input!C:C) -> xxxxx
B4: SKU Description | D4: =_xlfn.XLOOKUP(B4,input!A:A,input!C:C) -> Comfort 220ml
B5: Weight | C5: g | D5: =_xlfn.XLOOKUP(B5,input!A:A,input!C:C) -> 19
B7: Layer 1 Ratio | C7: % | D7: =_xlfn.XLOOKUP(B7,input!A:A,input!C:C) -> 0.48
B8: Layer 1 Polymer Rate | C8: =input!$C$5&"/kg" -> INR/kg | D8: =_xlfn.XLOOKUP(B8,input!A:A,input!C:C) -> 95
A9: Material | B9: Layer 1 Resin Cost | C9: =input!$C$5&" / 1000 pcs" -> INR / 1000 pcs | D9: =D5*D7*D8*(100%-D11-D15) -> 849.072
B11: Layer 1 Masterbatch Dosage | C11: % | D11: =_xlfn.XLOOKUP(B11,input!A:A,input!C:C) -> 0.02
B12: Layer 1 Masterbatch Rate | C12: =input!$C$5&"/kg" -> INR/kg | D12: =_xlfn.XLOOKUP(B12,input!A:A,input!C:C) -> 450
A13: Material | B13: Layer 1 Masterbatch Cost | C13: =input!$C$5&" / 1000 pcs" -> INR / 1000 pcs | D13: =D5*D7*D11*D12 -> 82.08
B15: Layer 1 Additive Dosage | C15: % | D15: =_xlfn.XLOOKUP(B15,input!A:A,input!C:C) -> 0
B16: Layer 1 Additive Rate | C16: =input!$C$5&"/kg" -> INR/kg | D16: =_xlfn.XLOOKUP(B16,input!A:A,input!C:C) -> 0
A17: Material | B17: Layer 1 Additive Cost | C17: =input!$C$5&" / 1000 pcs" -> INR / 1000 pcs | D17: =D5*D7*D15 -> 0
B19: Layer 2 Ratio | C19: % | D19: =_xlfn.XLOOKUP(B19,input!A:A,input!C:C) -> 0.5
B20: Layer 2 Polymer Rate | C20: =input!$C$5&"/kg" -> INR/kg | D20: =_xlfn.XLOOKUP(B20,input!A:A,input!C:C) -> 107
A21: Material | B21: Layer 2 Resin Cost | C21: =input!$C$5&" / 1000 pcs" -> INR / 1000 pcs | D21: =D5*D19*D20*(100%-D23-D27) -> 1016.5
B23: Layer 2 Masterbatch Dosage | C23: % | D23: =_xlfn.XLOOKUP(B23,input!A:A,input!C:C) -> 0
B24: Layer 2 Masterbatch Rate | C24: =input!$C$5&"/kg" -> INR/kg | D24: =_xlfn.XLOOKUP(B24,input!A:A,input!C:C) -> 0
A25: Material | B25: Layer 2 Masterbatch Cost | C25: =input!$C$5&" / 1000 pcs" -> INR / 1000 pcs | D25: =D5*D19*D23*D24 -> 0
B27: Layer 2 Additive Dosage | C27: % | D27: =_xlfn.XLOOKUP(B27,input!A:A,input!C:C) -> 0
B28: Layer 2 Additive Rate | C28: =input!$C$5&"/kg" -> INR/kg | D28: =_xlfn.XLOOKUP(B28,input!A:A,input!C:C) -> 0
A29: Material | B29: Layer 2 Additive Cost | C29: =input!$C$5&" / 1000 pcs" -> INR / 1000 pcs | D29: =D5*D19*D27*D28 -> 0
B31: Layer 3 Ratio | C31: % | D31: =_xlfn.XLOOKUP(B31,input!A:A,input!C:C) -> 0
B32: Layer 3 Polymer Rate | C32: =input!$C$5&"/kg" -> INR/kg | D32: =_xlfn.XLOOKUP(B32,input!A:A,input!C:C) -> 0
A33: Material | B33: Layer 3 Resin Cost | C33: =input!$C$5&" / 1000 pcs" -> INR / 1000 pcs | D33: =D5*D31*D32*(100%-D35-D39) -> 0
B35: Layer 3 Masterbatch Dosage | C35: % | D35: =_xlfn.XLOOKUP(B35,input!A:A,input!C:C) -> 0
B36: Layer 3 Masterbatch Rate | C36: =input!$C$5&"/kg" -> INR/kg | D36: =_xlfn.XLOOKUP(B36,input!A:A,input!C:C) -> 0
A37: Material | B37: Layer 3 Masterbatch Cost | C37: =input!$C$5&" / 1000 pcs" -> INR / 1000 pcs | D37: =D5*D31*D35*D36 -> 0
B39: Layer 3 Additive Dosage | C39: % | D39: =_xlfn.XLOOKUP(B39,input!A:A,input!C:C) -> 0
B40: Layer 3 Additive Rate | C40: =input!$C$5&"/kg" -> INR/kg | D40: =_xlfn.XLOOKUP(B40,input!A:A,input!C:C) -> 0
A41: Material | B41: Layer 3 Additive Cost | C41: =input!$C$5&" / 1000 pcs" -> INR / 1000 pcs | D41: =D5*D31*D39*D40 -> 0
B43: Wastage | C43: %
A44: Material | B44: Wastage | C44: =input!$C$5&" / 1000 pcs" -> INR / 1000 pcs | D44: =SUMIF($C$7:$C$41,$C44,D$7:D$41)*D$43 -> 0
B46: Other Costs
A47: Material | B47: Label Cost | C47: =input!$C$5&" / 1000 pcs" -> INR / 1000 pcs
B49: Material | C49: =input!$C$5&" / 1000 pcs" -> INR / 1000 pcs | D49: =SUMIF($A$7:$A$47,$B49,D$7:D$47) -> 1947.652
B51: Conversion Cost | C51: =input!$C$5&" / 1000 pcs" -> INR / 1000 pcs | D51: =SUM(conversion!D49,conversion!D53,conversion!D65,conversion!D69,conversion!D81,conversion!D83,conversion!D85) -> 697.65864
B53: Regrind Cost | C53: =input!$C$5&" / 1000 pcs" -> INR / 1000 pcs | D53: =SUM(D49:D51) -> 2645.3106
B54: Regrind Cost | C54: =input!$C$5&"/kg" -> INR/kg | D54: =D53/D5 -> 139.22688

Sheet conversion
B10: SKU Code | C10: Unit | D10: =_xlfn.XLOOKUP(B10,input!A:A,input!C:C) -> xxxxx
B11: SKU Description | D11: =_xlfn.XLOOKUP(B11,input!A:A,input!C:C) -> Comfort 220ml
B12: Production
B13: =input!A8 -> Annual Volume | C13: =input!B8 -> pcs | D13: =_xlfn.XLOOKUP($B13,input!$A:$A,input!C:C) -> 62975559
B14: Capacity Required | C14: =C13 -> pcs | D14: =D13/75% -> 83967412
B16: Mould Cavitation | C16: Nos | D16: =_xlfn.XLOOKUP($B16,input!$A:$A,input!C:C) -> 12
B17: Mould Cycle Time | C17: Secs | D17: =_xlfn.XLOOKUP($B17,input!$A:$A,input!C:C) -> 16.3
B18: Machine Model & Tonnage | D18: =_xlfn.XLOOKUP($B18,input!$A:$A,input!C:C) -> Jomar 65
B19: Output / Hour | C19: Nos | D19: =3600/D17*D16 -> 2650.3067
B20: Output / Annum | C20: Nos | D20: =3600/D17*D16*input!C98 -> 20990429
B21: Hours Required for Set up | C21: Nos | D21: =D32*D33/60 -> 18
B22: Hours Required for Ramp Up | C22: Nos | D22: =D34*D35/60 -> 4.5
B23: Hours Required for Production | C23: Nos | D23: =D14/D19 -> 31682.149
B24: No of Machines Required | C24: Nos | D24: =D14/D20 -> 4.0002713
B25: Capacity Utilized | C25: % | D25: =D13/(D20*D24) -> 0.75
B26: Actual Production Hours / Annum | C26: Hours | D26: =D13/D19 -> 23761.611
B27: Production Hours / Annum Allocated | C27: Hours | D27: =input!C98/3 -> 2640
B29: Set Up & Ramp Up
B30: No of Orders / Year | C30: Nos | D30: =_xlfn.XLOOKUP($B30,input!$A:$A,input!$C:$C) -> 12
B31: Average Order Size | C31: Nos | D31: =D13/D30 -> 5247963.2
B32: No of Set Up / Year | C32: Nos | D32: =_xlfn.XLOOKUP($B32,input!$A:$A,input!$C:$C) -> 6
B33: Time Required for Set Up | C33: Mins | D33: 180
B34: No of Ramp Ups/Year | C34: Nos | D34: =_xlfn.XLOOKUP($B34,input!$A:$A,input!$C:$C) -> 6
B35: Time required Ramp Up | C35: Mins | D35: 45
B36: Machine Speed at Ramp Up | C36: Pcs/ Min | D36: =60/D17*D16*input!C97 -> 35.337423
B37: No of Component Wasted | C37: Nos | D37: =D35*D36 -> 1590.184
B38: Process Wastage | C38: % | D38: =D37/D31 -> 0.00030300975
B39: Burning Wastage | C39: % | D39: 0.015
B40: Wastage | C40: % | D40: =SUM(D38:D39) -> 0.01530301
B42: Machine Cost | C42: =input!$C$5 -> INR | D42: =VLOOKUP(D18,Machines,COLUMNS(backup!$D$42:$K$51),0)*$D$24 -> 1.3492827e+08
B43: Robotic Arm | C43: =input!$C$5 -> INR | D43: 50000
B44: Ancilliary Equipments | C44: =input!$C$5 -> INR | D44: =backup!E39 -> 3618609.2
B45: Total Investment | C45: =input!$C$5 -> INR | D45: =SUM(D42:D44) -> 1.3859688e+08
B47: Completed life of asset | C47: Years | D47: =_xlfn.XLOOKUP($B47,input!$A:$A,input!C:C) -> 5
B48: Depreciation | C48: =input!$C$5 -> INR | D48: =VLOOKUP(D47,Depreciation_Schedule,COLUMNS($A$199:$D$199),0) -> 10309653
B49: Depreciation | C49: =input!$C$5&" / 1000 pcs" -> INR / 1000 pcs | D49: =D48*1000/$D$13 -> 163.70879
B51: Interest on Long Term Loan | C51: % | D51: =_xlfn.XLOOKUP($B51,input!$A:$A,input!C:C) -> 0.125
B52: Interest on Long Term Loan | C52: =input!$C$5 -> INR | D52: =VLOOKUP(D47,Interest_Schedule,COLUMNS($A$239:$D$297),0) -> 12685280
B53: Interest on Long Term Loan | C53: =input!$C$5&" / 1000 pcs" -> INR / 1000 pcs | D53: =D52*1000/D13 -> 201.43179
B55: Interest on Working Capital
...

Sheet backup
B2: EBM Facility Area | C2: EBM
B3: Area Type | C3: Recommended Size (SQM) | D3: Notes
C4: India
B5: IMM Production Hall | C5: =C21*H43 -> 160.01085 | D5: Including space between machines, operator walkways
B6: Raw Material Storage | C6: =conversion!D106 -> 184.59721 | D6: Silo + bag storage, covered with material loaders, fire safety
B7: Finished Goods Warehouse | C7: =conversion!D123 -> 109.03303 | D7: 3–5 days buffer stock, stacked pallets, racking possible
B8: Tool Room & Mould Storage | C8: =C5*5% -> 8.0005426 | D8: For in-use and spare moulds; includes EOT crane space
B9: QA, Testing & Lab | C9: =C5*1% -> 1.6001085 | D9: QC, testing, documentation
B10: Maintenance + Utility Block | C10: =C5*5% -> 8.0005426 | D10: Compressor, pump room, electrical panels, workshop
B11: Office/Admin Block | C11: =C5*5% -> 8.0005426 | D11: Planning, HR, finance, customer service, etc.
B12: Canteen & Washrooms | C12: =C5*1% -> 1.6001085 | D12: Based on workforce (~150–200 people)
B13: Loading/Unloading Bays | C13: =C5*1% -> 1.6001085 | D13: 5 Bays - Dock-level bays for raw/finished goods
B14: Future Expansion | C14: 5
B15: Total Built Up Area | C15: =SUM(C5:C14) -> 487.44304
B16: FSI | C16: 0.7
B17: Land Area | C17: =C15/C16 -> 696.3472
B19: List of Auxillary Equipments
B20: Equipment List | C20: Euro | E20: =K42 -> INR Machine Cost
B21: No of Machines | C21: =conversion!D24 -> 4.0002713
B22: Hopper Dryer | C22: =1200*C21 -> 4800.3255 | E22: =_xlfn.XLOOKUP($C$20,input!$A:$A,input!C:C,0)*C22 -> 500529.94
B23: Hopper Loader | C23: =2000*C21 -> 8000.5426 | E23: =_xlfn.XLOOKUP($C$20,input!$A:$A,input!C:C,0)*C23 -> 834216.57
B24: Industrial Chiller | C24: =10000/10 -> 1000 | D24: * check Volume & change number of chillers needed | E24: =_xlfn.XLOOKUP($C$20,input!$A:$A,input!C:C,0)*C24 -> 104270
B25: Plastic Granulator | C25: =1000/10 -> 100 | E25: =_xlfn.XLOOKUP($C$20,input!$A:$A,input!C:C,0)*C25 -> 10427
B26: Doser Unit | C26: =5000/10 -> 500 | E26: =_xlfn.XLOOKUP($C$20,input!$A:$A,input!C:C,0)*C26 -> 52135
B27: Lab Equipment | C27: =7500/10 -> 750 | E27: =_xlfn.XLOOKUP($C$20,input!$A:$A,input!C:C,0)*C27 -> 78202.5
B28: Forklift | C28: =(500*4)/10 -> 200 | D28: * 4 Numbers | E28: =_xlfn.XLOOKUP($C$20,input!$A:$A,input!C:C,0)*C28 -> 20854
B29: Generator for Power | C29: =15000/10 -> 1500 | D29: * estimate | E29: =_xlfn.XLOOKUP($C$20,input!$A:$A,input!C:C,0)*C29 -> 156405
B30: Water & Air Pipe lines | C30: =10000/10 -> 1000 | D30: * estimate | E30: =_xlfn.XLOOKUP($C$20,input!$A:$A,input!C:C,0)*C30 -> 104270
B31: Stabilizer & Electric connections | C31: =25000/10 -> 2500 | D31: * estimate | E31: =_xlfn.XLOOKUP($C$20,input!$A:$A,input!C:C,0)*C31 -> 260675
B32: Fire Safety Equipment | C32: =25000/10 -> 2500 | D32: * estimate | E32: =_xlfn.XLOOKUP($C$20,input!$A:$A,input!C:C,0)*C32 -> 260675
B33: PLC + HMI + basic sensorization + simple reject + wiring for Spray coating Automation | C33: =60000/10 -> 6000 | E33: =_xlfn.XLOOKUP($C$20,input!$A:$A,input!C:C,0)*C33 -> 625620
B34: Dehumidifier | E34: =_xlfn.XLOOKUP($C$20,input!$A:$A,input!C:C,0)*C34 -> 0
B35: Compressors / Silos / Utilities | E35: =_xlfn.XLOOKUP($C$20,input!$A:$A,input!C:C,0)*C35 -> 0
B36: Supply Chain Capex | C36: 0 | E36: =_xlfn.XLOOKUP($C$20,input!$A:$A,input!C:C,0)*C36 -> 0
B37: Air Conditioning | C37: =(C5)*2350/(1500*0.0929) -> 2698.4248 | D37: * 2350 per 1500 SQFT | E37: =_xlfn.XLOOKUP($C$20,input!$A:$A,input!C:C,0)*C37 -> 281364.76
B38: Contingencies | C38: =SUM(C22:C37)*10% -> 3154.9293 | D38: * contingencies | E38: =_xlfn.XLOOKUP($C$20,input!$A:$A,input!C:C,0)*C38 -> 328964.48
B39: Total Cost | C39: =SUM(C22:C38) -> 34704.222 | E39: =SUM(E22:E38) -> 3618609.2 | G39: =C39*103/10^7 -> 0.35745349
B41: Machine Details | E41: Euro
B42: Type | C42: Make | D42: Model | E42: Machine Cost | F42: Power Consumption KWH | G42: Speed | H42: Machine Footprint SQM | K42: =input!C5&" Machine Cost" -> INR Machine Cost
B43: EBM | C43: Jomar | D43: Jomar 65 | E43: =(285000+25000)*(100%+$C$71) -> 323485 | F43: 35 | H43: 40 | K43: =_xlfn.XLOOKUP($E$41,input!$A:$A,input!C:C)*E43 -> 33729781
...

Sheet Database
A1: =SUM(D4:P20)-[1]Database!$A$1 -> 0
D2: kWH | E2: Manpower Cost | J2: per sqm | K2: per sqm | L2: per sqm | O2: Exchange rate with Euro | P2: Exchange rate with USD | AE2: KM | AF2: 300
A3: Country | B3: Currency | C3: Currency Symbol | D3: Electricity Rate | E3: Skilled Labour | F3: Engineer | G3: Production Manager | H3: Depreciation on P&M | I3: Depreciation on Building | J3: Land Cost | K3: Building Cost | L3: Lease Cost | M3: Interest on Long Term Loan | N3: Interest on Working Capital | O3: Euro | P3: USD | Q3: Layer 1 Masterbatch Rate | R3: Layer 2 Masterbatch Rate | S3: Layer 3 Masterbatch Rate | T3: Layer 1 Additive Rate | U3: Layer 2 Additive Rate | V3: Layer 3 Additive Rate | AE3: =#REF!/AF2 -> #REF!
A4: Argentina | B4: Argentinian Pesos | C4: ARS | D4: {=_xlfn.XLOOKUP( $A4, [1]Database!$A$5:$A$20, _xlfn.XLOOKUP( D$3, [1]Database!$D$4:$T$4, [1]Database!$D$5:$T$20 ) )} -> 129.15 | E4: {=_xlfn.XLOOKUP( $A4, [1]Database!$A$5:$A$20, _xlfn.XLOOKUP( E$3, [1]Database!$D$4:$T$4, [1]Database!$D$5:$T$20 ) )} -> 9792000 | F4: {=_xlfn.XLOOKUP( $A4, [1]Database!$A$5:$A$20, _xlfn.XLOOKUP( F$3, [1]Database!$D$4:$T$4, [1]Database!$D$5:$T$20 ) )} -> 1632000 | G4: {=_xlfn.XLOOKUP( $A4, [1]Database!$A$5:$A$20, _xlfn.XLOOKUP( G$3, [1]Database!$D$4:$T$4, [1]Database!$D$5:$T$20 ) )} -> 13056000 | H4: {=_xlfn.XLOOKUP( $A4, [1]Database!$A$5:$A$20, _xlfn.XLOOKUP( H$3, [1]Database!$D$4:$T$4, [1]Database!$D$5:$T$20 ) )} -> 0.1 | I4: {=_xlfn.XLOOKUP( $A4, [1]Database!$A$5:$A$20, _xlfn.XLOOKUP( I$3, [1]Database!$D$4:$T$4, [1]Database!$D$5:$T$20 ) )} -> 0.02 | J4: {=_xlfn.XLOOKUP( $A4, [1]Database!$A$5:$A$20, _xlfn.XLOOKUP( J$3, [1]Database!$D$4:$T$4, [1]Database!$D$5:$T$20 ) )} -> 194373 | K4: {=_xlfn.XLOOKUP( $A4, [1]Database!$A$5:$A$20, _xlfn.XLOOKUP( K$3, [1]Database!$D$4:$T$4, [1]Database!$D$5:$T$20 ) )} -> 0 | ... P4: {=_xlfn.XLOOKUP( $A4, [1]Database!$A$5:$A$20, _xlfn.XLOOKUP( P$3, [1]Database!$D$4:$T$4, [1]Database!$D$5:$T$20 ) )} -> 1451.24 | Q4: =Q$7*$O4 -> 7268.361 | R4: =R$7*$O4 -> 7268.361 | S4: =S$7*$O4 -> 7268.361 | T4: =T$7*$O4 -> 4036.8169 | U4: =U$7*$O4 -> 4036.8169 | V4: =V$7*$O4 -> 4036.8169
A5: Brazil | B5: Brazilian Reals | C5: BRL | D5: {=_xlfn.XLOOKUP( $A5, [1]Database!$A$5:$A$20, _xlfn.XLOOKUP( D$3, [1]Database!$D$4:$T$4, [1]Database!$D$5:$T$20 ) )} -> 0.657 | E5: {=_xlfn.XLOOKUP( $A5, [1]Database!$A$5:$A$20, _xlfn.XLOOKUP( E$3, [1]Database!$D$4:$T$4, [1]Database!$D$5:$T$20 ) )} -> 73000 | F5: {=_xlfn.XLOOKUP( $A5, [1]Database!$A$5:$A$20, _xlfn.XLOOKUP( F$3, [1]Database!$D$4:$T$4, [1]Database!$D$5:$T$20 ) )} -> 210240 | G5: {=_xlfn.XLOOKUP( $A5, [1]Database!$A$5:$A$20, _xlfn.XLOOKUP( G$3, [1]Database!$D$4:$T$4, [1]Database!$D$5:$T$20 ) )} -> 315360 | H5: {=_xlfn.XLOOKUP( $A5, [1]Database!$A$5:$A$20, _xlfn.XLOOKUP( H$3, [1]Database!$D$4:$T$4, [1]Database!$D$5:$T$20 ) )} -> 0.1 | I5: {=_xlfn.XLOOKUP( $A5, [1]Database!$A$5:$A$20, _xlfn.XLOOKUP( I$3, [1]Database!$D$4:$T$4, [1]Database!$D$5:$T$20 ) )} -> 0.04 | J5: {=_xlfn.XLOOKUP( $A5, [1]Database!$A$5:$A$20, _xlfn.XLOOKUP( J$3, [1]Database!$D$4:$T$4, [1]Database!$D$5:$T$20 ) )} -> 2533.6 | K5: {=_xlfn.XLOOKUP( $A5, [1]Database!$A$5:$A$20, _xlfn.XLOOKUP( K$3, [1]Database!$D$4:$T$4, [1]Database!$D$5:$T$20 ) )} -> 14843.75 | ... P5: {=_xlfn.XLOOKUP( $A5, [1]Database!$A$5:$A$20, _xlfn.XLOOKUP( P$3, [1]Database!$D$4:$T$4, [1]Database!$D$5:$T$20 ) )} -> 5.37 | Q5: =Q$7*$O5 -> 26.886928 | R5: =R$7*$O5 -> 26.886928 | S5: =S$7*$O5 -> 26.886928 | T5: =T$7*$O5 -> 14.932886 | U5: =U$7*$O5 -> 14.932886 | V5: =V$7*$O5 -> 14.932886
A6: China | B6: Chinese Yuan | C6: CNY | D6: {=_xlfn.XLOOKUP( $A6, [1]Database!$A$5:$A$20, _xlfn.XLOOKUP( D$3, [1]Database!$D$4:$T$4, [1]Database!$D$5:$T$20 ) )} -> 0.794 | E6: {=_xlfn.XLOOKUP( $A6, [1]Database!$A$5:$A$20, _xlfn.XLOOKUP( E$3, [1]Database!$D$4:$T$4, [1]Database!$D$5:$T$20 ) )} -> 420000 | F6: {=_xlfn.XLOOKUP( $A6, [1]Database!$A$5:$A$20, _xlfn.XLOOKUP( F$3, [1]Database!$D$4:$T$4, [1]Database!$D$5:$T$20 ) )} -> 420000 | G6: {=_xlfn.XLOOKUP( $A6, [1]Database!$A$5:$A$20, _xlfn.XLOOKUP( G$3, [1]Database!$D$4:$T$4, [1]Database!$D$5:$T$20 ) )} -> 487200 | H6: {=_xlfn.XLOOKUP( $A6, [1]Database!$A$5:$A$20, _xlfn.XLOOKUP( H$3, [1]Database!$D$4:$T$4, [1]Database!$D$5:$T$20 ) )} -> 0.1 | I6: {=_xlfn.XLOOKUP( $A6, [1]Database!$A$5:$A$20, _xlfn.XLOOKUP( I$3, [1]Database!$D$4:$T$4, [1]Database!$D$5:$T$20 ) )} -> 0.1 | J6: {=_xlfn.XLOOKUP( $A6, [1]Database!$A$5:$A$20, _xlfn.XLOOKUP( J$3, [1]Database!$D$4:$T$4, [1]Database!$D$5:$T$20 ) )} -> 1228.5 | K6: {=_xlfn.XLOOKUP( $A6, [1]Database!$A$5:$A$20, _xlfn.XLOOKUP( K$3, [1]Database!$D$4:$T$4, [1]Database!$D$5:$T$20 ) )} -> 1056.51 | ... P6: {=_xlfn.XLOOKUP( $A6, [1]Database!$A$5:$A$20, _xlfn.XLOOKUP( P$3, [1]Database!$D$4:$T$4, [1]Database!$D$5:$T$20 ) )} -> 7.11 | Q6: =Q$7*$O6 -> 35.345737 | R6: =R$7*$O6 -> 35.345737 | S6: =S$7*$O6 -> 35.345737 | T6: =T$7*$O6 -> 19.630872 | U6: =U$7*$O6 -> 19.630872 | V6: =V$7*$O6 -> 19.630872
A7: France | B7: Euros | C7: EUR | D7: {=_xlfn.XLOOKUP( $A7, [1]Database!$A$5:$A$20, _xlfn.XLOOKUP( D$3, [1]Database!$D$4:$T$4, [1]Database!$D$5:$T$20 ) )} -> 0.153 | E7: {=_xlfn.XLOOKUP( $A7, [1]Database!$A$5:$A$20, _xlfn.XLOOKUP( E$3, [1]Database!$D$4:$T$4, [1]Database!$D$5:$T$20 ) )} -> 34800 | F7: {=_xlfn.XLOOKUP( $A7, [1]Database!$A$5:$A$20, _xlfn.XLOOKUP( F$3, [1]Database!$D$4:$T$4, [1]Database!$D$5:$T$20 ) )} -> 71050 | G7: {=_xlfn.XLOOKUP( $A7, [1]Database!$A$5:$A$20, _xlfn.XLOOKUP( G$3, [1]Database!$D$4:$T$4, [1]Database!$D$5:$T$20 ) )} -> 94250 | H7: {=_xlfn.XLOOKUP( $A7, [1]Database!$A$5:$A$20, _xlfn.XLOOKUP( H$3, [1]Database!$D$4:$T$4, [1]Database!$D$5:$T$20 ) )} -> 0.1 | I7: {=_xlfn.XLOOKUP( $A7, [1]Database!$A$5:$A$20, _xlfn.XLOOKUP( I$3, [1]Database!$D$4:$T$4, [1]Database!$D$5:$T$20 ) )} -> 0.1 | J7: {=_xlfn.XLOOKUP( $A7, [1]Database!$A$5:$A$20, _xlfn.XLOOKUP( J$3, [1]Database!$D$4:$T$4, [1]Database!$D$5:$T$20 ) )} -> 0 | K7: {=_xlfn.XLOOKUP( $A7, [1]Database!$A$5:$A$20, _xlfn.XLOOKUP( K$3, [1]Database!$D$4:$T$4, [1]Database!$D$5:$T$20 ) )} -> 0 | ... P7: {=_xlfn.XLOOKUP( $A7, [1]Database!$A$5:$A$20, _xlfn.XLOOKUP( P$3, [1]Database!$D$4:$T$4, [1]Database!$D$5:$T$20 ) )} -> 0.86 | Q7: 4.3157188 | R7: 4.3157188 | S7: 4.3157188 | T7: 2.3969319 | U7: 2.3969319 | V7: 2.3969319
A8: Germany | B8: Euros | C8: EUR | D8: {=_xlfn.XLOOKUP( $A8, [1]Database!$A$5:$A$20, _xlfn.XLOOKUP( D$3, [1]Database!$D$4:$T$4, [1]Database!$D$5:$T$20 ) )} -> 0.251 | E8: {=_xlfn.XLOOKUP( $A8, [1]Database!$A$5:$A$20, _xlfn.XLOOKUP( E$3, [1]Database!$D$4:$T$4, [1]Database!$D$5:$T$20 ) )} -> 36000 | F8: {=_xlfn.XLOOKUP( $A8, [1]Database!$A$5:$A$20, _xlfn.XLOOKUP( F$3, [1]Database!$D$4:$T$4, [1]Database!$D$5:$T$20 ) )} -> 75000 | G8: {=_xlfn.XLOOKUP( $A8, [1]Database!$A$5:$A$20, _xlfn.XLOOKUP( G$3, [1]Database!$D$4:$T$4, [1]Database!$D$5:$T$20 ) )} -> 85000 | H8: {=_xlfn.XLOOKUP( $A8, [1]Database!$A$5:$A$20, _xlfn.XLOOKUP( H$3, [1]Database!$D$4:$T$4, [1]Database!$D$5:$T$20 ) )} -> 0.1 | I8: {=_xlfn.XLOOKUP( $A8, [1]Database!$A$5:$A$20, _xlfn.XLOOKUP( I$3, [1]Database!$D$4:$T$4, [1]Database!$D$5:$T$20 ) )} -> 0.1 | J8: {=_xlfn.XLOOKUP( $A8, [1]Database!$A$5:$A$20, _xlfn.XLOOKUP( J$3, [1]Database!$D$4:$T$4, [1]Database!$D$5:$T$20 ) )} -> 0 | K8: {=_xlfn.XLOOKUP( $A8, [1]Database!$A$5:$A$20, _xlfn.XLOOKUP( K$3, [1]Database!$D$4:$T$4, [1]Database!$D$5:$T$20 ) )} -> 0 | ... P8: {=_xlfn.XLOOKUP( $A8, [1]Database!$A$5:$A$20, _xlfn.XLOOKUP( P$3, [1]Database!$D$4:$T$4, [1]Database!$D$5:$T$20 ) )} -> 0.86 | Q8: =Q$7*$O8 -> 4.3157188 | R8: =R$7*$O8 -> 4.3157188 | S8: =S$7*$O8 -> 4.3157188 | T8: =T$7*$O8 -> 2.3969319 | U8: =U$7*$O8 -> 2.3969319 | V8: =V$7*$O8 -> 2.3969319
A9: Hungary | B9: Hungarian Forints | C9: HUF | D9: {=_xlfn.XLOOKUP( $A9, [1]Database!$A$5:$A$20, _xlfn.XLOOKUP( D$3, [1]Database!$D$4:$T$4, [1]Database!$D$5:$T$20 ) )} -> 92.17 | E9: {=_xlfn.XLOOKUP( $A9, [1]Database!$A$5:$A$20, _xlfn.XLOOKUP( E$3, [1]Database!$D$4:$T$4, [1]Database!$D$5:$T$20 ) )} -> 4476000 | F9: {=_xlfn.XLOOKUP( $A9, [1]Database!$A$5:$A$20, _xlfn.XLOOKUP( F$3, [1]Database!$D$4:$T$4, [1]Database!$D$5:$T$20 ) )} -> 10800000 | G9: {=_xlfn.XLOOKUP( $A9, [1]Database!$A$5:$A$20, _xlfn.XLOOKUP( G$3, [1]Database!$D$4:$T$4, [1]Database!$D$5:$T$20 ) )} -> 16560000 | H9: {=_xlfn.XLOOKUP( $A9, [1]Database!$A$5:$A$20, _xlfn.XLOOKUP( H$3, [1]Database!$D$4:$T$4, [1]Database!$D$5:$T$20 ) )} -> 0.02 | I9: {=_xlfn.XLOOKUP( $A9, [1]Database!$A$5:$A$20, _xlfn.XLOOKUP( I$3, [1]Database!$D$4:$T$4, [1]Database!$D$5:$T$20 ) )} -> 0.145 | J9: {=_xlfn.XLOOKUP( $A9, [1]Database!$A$5:$A$20, _xlfn.XLOOKUP( J$3, [1]Database!$D$4:$T$4, [1]Database!$D$5:$T$20 ) )} -> 0 | K9: {=_xlfn.XLOOKUP( $A9, [1]Database!$A$5:$A$20, _xlfn.XLOOKUP( K$3, [1]Database!$D$4:$T$4, [1]Database!$D$5:$T$20 ) )} -> 0 | ... P9: {=_xlfn.XLOOKUP( $A9, [1]Database!$A$5:$A$20, _xlfn.XLOOKUP( P$3, [1]Database!$D$4:$T$4, [1]Database!$D$5:$T$20 ) )} -> 328.47 | Q9: =Q$7*$O9 -> 1645.152 | R9: =R$7*$O9 -> 1645.152 | S9: =S$7*$O9 -> 1645.152 | T9: =T$7*$O9 -> 913.71045 | U9: =U$7*$O9 -> 913.71045 | V9: =V$7*$O9 -> 913.71045
A10: India | B10: Indian Rupees | C10: INR | D10: {=_xlfn.XLOOKUP( $A10, [1]Database!$A$5:$A$20, _xlfn.XLOOKUP( D$3, [1]Database!$D$4:$T$4, [1]Database!$D$5:$T$20 ) )} -> 10.72 | E10: {=_xlfn.XLOOKUP( $A10, [1]Database!$A$5:$A$20, _xlfn.XLOOKUP( E$3, [1]Database!$D$4:$T$4, [1]Database!$D$5:$T$20 ) )} -> 541800 | F10: {=_xlfn.XLOOKUP( $A10, [1]Database!$A$5:$A$20, _xlfn.XLOOKUP( F$3, [1]Database!$D$4:$T$4, [1]Database!$D$5:$T$20 ) )} -> 1260000 | G10: {=_xlfn.XLOOKUP( $A10, [1]Database!$A$5:$A$20, _xlfn.XLOOKUP( G$3, [1]Database!$D$4:$T$4, [1]Database!$D$5:$T$20 ) )} -> 1890000 | H10: {=_xlfn.XLOOKUP( $A10, [1]Database!$A$5:$A$20, _xlfn.XLOOKUP( H$3, [1]Database!$D$4:$T$4, [1]Database!$D$5:$T$20 ) )} -> 0.15 | I10: {=_xlfn.XLOOKUP( $A10, [1]Database!$A$5:$A$20, _xlfn.XLOOKUP( I$3, [1]Database!$D$4:$T$4, [1]Database!$D$5:$T$20 ) )} -> 0.1 | J10: {=_xlfn.XLOOKUP( $A10, [1]Database!$A$5:$A$20, _xlfn.XLOOKUP( J$3, [1]Database!$D$4:$T$4, [1]Database!$D$5:$T$20 ) )} -> 23519.019 | K10: {=_xlfn.XLOOKUP( $A10, [1]Database!$A$5:$A$20, _xlfn.XLOOKUP( K$3, [1]Database!$D$4:$T$4, [1]Database!$D$5:$T$20 ) )} -> 7000 | ... P10: {=_xlfn.XLOOKUP( $A10, [1]Database!$A$5:$A$20, _xlfn.XLOOKUP( P$3, [1]Database!$D$4:$T$4, [1]Database!$D$5:$T$20 ) )} -> 87 | Q10: =Q$7*$O10 -> 450 | R10: =R$7*$O10 -> 450 | S10: =S$7*$O10 -> 450 | T10: =T$7*$O10 -> 249.92809 | U10: =U$7*$O10 -> 249.92809 | V10: =V$7*$O10 -> 249.92809
A11: Indonesia | B11: Indonesian Rupiah | C11: IDR | D11: {=_xlfn.XLOOKUP( $A11, [1]Database!$A$5:$A$20, _xlfn.XLOOKUP( D$3, [1]Database!$D$4:$T$4, [1]Database!$D$5:$T$20 ) )} -> 1114.74 | E11: {=_xlfn.XLOOKUP( $A11, [1]Database!$A$5:$A$20, _xlfn.XLOOKUP( E$3, [1]Database!$D$4:$T$4, [1]Database!$D$5:$T$20 ) )} -> 7332000 | F11: {=_xlfn.XLOOKUP( $A11, [1]Database!$A$5:$A$20, _xlfn.XLOOKUP( F$3, [1]Database!$D$4:$T$4, [1]Database!$D$5:$T$20 ) )} -> 19552000 | G11: {=_xlfn.XLOOKUP( $A11, [1]Database!$A$5:$A$20, _xlfn.XLOOKUP( G$3, [1]Database!$D$4:$T$4, [1]Database!$D$5:$T$20 ) )} -> 24440000 | H11: {=_xlfn.XLOOKUP( $A11, [1]Database!$A$5:$A$20, _xlfn.XLOOKUP( H$3, [1]Database!$D$4:$T$4, [1]Database!$D$5:$T$20 ) )} -> 0.25 | I11: {=_xlfn.XLOOKUP( $A11, [1]Database!$A$5:$A$20, _xlfn.XLOOKUP( I$3, [1]Database!$D$4:$T$4, [1]Database!$D$5:$T$20 ) )} -> 0.1 | J11: {=_xlfn.XLOOKUP( $A11, [1]Database!$A$5:$A$20, _xlfn.XLOOKUP( J$3, [1]Database!$D$4:$T$4, [1]Database!$D$5:$T$20 ) )} -> 1700000 | K11: {=_xlfn.XLOOKUP( $A11, [1]Database!$A$5:$A$20, _xlfn.XLOOKUP( K$3, [1]Database!$D$4:$T$4, [1]Database!$D$5:$T$20 ) )} -> 5500000 | ... P11: {=_xlfn.XLOOKUP( $A11, [1]Database!$A$5:$A$20, _xlfn.XLOOKUP( P$3, [1]Database!$D$4:$T$4, [1]Database!$D$5:$T$20 ) )} -> 16665.3 | Q11: =Q$7*$O11 -> 83354.656 | R11: =R$7*$O11 -> 83354.656 | S11: =S$7*$O11 -> 83354.656 | T11: =T$7*$O11 -> 46294.823 | U11: =U$7*$O11 -> 46294.823 | V11: =V$7*$O11 -> 46294.823
A12: Mexico | B12: Mexican Pesos | C12: MXN | D12: {=_xlfn.XLOOKUP( $A12, [1]Database!$A$5:$A$20, _xlfn.XLOOKUP( D$3, [1]Database!$D$4:$T$4, [1]Database!$D$5:$T$20 ) )} -> 3.972 | E12: {=_xlfn.XLOOKUP( $A12, [1]Database!$A$5:$A$20, _xlfn.XLOOKUP( E$3, [1]Database!$D$4:$T$4, [1]Database!$D$5:$T$20 ) )} -> 180000 | F12: {=_xlfn.XLOOKUP( $A12, [1]Database!$A$5:$A$20, _xlfn.XLOOKUP( F$3, [1]Database!$D$4:$T$4, [1]Database!$D$5:$T$20 ) )} -> 492000 | G12: {=_xlfn.XLOOKUP( $A12, [1]Database!$A$5:$A$20, _xlfn.XLOOKUP( G$3, [1]Database!$D$4:$T$4, [1]Database!$D$5:$T$20 ) )} -> 852000 | H12: {=_xlfn.XLOOKUP( $A12, [1]Database!$A$5:$A$20, _xlfn.XLOOKUP( H$3, [1]Database!$D$4:$T$4, [1]Database!$D$5:$T$20 ) )} -> 0.1 | I12: {=_xlfn.XLOOKUP( $A12, [1]Database!$A$5:$A$20, _xlfn.XLOOKUP( I$3, [1]Database!$D$4:$T$4, [1]Database!$D$5:$T$20 ) )} -> 0.05 | J12: {=_xlfn.XLOOKUP( $A12, [1]Database!$A$5:$A$20, _xlfn.XLOOKUP( J$3, [1]Database!$D$4:$T$4, [1]Database!$D$5:$T$20 ) )} -> 0 | K12: {=_xlfn.XLOOKUP( $A12, [1]Database!$A$5:$A$20, _xlfn.XLOOKUP( K$3, [1]Database!$D$4:$T$4, [1]Database!$D$5:$T$20 ) )} -> 0 | ... P12: {=_xlfn.XLOOKUP( $A12, [1]Database!$A$5:$A$20, _xlfn.XLOOKUP( P$3, [1]Database!$D$4:$T$4, [1]Database!$D$5:$T$20 ) )} -> 18.32 | Q12: =Q$7*$O12 -> 91.752182 | R12: =R$7*$O12 -> 91.752182 | S12: =S$7*$O12 -> 91.752182 | T12: =T$7*$O12 -> 50.958773 | U12: =U$7*$O12 -> 50.958773 | V12: =V$7*$O12 -> 50.958773
A13: Pakistan | B13: Pakistani Rupees | C13: PKR | D13: {=_xlfn.XLOOKUP( $A13, [1]Database!$A$5:$A$20, _xlfn.XLOOKUP( D$3, [1]Database!$D$4:$T$4, [1]Database!$D$5:$T$20 ) )} -> 41.99 | E13: {=_xlfn.XLOOKUP( $A13, [1]Database!$A$5:$A$20, _xlfn.XLOOKUP( E$3, [1]Database!$D$4:$T$4, [1]Database!$D$5:$T$20 ) )} -> 504000 | F13: {=_xlfn.XLOOKUP( $A13, [1]Database!$A$5:$A$20, _xlfn.XLOOKUP( F$3, [1]Database!$D$4:$T$4, [1]Database!$D$5:$T$20 ) )} -> 384000 | G13: {=_xlfn.XLOOKUP( $A13, [1]Database!$A$5:$A$20, _xlfn.XLOOKUP( G$3, [1]Database!$D$4:$T$4, [1]Database!$D$5:$T$20 ) )} -> 2400000 | H13: {=_xlfn.XLOOKUP( $A13, [1]Database!$A$5:$A$20, _xlfn.XLOOKUP( H$3, [1]Database!$D$4:$T$4, [1]Database!$D$5:$T$20 ) )} -> 0.15 | I13: {=_xlfn.XLOOKUP( $A13, [1]Database!$A$5:$A$20, _xlfn.XLOOKUP( I$3, [1]Database!$D$4:$T$4, [1]Database!$D$5:$T$20 ) )} -> 0.1 | J13: {=_xlfn.XLOOKUP( $A13, [1]Database!$A$5:$A$20, _xlfn.XLOOKUP( J$3, [1]Database!$D$4:$T$4, [1]Database!$D$5:$T$20 ) )} -> 0 | K13: {=_xlfn.XLOOKUP( $A13, [1]Database!$A$5:$A$20, _xlfn.XLOOKUP( K$3, [1]Database!$D$4:$T$4, [1]Database!$D$5:$T$20 ) )} -> 0 | ... P13: {=_xlfn.XLOOKUP( $A13, [1]Database!$A$5:$A$20, _xlfn.XLOOKUP( P$3, [1]Database!$D$4:$T$4, [1]Database!$D$5:$T$20 ) )} -> 282.99 | Q13: =Q$7*$O13 -> 1417.7999 | R13: =R$7*$O13 -> 1417.7999 | S13: =S$7*$O13 -> 1417.7999 | T13: =T$7*$O13 -> 787.44008 | U13: =U$7*$O13 -> 787.44008 | V13: =V$7*$O13 -> 787.44008
A14: Philippines | B14: Philippines Pesos | C14: PHP | D14: {=_xlfn.XLOOKUP( $A14, [1]Database!$A$5:$A$20, _xlfn.XLOOKUP( D$3, [1]Database!$D$4:$T$4, [1]Database!$D$5:$T$20 ) )} -> 8.847 | E14: {=_xlfn.XLOOKUP( $A14, [1]Database!$A$5:$A$20, _xlfn.XLOOKUP( E$3, [1]Database!$D$4:$T$4, [1]Database!$D$5:$T$20 ) )} -> 242880 | F14: {=_xlfn.XLOOKUP( $A14, [1]Database!$A$5:$A$20, _xlfn.XLOOKUP( F$3, [1]Database!$D$4:$T$4, [1]Database!$D$5:$T$20 ) )} -> 473470.52 | G14: {=_xlfn.XLOOKUP( $A14, [1]Database!$A$5:$A$20, _xlfn.XLOOKUP( G$3, [1]Database!$D$4:$T$4, [1]Database!$D$5:$T$20 ) )} -> 538167.68 | H14: {=_xlfn.XLOOKUP( $A14, [1]Database!$A$5:$A$20, _xlfn.XLOOKUP( H$3, [1]Database!$D$4:$T$4, [1]Database!$D$5:$T$20 ) )} -> 0.1 | I14: {=_xlfn.XLOOKUP( $A14, [1]Database!$A$5:$A$20, _xlfn.XLOOKUP( I$3, [1]Database!$D$4:$T$4, [1]Database!$D$5:$T$20 ) )} -> 0.1 | J14: {=_xlfn.XLOOKUP( $A14, [1]Database!$A$5:$A$20, _xlfn.XLOOKUP( J$3, [1]Database!$D$4:$T$4, [1]Database!$D$5:$T$20 ) )} -> 16240 | K14: {=_xlfn.XLOOKUP( $A14, [1]Database!$A$5:$A$20, _xlfn.XLOOKUP( K$3, [1]Database!$D$4:$T$4, [1]Database!$D$5:$T$20 ) )} -> 20000 | ... P14: {=_xlfn.XLOOKUP( $A14, [1]Database!$A$5:$A$20, _xlfn.XLOOKUP( P$3, [1]Database!$D$4:$T$4, [1]Database!$D$5:$T$20 ) )} -> 58.89 | Q14: =Q$7*$O14 -> 292.90784 | R14: =R$7*$O14 -> 292.90784 | S14: =S$7*$O14 -> 292.90784 | T14: =T$7*$O14 -> 162.67977 | U14: =U$7*$O14 -> 162.67977 | V14: =V$7*$O14 -> 162.67977
A15: South Africa | B15: South African Rand | C15: ZAR | D15: {=_xlfn.XLOOKUP( $A15, [1]Database!$A$5:$A$20, _xlfn.XLOOKUP( D$3, [1]Database!$D$4:$T$4, [1]Database!$D$5:$T$20 ) )} -> 1.795 | E15: {=_xlfn.XLOOKUP( $A15, [1]Database!$A$5:$A$20, _xlfn.XLOOKUP( E$3, [1]Database!$D$4:$T$4, [1]Database!$D$5:$T$20 ) )} -> 231858 | F15: {=_xlfn.XLOOKUP( $A15, [1]Database!$A$5:$A$20, _xlfn.XLOOKUP( F$3, [1]Database!$D$4:$T$4, [1]Database!$D$5:$T$20 ) )} -> 494630.4 | G15: {=_xlfn.XLOOKUP( $A15, [1]Database!$A$5:$A$20, _xlfn.XLOOKUP( G$3, [1]Database!$D$4:$T$4, [1]Database!$D$5:$T$20 ) )} -> 772860 | H15: {=_xlfn.XLOOKUP( $A15, [1]Database!$A$5:$A$20, _xlfn.XLOOKUP( H$3, [1]Database!$D$4:$T$4, [1]Database!$D$5:$T$20 ) )} -> 0.2 | I15: {=_xlfn.XLOOKUP( $A15, [1]Database!$A$5:$A$20, _xlfn.XLOOKUP( I$3, [1]Database!$D$4:$T$4, [1]Database!$D$5:$T$20 ) )} -> 0.05 | J15: {=_xlfn.XLOOKUP( $A15, [1]Database!$A$5:$A$20, _xlfn.XLOOKUP( J$3, [1]Database!$D$4:$T$4, [1]Database!$D$5:$T$20 ) )} -> 0 | K15: {=_xlfn.XLOOKUP( $A15, [1]Database!$A$5:$A$20, _xlfn.XLOOKUP( K$3, [1]Database!$D$4:$T$4, [1]Database!$D$5:$T$20 ) )} -> 0 | ... P15: {=_xlfn.XLOOKUP( $A15, [1]Database!$A$5:$A$20, _xlfn.XLOOKUP( P$3, [1]Database!$D$4:$T$4, [1]Database!$D$5:$T$20 ) )} -> 17.13 | Q15: =Q$7*$O15 -> 85.79649 | R15: =R$7*$O15 -> 85.79649 | S15: =S$7*$O15 -> 85.79649 | T15: =T$7*$O15 -> 47.651007 | U15: =U$7*$O15 -> 47.651007 | V15: =V$7*$O15 -> 47.651007
A16: Turkey | B16: Turkish Lira | C16: TRY | D16: {=_xlfn.XLOOKUP( $A16, [1]Database!$A$5:$A$20, _xlfn.XLOOKUP( D$3, [1]Database!$D$4:$T$4, [1]Database!$D$5:$T$20 ) )} -> 4.35 | E16: {=_xlfn.XLOOKUP( $A16, [1]Database!$A$5:$A$20, _xlfn.XLOOKUP( E$3, [1]Database!$D$4:$T$4, [1]Database!$D$5:$T$20 ) )} -> 281880 | F16: {=_xlfn.XLOOKUP( $A16, [1]Database!$A$5:$A$20, _xlfn.XLOOKUP( F$3, [1]Database!$D$4:$T$4, [1]Database!$D$5:$T$20 ) )} -> 548100 | G16: {=_xlfn.XLOOKUP( $A16, [1]Database!$A$5:$A$20, _xlfn.XLOOKUP( G$3, [1]Database!$D$4:$T$4, [1]Database!$D$5:$T$20 ) )} -> 532440 | H16: {=_xlfn.XLOOKUP( $A16, [1]Database!$A$5:$A$20, _xlfn.XLOOKUP( H$3, [1]Database!$D$4:$T$4, [1]Database!$D$5:$T$20 ) )} -> 0.1 | I16: {=_xlfn.XLOOKUP( $A16, [1]Database!$A$5:$A$20, _xlfn.XLOOKUP( I$3, [1]Database!$D$4:$T$4, [1]Database!$D$5:$T$20 ) )} -> 0.1 | J16: {=_xlfn.XLOOKUP( $A16, [1]Database!$A$5:$A$20, _xlfn.XLOOKUP( J$3, [1]Database!$D$4:$T$4, [1]Database!$D$5:$T$20 ) )} -> 0 | K16: {=_xlfn.XLOOKUP( $A16, [1]Database!$A$5:$A$20, _xlfn.XLOOKUP( K$3, [1]Database!$D$4:$T$4, [1]Database!$D$5:$T$20 ) )} -> 0 | ... P16: {=_xlfn.XLOOKUP( $A16, [1]Database!$A$5:$A$20, _xlfn.XLOOKUP( P$3, [1]Database!$D$4:$T$4, [1]Database!$D$5:$T$20 ) )} -> 42.43 | Q16: =Q$7*$O16 -> 212.72178 | R16: =R$7*$O16 -> 212.72178 | S16: =S$7*$O16 -> 212.72178 | T16: =T$7*$O16 -> 118.14477 | U16: =U$7*$O16 -> 118.14477 | V16: =V$7*$O16 -> 118.14477
A17: United Kingdom | B17: British Pounds | C17: GBP | D17: {=_xlfn.XLOOKUP( $A17, [1]Database!$A$5:$A$20, _xlfn.XLOOKUP( D$3, [1]Database!$D$4:$T$4, [1]Database!$D$5:$T$20 ) )} -> 0.346 | E17: {=_xlfn.XLOOKUP( $A17, [1]Database!$A$5:$A$20, _xlfn.XLOOKUP( E$3, [1]Database!$D$4:$T$4, [1]Database!$D$5:$T$20 ) )} -> 39900 | F17: {=_xlfn.XLOOKUP( $A17, [1]Database!$A$5:$A$20, _xlfn.XLOOKUP( F$3, [1]Database!$D$4:$T$4, [1]Database!$D$5:$T$20 ) )} -> 57190 | G17: {=_xlfn.XLOOKUP( $A17, [1]Database!$A$5:$A$20, _xlfn.XLOOKUP( G$3, [1]Database!$D$4:$T$4, [1]Database!$D$5:$T$20 ) )} -> 66500 | H17: {=_xlfn.XLOOKUP( $A17, [1]Database!$A$5:$A$20, _xlfn.XLOOKUP( H$3, [1]Database!$D$4:$T$4, [1]Database!$D$5:$T$20 ) )} -> 0.18 | I17: {=_xlfn.XLOOKUP( $A17, [1]Database!$A$5:$A$20, _xlfn.XLOOKUP( I$3, [1]Database!$D$4:$T$4, [1]Database!$D$5:$T$20 ) )} -> 0.03 | J17: {=_xlfn.XLOOKUP( $A17, [1]Database!$A$5:$A$20, _xlfn.XLOOKUP( J$3, [1]Database!$D$4:$T$4, [1]Database!$D$5:$T$20 ) )} -> 0 | K17: {=_xlfn.XLOOKUP( $A17, [1]Database!$A$5:$A$20, _xlfn.XLOOKUP( K$3, [1]Database!$D$4:$T$4, [1]Database!$D$5:$T$20 ) )} -> 0 | ... P17: {=_xlfn.XLOOKUP( $A17, [1]Database!$A$5:$A$20, _xlfn.XLOOKUP( P$3, [1]Database!$D$4:$T$4, [1]Database!$D$5:$T$20 ) )} -> 0.76 | Q17: =Q$7*$O17 -> 3.7978326 | R17: =R$7*$O17 -> 3.7978326 | S17: =S$7*$O17 -> 3.7978326 | T17: =T$7*$O17 -> 2.1093001 | U17: =U$7*$O17 -> 2.1093001 | V17: =V$7*$O17 -> 2.1093001
A18: United States | B18: U.S. Dollars | C18: USD | D18: {=_xlfn.XLOOKUP( $A18, [1]Database!$A$5:$A$20, _xlfn.XLOOKUP( D$3, [1]Database!$D$4:$T$4, [1]Database!$D$5:$T$20 ) )} -> 0.149 | E18: {=_xlfn.XLOOKUP( $A18, [1]Database!$A$5:$A$20, _xlfn.XLOOKUP( E$3, [1]Database!$D$4:$T$4, [1]Database!$D$5:$T$20 ) )} -> 98250.6 | F18: {=_xlfn.XLOOKUP( $A18, [1]Database!$A$5:$A$20, _xlfn.XLOOKUP( F$3, [1]Database!$D$4:$T$4, [1]Database!$D$5:$T$20 ) )} -> 130993.8 | G18: {=_xlfn.XLOOKUP( $A18, [1]Database!$A$5:$A$20, _xlfn.XLOOKUP( G$3, [1]Database!$D$4:$T$4, [1]Database!$D$5:$T$20 ) )} -> 117125.4 | H18: {=_xlfn.XLOOKUP( $A18, [1]Database!$A$5:$A$20, _xlfn.XLOOKUP( H$3, [1]Database!$D$4:$T$4, [1]Database!$D$5:$T$20 ) )} -> 0.1 | I18: {=_xlfn.XLOOKUP( $A18, [1]Database!$A$5:$A$20, _xlfn.XLOOKUP( I$3, [1]Database!$D$4:$T$4, [1]Database!$D$5:$T$20 ) )} -> 0.1 | J18: {=_xlfn.XLOOKUP( $A18, [1]Database!$A$5:$A$20, _xlfn.XLOOKUP( J$3, [1]Database!$D$4:$T$4, [1]Database!$D$5:$T$20 ) )} -> 2.47 | K18: {=_xlfn.XLOOKUP( $A18, [1]Database!$A$5:$A$20, _xlfn.XLOOKUP( K$3, [1]Database!$D$4:$T$4, [1]Database!$D$5:$T$20 ) )} -> 0 | ... P18: {=_xlfn.XLOOKUP( $A18, [1]Database!$A$5:$A$20, _xlfn.XLOOKUP( P$3, [1]Database!$D$4:$T$4, [1]Database!$D$5:$T$20 ) )} -> 1 | Q18: =Q$7*$O18 -> 5.0062338 | R18: =R$7*$O18 -> 5.0062338 | S18: =S$7*$O18 -> 5.0062338 | T18: =T$7*$O18 -> 2.780441 | U18: =U$7*$O18 -> 2.780441 | V18: =V$7*$O18 -> 2.780441
A19: Vietnam | B19: Vietnamese Dong | C19: VND | D19: {=_xlfn.XLOOKUP( $A19, [1]Database!$A$5:$A$20, _xlfn.XLOOKUP( D$3, [1]Database!$D$4:$T$4, [1]Database!$D$5:$T$20 ) )} -> 1744 | E19: {=_xlfn.XLOOKUP( $A19, [1]Database!$A$5:$A$20, _xlfn.XLOOKUP( E$3, [1]Database!$D$4:$T$4, [1]Database!$D$5:$T$20 ) )} -> 139920000 | F19: {=_xlfn.XLOOKUP( $A19, [1]Database!$A$5:$A$20, _xlfn.XLOOKUP( F$3, [1]Database!$D$4:$T$4, [1]Database!$D$5:$T$20 ) )} -> 8.2716216e+08 | G19: {=_xlfn.XLOOKUP( $A19, [1]Database!$A$5:$A$20, _xlfn.XLOOKUP( G$3, [1]Database!$D$4:$T$4, [1]Database!$D$5:$T$20 ) )} -> 9.2173476e+08 | H19: {=_xlfn.XLOOKUP( $A19, [1]Database!$A$5:$A$20, _xlfn.XLOOKUP( H$3, [1]Database!$D$4:$T$4, [1]Database!$D$5:$T$20 ) )} -> 0.1 | I19: {=_xlfn.XLOOKUP( $A19, [1]Database!$A$5:$A$20, _xlfn.XLOOKUP( I$3, [1]Database!$D$4:$T$4, [1]Database!$D$5:$T$20 ) )} -> 0.1 | J19: {=_xlfn.XLOOKUP( $A19, [1]Database!$A$5:$A$20, _xlfn.XLOOKUP( J$3, [1]Database!$D$4:$T$4, [1]Database!$D$5:$T$20 ) )} -> 3586051.9 | K19: {=_xlfn.XLOOKUP( $A19, [1]Database!$A$5:$A$20, _xlfn.XLOOKUP( K$3, [1]Database!$D$4:$T$4, [1]Database!$D$5:$T$20 ) )} -> 3403710.2 | ... P19: {=_xlfn.XLOOKUP( $A19, [1]Database!$A$5:$A$20, _xlfn.XLOOKUP( P$3, [1]Database!$D$4:$T$4, [1]Database!$D$5:$T$20 ) )} -> 26369 | Q19: =Q$7*$O19 -> 131155.86 | R19: =R$7*$O19 -> 131155.86 | S19: =S$7*$O19 -> 131155.86 | T19: =T$7*$O19 -> 72843.408 | U19: =U$7*$O19 -> 72843.408 | V19: =V$7*$O19 -> 72843.408

Sheet Log
A3: Sl No | B3: Date | C3: Cost INR/ TH | D3: Change | E3: Reason
A4: 1 | B4: 17thDec25 | C4: 3197.5
C5: 3185.6 | D5: =(C4-C5)/C4 -> 0.0037216575 | E5: Due to change in land, building and labour cost

Sheet rational_sheet
B2: Details | C2: Unit | D2: Assumption | E2: Rationale | F2: Source | G2: Screenshot
B3: Financials
B4: Land Area | C4: SQM
B5: Building Area | C5: SQM
B6: Land Cost | C6: ₹/SQM | D6: 14833.58 | E6: - Cost for Industrial land in the area of supplier | F6: Industrial Land for sale in Silvassa | Buy 88+ Industrial Plots in Silvassa | G6: #VALUE! | H6: 2177 SQFT = ₹ 30 lakhs 1 SQFT = ₹ 1378.04 0.0929 SQM = ₹ 1378.04 1 SQM = 1378.04 / 0.0929 = ₹ 14,833.58
B7: Building Cost | C7: ₹/SQM | D7: 36681.16 | E7: - Cost of Constructing Building & Industrial Shed in the area of supplier | F7: Factory for sale in Silvassa | Buy 165+ Industrial Building in Silvassa | G7: #VALUE! | H7: 16140 SQFT = ₹ 5.5cr 1 SQFT = ₹ 3407.68 0.0929 SQM = ₹ 3407.68 1 SQM = 3407.68 / 0.0929 = ₹ 36,681.16
B8: Lease Cost | C8: ₹/SQM | D8: 1560.6 | E8: - Cost of leasing factory Land & Building in area of supplier | F8: Factory for Rent in Silvassa | Rental Factory in Silvassa | G8: #VALUE! | H8: 26900 SQFT = ₹ 39 lakhs 1 SQFT = ₹ 144.98 0.0929 SQM = ₹ 144.98 1 SQM = 144.98 / 0.0929 = ₹ 1,560.60
B9: Type of Premises | E9: Option to select whether factory is leased or owned
B10: Depreciation on Building | C10: % | D10: 0.1 | E10: - As per Income Tax Act - Compensates the company for utilizing the building in production activities & ensures its upkeep. | F10: https://incometaxindia.gov.in/charts%20%20tables/depreciation%20rates.htm
B11: Depreciation on Plant and Machinery | C11: % | D11: 0.15 | E11: - Applied on a reducing balance basis over a period of up to 15 years - Accounts for ongoing wear & tear caused by extreme operating conditions, with certain components requiring replacement every 5 to 10 years | F11: https://incometaxindia.gov.in/charts%20%20tables/depreciation%20rates.htm | G11: #VALUE!
B12: Interest on Long Term Loan | C12: % | D12: 0.1075 | E12: - based on prevailing banking interest rates in the country - Calculated basis Simple Interest - Assumption that all assets & replacements are fully financed through bank loans | F12: Business Loan Interest Rates, Fees & Charges (October 2025) | HDFC Bank | G12: #VALUE!
B13: Interest on Working Capital | C13: % | D13: 0.0925 | E13: - Based on prevailing banking interest rates in the country | F13: Bill Discounting Scheme - NSIC : National Small Industries Corporation Ltd. | G13: #VALUE!
B14: Electricity | C14: ₹/KWH | D14: 7.5 | E14: - Rate assumed for the industrial use as prevalent in the specific area of the country.
B15: Rpair & Maintenance | C15: % | D15: 0.025 | E15: - Regular Maintenance for wear & tear of Machines
B16: Other Overheads | C16: % | D16: 0.025 | E16: - Cover any costs like Administrative costs, Office space, Travel & Logistics, IT, communication, HR & Training Costs, Compliance & Certifications, etc
B18: Manpower Details
B19: Skilled Labour | C19: ₹/ Annum | D19: =360000*128% -> 460800 | E19: Annual Salary + Benefits - Employer’s contributions to Provident Fund(12%) - Employer’s Pension (4.81%) - Bonus - 10% | F19: Machine operator salary in Silvassa, Dadra and Nagar Haveli | G19: #VALUE!
B20: Engineer | C20: ₹/ Annum | D20: =550000*128% -> 704000 | E20: Annual Salary + Benefits - Employer’s contributions to Provident Fund(12%) - Employer’s Pension (4.81%) - Bonus - 10% | F20: Engineer salary in Silvassa, Dadra and Nagar Haveli | G20: #VALUE!
B21: Production Manager | C21: ₹/ Annum | D21: =1800000*128% -> 2304000 | E21: Annual Salary + Benefits - Employer’s contributions to Provident Fund(12%) - Employer’s Pension (4.81%) - Bonus - 10% | F21: Production manager salary in Silvassa, Dadra and Nagar Haveli | G21: #VALUE!
B22: No of Shifts
C33: =60000/10 -> 6000
C37: =(C5)*2350/(1500*0.0929) -> #VALUE!
C38: =SUM(C22:C37)*10% -> #VALUE!
C39: =SUM(C22:C38) -> #VALUE!
